#VRML_SIM R2025a utf8

EXTERNPROTO "https://raw.githubusercontent.com/cyberbotics/webots/R2022b/projects/objects/backgrounds/protos/TexturedBackground.proto"
EXTERNPROTO "https://raw.githubusercontent.com/cyberbotics/webots/R2022b/projects/objects/backgrounds/protos/TexturedBackgroundLight.proto"
EXTERNPROTO "https://raw.githubusercontent.com/cyberbotics/webots/R2022b/projects/objects/floors/protos/CircleArena.proto"

WorldInfo {
  basicTimeStep 8
}
Viewpoint {
  orientation -0.3352085394445663 0.2621028342324504 0.9049515674171503 2.0141582411281442
  position 1.2785984690626009 -3.4728601385371554 2.937443709880219
  followType "None"
}
TexturedBackground {
}
TexturedBackgroundLight {
}
CircleArena {
  radius 2
}
Robot {
  translation 0 0 0.04
  children [
    Shape {
      appearance DEF silver PBRAppearance {
        baseColor 0.5 0.5 0.5
        roughness 1
        metalness 0
      }
      geometry DEF base_link Mesh {
        url [
          "/home/hostuser/omni-1-ws/src/omni_1_description/meshes/base_link.stl"
        ]
      }
    }
    HingeJoint {
      jointParameters HingeJointParameters {
        axis 0 -1 0
        anchor 0 -0.1 0
      }
      device [
        RotationalMotor {
          name "wheel-frame0"
          maxVelocity 100
          maxTorque 100
        }
        PositionSensor {
          name "wheel-frame0_sensor"
        }
      ]
      endPoint Solid {
        translation 0 -0.1 0
        children [
          Shape {
            appearance DEF grey PBRAppearance {
              baseColor 0.5 0.5 0.5
              roughness 1
              metalness 0
            }
            geometry DEF wheel_frame Mesh {
              url [
                "/home/hostuser/omni-1-ws/src/omni_1_description/meshes/wheel_frame.stl"
              ]
            }
          }
          HingeJoint {
            jointParameters HingeJointParameters {
              anchor 0 0.013 0.024
              dampingConstant 0.01
              staticFriction 0.1
            }
            device [
              RotationalMotor {
                name "wheel0-roller0"
                maxTorque 10000
              }
              PositionSensor {
                name "wheel0-roller0_sensor"
              }
            ]
            endPoint Solid {
              translation 0 0.013 0.024
              children [
                Pose {
                  translation 0 0 -0.024
                  children [
                    Shape {
                      appearance DEF black PBRAppearance {
                        baseColor 0.5 0.5 0.5
                        roughness 1
                        metalness 0
                      }
                      geometry DEF roller Mesh {
                        url [
                          "/home/hostuser/omni-1-ws/src/omni_1_description/meshes/roller.stl"
                        ]
                      }
                    }
                  ]
                }
              ]
              name "roller-0-0"
              boundingObject Pose {
                translation 0 0 -0.024
                children [
                  USE roller
                ]
              }
              physics Physics {
                density -1
                mass 0.02
                centerOfMass [
                  0 0 0
                ]
                inertiaMatrix [
                  2.7e-06 2.7e-06 1e-06
                  0 0 0
                ]
              }
            }
          }
          HingeJoint {
            jointParameters HingeJointParameters {
              axis -0.5 0 -0.866025
              anchor 0.020785 0.013 -0.012
              dampingConstant 0.01
              staticFriction 0.1
            }
            device [
              RotationalMotor {
                name "wheel0-roller1"
                maxTorque 10000
              }
              PositionSensor {
                name "wheel0-roller1_sensor"
              }
            ]
            endPoint Solid {
              translation 0.020785 0.013 -0.012
              rotation 0 1 0 2.094395
              children [
                Pose {
                  translation 0 0 -0.024
                  children [
                    Shape {
                      appearance USE black
                      geometry USE roller
                    }
                  ]
                }
              ]
              name "roller-0-1"
              boundingObject Pose {
                translation 0 0 -0.024
                children [
                  USE roller
                ]
              }
              physics Physics {
                density -1
                mass 0.02
                centerOfMass [
                  0 0 0
                ]
                inertiaMatrix [
                  2.7e-06 2.7e-06 1e-06
                  0 0 0
                ]
              }
            }
          }
          HingeJoint {
            jointParameters HingeJointParameters {
              axis -0.5 0 0.866025
              anchor -0.020785 0.013 -0.012
              dampingConstant 0.01
              staticFriction 0.1
            }
            device [
              RotationalMotor {
                name "wheel0-roller2"
                maxTorque 10000
              }
              PositionSensor {
                name "wheel0-roller2_sensor"
              }
            ]
            endPoint Solid {
              translation -0.020785 0.013 -0.012
              rotation 0 1 0 4.18879
              children [
                Pose {
                  translation 0 0 -0.024
                  children [
                    Shape {
                      appearance USE black
                      geometry USE roller
                    }
                  ]
                }
              ]
              name "roller-0-2"
              boundingObject Pose {
                translation 0 0 -0.024
                children [
                  USE roller
                ]
              }
              physics Physics {
                density -1
                mass 0.02
                centerOfMass [
                  0 0 0
                ]
                inertiaMatrix [
                  2.7e-06 2.7e-06 1e-06
                  0 0 0
                ]
              }
            }
          }
          HingeJoint {
            jointParameters HingeJointParameters {
              axis 0.5 0 -0.866025
              anchor 0.020785 -0.013 0.012
              dampingConstant 0.01
              staticFriction 0.1
            }
            device [
              RotationalMotor {
                name "wheel0-roller3"
                maxTorque 10000
              }
              PositionSensor {
                name "wheel0-roller3_sensor"
              }
            ]
            endPoint Solid {
              translation 0.020785 -0.013 0.012
              rotation 0 1 0 1.047198
              children [
                Pose {
                  translation 0 0 -0.024
                  children [
                    Shape {
                      appearance USE black
                      geometry USE roller
                    }
                  ]
                }
              ]
              name "roller-0-3"
              boundingObject Pose {
                translation 0 0 -0.024
                children [
                  USE roller
                ]
              }
              physics Physics {
                density -1
                mass 0.02
                centerOfMass [
                  0 0 0
                ]
                inertiaMatrix [
                  2.7e-06 2.7e-06 1e-06
                  0 0 0
                ]
              }
            }
          }
          HingeJoint {
            jointParameters HingeJointParameters {
              axis -1 0 0
              anchor 0 -0.013 -0.024
              dampingConstant 0.01
              staticFriction 0.1
            }
            device [
              RotationalMotor {
                name "wheel0-roller4"
                maxTorque 10000
              }
              PositionSensor {
                name "wheel0-roller4_sensor"
              }
            ]
            endPoint Solid {
              translation 0 -0.013 -0.024
              rotation 0 1 0 3.141593
              children [
                Pose {
                  translation 0 0 -0.024
                  children [
                    Shape {
                      appearance USE black
                      geometry USE roller
                    }
                  ]
                }
              ]
              name "roller-0-4"
              boundingObject Pose {
                translation 0 0 -0.024
                children [
                  USE roller
                ]
              }
              physics Physics {
                density -1
                mass 0.02
                centerOfMass [
                  0 0 0
                ]
                inertiaMatrix [
                  2.7e-06 2.7e-06 1e-06
                  0 0 0
                ]
              }
            }
          }
          HingeJoint {
            jointParameters HingeJointParameters {
              axis 0.5 0 0.866025
              anchor -0.020785 -0.013 0.012
              dampingConstant 0.01
              staticFriction 0.1
            }
            device [
              RotationalMotor {
                name "wheel0-roller5"
                maxTorque 10000
              }
              PositionSensor {
                name "wheel0-roller5_sensor"
              }
            ]
            endPoint Solid {
              translation -0.020785 -0.013 0.012
              rotation 0 1 0 5.235988
              children [
                Pose {
                  translation 0 0 -0.024
                  children [
                    Shape {
                      appearance USE black
                      geometry USE roller
                    }
                  ]
                }
              ]
              name "roller-0-5"
              boundingObject Pose {
                translation 0 0 -0.024
                children [
                  USE roller
                ]
              }
              physics Physics {
                density -1
                mass 0.02
                centerOfMass [
                  0 0 0
                ]
                inertiaMatrix [
                  2.7e-06 2.7e-06 1e-06
                  0 0 0
                ]
              }
            }
          }
        ]
        name "wheel-frame0"
        boundingObject USE wheel_frame
        physics Physics {
          density -1
          mass 0.5
          centerOfMass [
            0 0 0
          ]
          inertiaMatrix [
            0.00017 0.00018 0.00017
            0 0 0
          ]
        }
      }
    }
    HingeJoint {
      jointParameters HingeJointParameters {
        axis 0.866025 0.5 0
        anchor 0.086603 0.05 0
      }
      device [
        RotationalMotor {
          name "wheel-frame120"
          maxVelocity 100
          maxTorque 100
        }
        PositionSensor {
          name "wheel-frame120_sensor"
        }
      ]
      endPoint Solid {
        translation 0.086603 0.05 0
        rotation 0 0 1 2.094395
        children [
          Shape {
            appearance USE grey
            geometry USE wheel_frame
          }
          HingeJoint {
            jointParameters HingeJointParameters {
              anchor 0 0.013 0.024
              dampingConstant 0.01
              staticFriction 0.1
            }
            device [
              RotationalMotor {
                name "wheel120-roller0"
                maxTorque 10000
              }
              PositionSensor {
                name "wheel120-roller0_sensor"
              }
            ]
            endPoint Solid {
              translation 0 0.013 0.024
              children [
                Pose {
                  translation 0 0 -0.024
                  children [
                    Shape {
                      appearance USE black
                      geometry USE roller
                    }
                  ]
                }
              ]
              name "roller-1-0"
              boundingObject Pose {
                translation 0 0 -0.024
                children [
                  USE roller
                ]
              }
              physics Physics {
                density -1
                mass 0.02
                centerOfMass [
                  0 0 0
                ]
                inertiaMatrix [
                  2.7e-06 2.7e-06 1e-06
                  0 0 0
                ]
              }
            }
          }
          HingeJoint {
            jointParameters HingeJointParameters {
              axis -0.5 0 -0.866025
              anchor 0.020785 0.013 -0.012
              dampingConstant 0.01
              staticFriction 0.1
            }
            device [
              RotationalMotor {
                name "wheel120-roller1"
                maxTorque 10000
              }
              PositionSensor {
                name "wheel120-roller1_sensor"
              }
            ]
            endPoint Solid {
              translation 0.020785 0.013 -0.012
              rotation 0 1 0 2.094395
              children [
                Pose {
                  translation 0 0 -0.024
                  children [
                    Shape {
                      appearance USE black
                      geometry USE roller
                    }
                  ]
                }
              ]
              name "roller-1-1"
              boundingObject Pose {
                translation 0 0 -0.024
                children [
                  USE roller
                ]
              }
              physics Physics {
                density -1
                mass 0.02
                centerOfMass [
                  0 0 0
                ]
                inertiaMatrix [
                  2.7e-06 2.7e-06 1e-06
                  0 0 0
                ]
              }
            }
          }
          HingeJoint {
            jointParameters HingeJointParameters {
              axis -0.5 0 0.866025
              anchor -0.020785 0.013 -0.012
              dampingConstant 0.01
              staticFriction 0.1
            }
            device [
              RotationalMotor {
                name "wheel120-roller2"
                maxTorque 10000
              }
              PositionSensor {
                name "wheel120-roller2_sensor"
              }
            ]
            endPoint Solid {
              translation -0.020785 0.013 -0.012
              rotation 0 1 0 4.18879
              children [
                Pose {
                  translation 0 0 -0.024
                  children [
                    Shape {
                      appearance USE black
                      geometry USE roller
                    }
                  ]
                }
              ]
              name "roller-1-2"
              boundingObject Pose {
                translation 0 0 -0.024
                children [
                  USE roller
                ]
              }
              physics Physics {
                density -1
                mass 0.02
                centerOfMass [
                  0 0 0
                ]
                inertiaMatrix [
                  2.7e-06 2.7e-06 1e-06
                  0 0 0
                ]
              }
            }
          }
          HingeJoint {
            jointParameters HingeJointParameters {
              axis 0.5 0 -0.866025
              anchor 0.020785 -0.013 0.012
              dampingConstant 0.01
              staticFriction 0.1
            }
            device [
              RotationalMotor {
                name "wheel120-roller3"
                maxTorque 10000
              }
              PositionSensor {
                name "wheel120-roller3_sensor"
              }
            ]
            endPoint Solid {
              translation 0.020785 -0.013 0.012
              rotation 0 1 0 1.047198
              children [
                Pose {
                  translation 0 0 -0.024
                  children [
                    Shape {
                      appearance USE black
                      geometry USE roller
                    }
                  ]
                }
              ]
              name "roller-1-3"
              boundingObject Pose {
                translation 0 0 -0.024
                children [
                  USE roller
                ]
              }
              physics Physics {
                density -1
                mass 0.02
                centerOfMass [
                  0 0 0
                ]
                inertiaMatrix [
                  2.7e-06 2.7e-06 1e-06
                  0 0 0
                ]
              }
            }
          }
          HingeJoint {
            jointParameters HingeJointParameters {
              axis -1 0 0
              anchor 0 -0.013 -0.024
              dampingConstant 0.01
              staticFriction 0.1
            }
            device [
              RotationalMotor {
                name "wheel120-roller4"
                maxTorque 10000
              }
              PositionSensor {
                name "wheel120-roller4_sensor"
              }
            ]
            endPoint Solid {
              translation 0 -0.013 -0.024
              rotation 0 1 0 3.141593
              children [
                Pose {
                  translation 0 0 -0.024
                  children [
                    Shape {
                      appearance USE black
                      geometry USE roller
                    }
                  ]
                }
              ]
              name "roller-1-4"
              boundingObject Pose {
                translation 0 0 -0.024
                children [
                  USE roller
                ]
              }
              physics Physics {
                density -1
                mass 0.02
                centerOfMass [
                  0 0 0
                ]
                inertiaMatrix [
                  2.7e-06 2.7e-06 1e-06
                  0 0 0
                ]
              }
            }
          }
          HingeJoint {
            jointParameters HingeJointParameters {
              axis 0.5 0 0.866025
              anchor -0.020785 -0.013 0.012
              dampingConstant 0.01
              staticFriction 0.1
            }
            device [
              RotationalMotor {
                name "wheel120-roller5"
                maxTorque 10000
              }
              PositionSensor {
                name "wheel120-roller5_sensor"
              }
            ]
            endPoint Solid {
              translation -0.020785 -0.013 0.012
              rotation 0 1 0 5.235988
              children [
                Pose {
                  translation 0 0 -0.024
                  children [
                    Shape {
                      appearance USE black
                      geometry USE roller
                    }
                  ]
                }
              ]
              name "roller-1-5"
              boundingObject Pose {
                translation 0 0 -0.024
                children [
                  USE roller
                ]
              }
              physics Physics {
                density -1
                mass 0.02
                centerOfMass [
                  0 0 0
                ]
                inertiaMatrix [
                  2.7e-06 2.7e-06 1e-06
                  0 0 0
                ]
              }
            }
          }
        ]
        name "wheel-frame120"
        boundingObject USE wheel_frame
        physics Physics {
          density -1
          mass 0.5
          centerOfMass [
            0 0 0
          ]
          inertiaMatrix [
            0.00017 0.00018 0.00017
            0 0 0
          ]
        }
      }
    }
    HingeJoint {
      jointParameters HingeJointParameters {
        axis -0.866025 0.5 0
        anchor -0.086603 0.05 0
      }
      device [
        RotationalMotor {
          name "wheel-frame240"
          maxVelocity 100
          maxTorque 100
        }
        PositionSensor {
          name "wheel-frame240_sensor"
        }
      ]
      endPoint Solid {
        translation -0.086603 0.05 0
        rotation 0 0 1 4.18879
        children [
          Shape {
            appearance USE grey
            geometry USE wheel_frame
          }
          HingeJoint {
            jointParameters HingeJointParameters {
              anchor 0 0.013 0.024
              dampingConstant 0.01
              staticFriction 0.1
            }
            device [
              RotationalMotor {
                name "wheel240-roller0"
                maxTorque 10000
              }
              PositionSensor {
                name "wheel240-roller0_sensor"
              }
            ]
            endPoint Solid {
              translation 0 0.013 0.024
              children [
                Pose {
                  translation 0 0 -0.024
                  children [
                    Shape {
                      appearance USE black
                      geometry USE roller
                    }
                  ]
                }
              ]
              name "roller-2-0"
              boundingObject Pose {
                translation 0 0 -0.024
                children [
                  USE roller
                ]
              }
              physics Physics {
                density -1
                mass 0.02
                centerOfMass [
                  0 0 0
                ]
                inertiaMatrix [
                  2.7e-06 2.7e-06 1e-06
                  0 0 0
                ]
              }
            }
          }
          HingeJoint {
            jointParameters HingeJointParameters {
              axis -0.5 0 -0.866025
              anchor 0.020785 0.013 -0.012
              dampingConstant 0.01
              staticFriction 0.1
            }
            device [
              RotationalMotor {
                name "wheel240-roller1"
                maxTorque 10000
              }
              PositionSensor {
                name "wheel240-roller1_sensor"
              }
            ]
            endPoint Solid {
              translation 0.020785 0.013 -0.012
              rotation 0 1 0 2.094395
              children [
                Pose {
                  translation 0 0 -0.024
                  children [
                    Shape {
                      appearance USE black
                      geometry USE roller
                    }
                  ]
                }
              ]
              name "roller-2-1"
              boundingObject Pose {
                translation 0 0 -0.024
                children [
                  USE roller
                ]
              }
              physics Physics {
                density -1
                mass 0.02
                centerOfMass [
                  0 0 0
                ]
                inertiaMatrix [
                  2.7e-06 2.7e-06 1e-06
                  0 0 0
                ]
              }
            }
          }
          HingeJoint {
            jointParameters HingeJointParameters {
              axis -0.5 0 0.866025
              anchor -0.020785 0.013 -0.012
              dampingConstant 0.01
              staticFriction 0.1
            }
            device [
              RotationalMotor {
                name "wheel240-roller2"
                maxTorque 10000
              }
              PositionSensor {
                name "wheel240-roller2_sensor"
              }
            ]
            endPoint Solid {
              translation -0.020785 0.013 -0.012
              rotation 0 1 0 4.18879
              children [
                Pose {
                  translation 0 0 -0.024
                  children [
                    Shape {
                      appearance USE black
                      geometry USE roller
                    }
                  ]
                }
              ]
              name "roller-2-2"
              boundingObject Pose {
                translation 0 0 -0.024
                children [
                  USE roller
                ]
              }
              physics Physics {
                density -1
                mass 0.02
                centerOfMass [
                  0 0 0
                ]
                inertiaMatrix [
                  2.7e-06 2.7e-06 1e-06
                  0 0 0
                ]
              }
            }
          }
          HingeJoint {
            jointParameters HingeJointParameters {
              axis 0.5 0 -0.866025
              anchor 0.020785 -0.013 0.012
              dampingConstant 0.01
              staticFriction 0.1
            }
            device [
              RotationalMotor {
                name "wheel240-roller3"
                maxTorque 10000
              }
              PositionSensor {
                name "wheel240-roller3_sensor"
              }
            ]
            endPoint Solid {
              translation 0.020785 -0.013 0.012
              rotation 0 1 0 1.047198
              children [
                Pose {
                  translation 0 0 -0.024
                  children [
                    Shape {
                      appearance USE black
                      geometry USE roller
                    }
                  ]
                }
              ]
              name "roller-2-3"
              boundingObject Pose {
                translation 0 0 -0.024
                children [
                  USE roller
                ]
              }
              physics Physics {
                density -1
                mass 0.02
                centerOfMass [
                  0 0 0
                ]
                inertiaMatrix [
                  2.7e-06 2.7e-06 1e-06
                  0 0 0
                ]
              }
            }
          }
          HingeJoint {
            jointParameters HingeJointParameters {
              axis -1 0 0
              anchor 0 -0.013 -0.024
              dampingConstant 0.01
              staticFriction 0.1
            }
            device [
              RotationalMotor {
                name "wheel240-roller4"
                maxTorque 10000
              }
              PositionSensor {
                name "wheel240-roller4_sensor"
              }
            ]
            endPoint Solid {
              translation 0 -0.013 -0.024
              rotation 0 1 0 3.141593
              children [
                Pose {
                  translation 0 0 -0.024
                  children [
                    Shape {
                      appearance USE black
                      geometry USE roller
                    }
                  ]
                }
              ]
              name "roller-2-4"
              boundingObject Pose {
                translation 0 0 -0.024
                children [
                  USE roller
                ]
              }
              physics Physics {
                density -1
                mass 0.02
                centerOfMass [
                  0 0 0
                ]
                inertiaMatrix [
                  2.7e-06 2.7e-06 1e-06
                  0 0 0
                ]
              }
            }
          }
          HingeJoint {
            jointParameters HingeJointParameters {
              axis 0.5 0 0.866025
              anchor -0.020785 -0.013 0.012
              dampingConstant 0.01
              staticFriction 0.1
            }
            device [
              RotationalMotor {
                name "wheel240-roller5"
                maxTorque 10000
              }
              PositionSensor {
                name "wheel240-roller5_sensor"
              }
            ]
            endPoint Solid {
              translation -0.020785 -0.013 0.012
              rotation 0 1 0 5.235988
              children [
                Pose {
                  translation 0 0 -0.024
                  children [
                    Shape {
                      appearance USE black
                      geometry USE roller
                    }
                  ]
                }
              ]
              name "roller-2-5"
              boundingObject Pose {
                translation 0 0 -0.024
                children [
                  USE roller
                ]
              }
              physics Physics {
                density -1
                mass 0.02
                centerOfMass [
                  0 0 0
                ]
                inertiaMatrix [
                  2.7e-06 2.7e-06 1e-06
                  0 0 0
                ]
              }
            }
          }
        ]
        name "wheel-frame240"
        boundingObject USE wheel_frame
        physics Physics {
          density -1
          mass 0.5
          centerOfMass [
            0 0 0
          ]
          inertiaMatrix [
            0.00017 0.00018 0.00017
            0 0 0
          ]
        }
      }
    }
  ]
  name "omni-1"
  boundingObject USE base_link
  physics Physics {
    density -1
    mass 4.8
    centerOfMass [
      0 0 3.8
    ]
  }
  controller "<extern>"
}
