<?xml version="1.0" ?>
<!-- =================================================================================== -->
<!-- |    This document was autogenerated by xacro from omni_1.urdf.xacro              | -->
<!-- |    EDITING THIS FILE BY HAND IS NOT RECOMMENDED                                 | -->
<!-- =================================================================================== -->
<robot name="omni_robot">
  <!-- MATERIAL DEFINITIONS -->
  <material name="white">
    <color rgba="1 1 1 1"/>
    <!-- White -->
  </material>
  <material name="copper">
    <color rgba="0.72 0.45 0.20 1"/>
    <!-- Copper -->
  </material>
  <!-- BASE LINK (CYLINDER) -->
  <link name="base_link">
    <visual>
      <origin rpy="0 0 0" xyz="0 0 0"/>
      <geometry>
        <cylinder length="0.064" radius="0.11"/>
        <!-- 220mm dia, 64mm height -->
      </geometry>
      <material name="white"/>
    </visual>
    <collision>
      <geometry>
        <cylinder length="0.064" radius="0.11"/>
      </geometry>
    </collision>
    <inertial>
      <mass value="1.0"/>
      <inertia ixx="0.001" ixy="0" ixz="0" iyy="0.001" iyz="0" izz="0.001"/>
    </inertial>
  </link>
  <!-- Main Wheel -->
  <link name="wheel_0">
    <visual>
      <origin rpy="0 0 0" xyz="0 0 0"/>
      <!-- Wheel rotation -->
      <geometry>
        <cylinder length="0.02" radius="0.032"/>
        <!-- 64mm dia, 20mm thick -->
      </geometry>
      <material name="copper"/>
    </visual>
    <collision>
      <geometry>
        <cylinder length="0.02" radius="0.04"/>
      </geometry>
    </collision>
    <inertial>
      <mass value="0.15"/>
      <inertia ixx="0.0002" ixy="0" ixz="0" iyy="0.0002" iyz="0" izz="0.0002"/>
    </inertial>
  </link>
  <!-- Joint to Base -->
  <joint name="wheel_0_joint" type="continuous">
    <parent link="base_link"/>
    <child link="wheel_0"/>
    <origin rpy="0 1.5708 0" xyz="0.125 0 -0.01"/>
    <axis xyz="0 0 1"/>
    <limit effort="10.0" velocity="10.0"/>
    <dynamics damping="0.1" friction="0.01"/>
  </joint>
  <!-- Roller 0: 0°, inside -->
  <link name="wheel_0_roller_0">
    <visual>
      <origin rpy="0 0 0" xyz="0 0 0"/>
      <geometry>
        <cylinder length="0.012" radius="0.006"/>
      </geometry>
      <material name="white"/>
    </visual>
    <collision>
      <geometry>
        <cylinder length="0.012" radius="0.006"/>
      </geometry>
    </collision>
    <inertial>
      <mass value="0.01"/>
      <inertia ixx="0.00001" ixy="0" ixz="0" iyy="0.00001" iyz="0" izz="0.00001"/>
    </inertial>
  </link>
  <joint name="wheel_0_roller_0_joint" type="continuous">
    <parent link="wheel_0"/>
    <child link="wheel_0_roller_0"/>
    <origin rpy="0 1.5708 0" xyz="0 0.04 -0.006"/>
    <axis xyz="0 0 1"/>
    <!-- Roller spins around its own axis -->
    <limit effort="0.0" velocity="0.0"/>
    <dynamics damping="0.01" friction="0.01"/>
  </joint>
  <!-- Roller 1: 22.5°, outnside -->
  <link name="wheel_0_roller_1">
    <visual>
      <origin rpy="0 0 0" xyz="0 0 0"/>
      <geometry>
        <cylinder length="0.012" radius="0.006"/>
      </geometry>
      <material name="white"/>
    </visual>
    <collision>
      <geometry>
        <cylinder length="0.012" radius="0.006"/>
      </geometry>
    </collision>
    <inertial>
      <mass value="0.01"/>
      <inertia ixx="0.00001" ixy="0" ixz="0" iyy="0.00001" iyz="0" izz="0.00001"/>
    </inertial>
  </link>
  <joint name="wheel_0_roller_1_joint" type="continuous">
    <parent link="wheel_0"/>
    <child link="wheel_0_roller_1"/>
    <origin rpy="0.3927 1.5708 0" xyz="0.015307200000000002 0.0369552 0.006"/>
    <axis xyz="0 0 1"/>
    <!-- Roller spins around its own axis -->
    <limit effort="0.0" velocity="0.0"/>
    <dynamics damping="0.01" friction="0.01"/>
  </joint>
  <!-- Roller 2: 45°, inside -->
  <link name="wheel_0_roller_2">
    <visual>
      <origin rpy="0 0 0" xyz="0 0 0"/>
      <geometry>
        <cylinder length="0.012" radius="0.006"/>
      </geometry>
      <material name="white"/>
    </visual>
    <collision>
      <geometry>
        <cylinder length="0.012" radius="0.006"/>
      </geometry>
    </collision>
    <inertial>
      <mass value="0.01"/>
      <inertia ixx="0.00001" ixy="0" ixz="0" iyy="0.00001" iyz="0" izz="0.00001"/>
    </inertial>
  </link>
  <joint name="wheel_0_roller_2_joint" type="continuous">
    <parent link="wheel_0"/>
    <child link="wheel_0_roller_2"/>
    <origin rpy="0.7854 1.5708 0" xyz="0.028284 0.028284 -0.006"/>
    <axis xyz="0 0 1"/>
    <limit effort="0.0" velocity="0.0"/>
    <dynamics damping="0.01" friction="0.01"/>
  </joint>
  <!-- Roller 3: 67.5°, outside -->
  <link name="wheel_0_roller_3">
    <visual>
      <origin rpy="0 0 0" xyz="0 0 0"/>
      <geometry>
        <cylinder length="0.012" radius="0.006"/>
      </geometry>
      <material name="white"/>
    </visual>
    <collision>
      <geometry>
        <cylinder length="0.012" radius="0.006"/>
      </geometry>
    </collision>
    <inertial>
      <mass value="0.01"/>
      <inertia ixx="0.00001" ixy="0" ixz="0" iyy="0.00001" iyz="0" izz="0.00001"/>
    </inertial>
  </link>
  <joint name="wheel_0_roller_3_joint" type="continuous">
    <parent link="wheel_0"/>
    <child link="wheel_0_roller_3"/>
    <origin rpy="1.1781 1.5708 0" xyz="0.0369552 0.015307200000000002 0.006"/>
    <axis xyz="0 0 1"/>
    <limit effort="0.0" velocity="0.0"/>
    <dynamics damping="0.01" friction="0.01"/>
  </joint>
  <!-- Roller 4: 90°, inside -->
  <link name="wheel_0_roller_4">
    <visual>
      <origin rpy="0 0 0" xyz="0 0 0"/>
      <geometry>
        <cylinder length="0.012" radius="0.006"/>
      </geometry>
      <material name="white"/>
    </visual>
    <collision>
      <geometry>
        <cylinder length="0.012" radius="0.006"/>
      </geometry>
    </collision>
    <inertial>
      <mass value="0.01"/>
      <inertia ixx="0.00001" ixy="0" ixz="0" iyy="0.00001" iyz="0" izz="0.00001"/>
    </inertial>
  </link>
  <joint name="wheel_0_roller_4_joint" type="continuous">
    <parent link="wheel_0"/>
    <child link="wheel_0_roller_4"/>
    <origin rpy="1.5708 1.5708 0" xyz="0.04 0 -0.006"/>
    <axis xyz="0 0 1"/>
    <limit effort="0.0" velocity="0.0"/>
    <dynamics damping="0.01" friction="0.01"/>
  </joint>
  <!-- Roller 5: 112.5°, outside -->
  <link name="wheel_0_roller_5">
    <visual>
      <origin rpy="0 0 0" xyz="0 0 0"/>
      <geometry>
        <cylinder length="0.012" radius="0.006"/>
      </geometry>
      <material name="white"/>
    </visual>
    <collision>
      <geometry>
        <cylinder length="0.012" radius="0.006"/>
      </geometry>
    </collision>
    <inertial>
      <mass value="0.01"/>
      <inertia ixx="0.00001" ixy="0" ixz="0" iyy="0.00001" iyz="0" izz="0.00001"/>
    </inertial>
  </link>
  <joint name="wheel_0_roller_5_joint" type="continuous">
    <parent link="wheel_0"/>
    <child link="wheel_0_roller_5"/>
    <origin rpy="1.9635 1.5708 0" xyz="0.0369552 -0.015307200000000002 0.006"/>
    <axis xyz="0 0 1"/>
    <limit effort="0.0" velocity="0.0"/>
    <dynamics damping="0.01" friction="0.01"/>
  </joint>
  <!-- Roller 6: 135°, inside -->
  <link name="wheel_0_roller_6">
    <visual>
      <origin rpy="0 0 0" xyz="0 0 0"/>
      <geometry>
        <cylinder length="0.012" radius="0.006"/>
      </geometry>
      <material name="white"/>
    </visual>
    <collision>
      <geometry>
        <cylinder length="0.012" radius="0.006"/>
      </geometry>
    </collision>
    <inertial>
      <mass value="0.01"/>
      <inertia ixx="0.00001" ixy="0" ixz="0" iyy="0.00001" iyz="0" izz="0.00001"/>
    </inertial>
  </link>
  <joint name="wheel_0_roller_6_joint" type="continuous">
    <parent link="wheel_0"/>
    <child link="wheel_0_roller_6"/>
    <origin rpy="2.3562 1.5708 0" xyz="0.028284 -0.028284 -0.006"/>
    <axis xyz="0 0 1"/>
    <limit effort="0.0" velocity="0.0"/>
    <dynamics damping="0.01" friction="0.01"/>
  </joint>
  <!-- Roller 7: 157.5°, outside -->
  <link name="wheel_0_roller_7">
    <visual>
      <origin rpy="0 0 0" xyz="0 0 0"/>
      <geometry>
        <cylinder length="0.012" radius="0.006"/>
      </geometry>
      <material name="white"/>
    </visual>
    <collision>
      <geometry>
        <cylinder length="0.012" radius="0.006"/>
      </geometry>
    </collision>
    <inertial>
      <mass value="0.01"/>
      <inertia ixx="0.00001" ixy="0" ixz="0" iyy="0.00001" iyz="0" izz="0.00001"/>
    </inertial>
  </link>
  <joint name="wheel_0_roller_7_joint" type="continuous">
    <parent link="wheel_0"/>
    <child link="wheel_0_roller_7"/>
    <origin rpy="2.7489 1.5708 0" xyz="0.015307200000000002 -0.0369552 0.006"/>
    <axis xyz="0 0 1"/>
    <limit effort="0.0" velocity="0.0"/>
    <dynamics damping="0.01" friction="0.01"/>
  </joint>
  <!-- Roller 8: 180°, inside -->
  <link name="wheel_0_roller_8">
    <visual>
      <origin rpy="0 0 0" xyz="0 0 0"/>
      <geometry>
        <cylinder length="0.012" radius="0.006"/>
      </geometry>
      <material name="white"/>
    </visual>
    <collision>
      <geometry>
        <cylinder length="0.012" radius="0.006"/>
      </geometry>
    </collision>
    <inertial>
      <mass value="0.01"/>
      <inertia ixx="0.00001" ixy="0" ixz="0" iyy="0.00001" iyz="0" izz="0.00001"/>
    </inertial>
  </link>
  <joint name="wheel_0_roller_8_joint" type="continuous">
    <parent link="wheel_0"/>
    <child link="wheel_0_roller_8"/>
    <origin rpy="0 1.5708 0" xyz="0 -0.04 -0.006"/>
    <axis xyz="0 0 1"/>
    <limit effort="0.0" velocity="0.0"/>
    <dynamics damping="0.01" friction="0.01"/>
  </joint>
  <!-- Roller 9: 202.5°, outside -->
  <link name="wheel_0_roller_9">
    <visual>
      <origin rpy="0 0 0" xyz="0 0 0"/>
      <geometry>
        <cylinder length="0.012" radius="0.006"/>
      </geometry>
      <material name="white"/>
    </visual>
    <collision>
      <geometry>
        <cylinder length="0.012" radius="0.006"/>
      </geometry>
    </collision>
    <inertial>
      <mass value="0.01"/>
      <inertia ixx="0.00001" ixy="0" ixz="0" iyy="0.00001" iyz="0" izz="0.00001"/>
    </inertial>
  </link>
  <joint name="wheel_0_roller_9_joint" type="continuous">
    <parent link="wheel_0"/>
    <child link="wheel_0_roller_9"/>
    <origin rpy="0.3927 1.5708 0" xyz="-0.015307200000000002 -0.0369552 0.006"/>
    <axis xyz="0 0 1"/>
    <limit effort="0.0" velocity="0.0"/>
    <dynamics damping="0.01" friction="0.01"/>
  </joint>
  <!-- Roller 10: 225°, inside -->
  <link name="wheel_0_roller_10">
    <visual>
      <origin rpy="0 0 0" xyz="0 0 0"/>
      <geometry>
        <cylinder length="0.012" radius="0.006"/>
      </geometry>
      <material name="white"/>
    </visual>
    <collision>
      <geometry>
        <cylinder length="0.012" radius="0.006"/>
      </geometry>
    </collision>
    <inertial>
      <mass value="0.01"/>
      <inertia ixx="0.00001" ixy="0" ixz="0" iyy="0.00001" iyz="0" izz="0.00001"/>
    </inertial>
  </link>
  <joint name="wheel_0_roller_10_joint" type="continuous">
    <parent link="wheel_0"/>
    <child link="wheel_0_roller_10"/>
    <origin rpy="0.7854 1.5708 0" xyz="-0.028284 -0.028284 -0.006"/>
    <axis xyz="0 0 1"/>
    <limit effort="0.0" velocity="0.0"/>
    <dynamics damping="0.01" friction="0.01"/>
  </joint>
  <!-- Roller 11: 247.5°, outside -->
  <link name="wheel_0_roller_11">
    <visual>
      <origin rpy="0 0 0" xyz="0 0 0"/>
      <geometry>
        <cylinder length="0.012" radius="0.006"/>
      </geometry>
      <material name="white"/>
    </visual>
    <collision>
      <geometry>
        <cylinder length="0.012" radius="0.006"/>
      </geometry>
    </collision>
    <inertial>
      <mass value="0.01"/>
      <inertia ixx="0.00001" ixy="0" ixz="0" iyy="0.00001" iyz="0" izz="0.00001"/>
    </inertial>
  </link>
  <joint name="wheel_0_roller_11_joint" type="continuous">
    <parent link="wheel_0"/>
    <child link="wheel_0_roller_11"/>
    <origin rpy="1.1781 1.5708 0" xyz="-0.0369552 -0.015307200000000002 0.006"/>
    <axis xyz="0 0 1"/>
    <limit effort="0.0" velocity="0.0"/>
    <dynamics damping="0.01" friction="0.01"/>
  </joint>
  <!-- Roller 12: 270°, inside -->
  <link name="wheel_0_roller_12">
    <visual>
      <origin rpy="0 0 0" xyz="0 0 0"/>
      <geometry>
        <cylinder length="0.012" radius="0.006"/>
      </geometry>
      <material name="white"/>
    </visual>
    <collision>
      <geometry>
        <cylinder length="0.012" radius="0.006"/>
      </geometry>
    </collision>
    <inertial>
      <mass value="0.01"/>
      <inertia ixx="0.00001" ixy="0" ixz="0" iyy="0.00001" iyz="0" izz="0.00001"/>
    </inertial>
  </link>
  <joint name="wheel_0_roller_12_joint" type="continuous">
    <parent link="wheel_0"/>
    <child link="wheel_0_roller_12"/>
    <origin rpy="1.5708 1.5708 0" xyz="-0.04 0 -0.006"/>
    <axis xyz="0 0 1"/>
    <limit effort="0.0" velocity="0.0"/>
    <dynamics damping="0.01" friction="0.01"/>
  </joint>
  <!-- Roller 13: 292.5°, outside -->
  <link name="wheel_0_roller_13">
    <visual>
      <origin rpy="0 0 0" xyz="0 0 0"/>
      <geometry>
        <cylinder length="0.012" radius="0.006"/>
      </geometry>
      <material name="white"/>
    </visual>
    <collision>
      <geometry>
        <cylinder length="0.012" radius="0.006"/>
      </geometry>
    </collision>
    <inertial>
      <mass value="0.01"/>
      <inertia ixx="0.00001" ixy="0" ixz="0" iyy="0.00001" iyz="0" izz="0.00001"/>
    </inertial>
  </link>
  <joint name="wheel_0_roller_13_joint" type="continuous">
    <parent link="wheel_0"/>
    <child link="wheel_0_roller_13"/>
    <origin rpy="1.9635 1.5708 0" xyz="-0.0369552 0.015307200000000002 0.006"/>
    <axis xyz="0 0 1"/>
    <limit effort="0.0" velocity="0.0"/>
    <dynamics damping="0.01" friction="0.01"/>
  </joint>
  <!-- Roller 14: 315°, inside -->
  <link name="wheel_0_roller_14">
    <visual>
      <origin rpy="0 0 0" xyz="0 0 0"/>
      <geometry>
        <cylinder length="0.012" radius="0.006"/>
      </geometry>
      <material name="white"/>
    </visual>
    <collision>
      <geometry>
        <cylinder length="0.012" radius="0.006"/>
      </geometry>
    </collision>
    <inertial>
      <mass value="0.01"/>
      <inertia ixx="0.00001" ixy="0" ixz="0" iyy="0.00001" iyz="0" izz="0.00001"/>
    </inertial>
  </link>
  <joint name="wheel_0_roller_14_joint" type="continuous">
    <parent link="wheel_0"/>
    <child link="wheel_0_roller_14"/>
    <origin rpy="2.3562 1.5708 0" xyz="-0.028284 0.028284 -0.006"/>
    <axis xyz="0 0 1"/>
    <limit effort="0.0" velocity="0.0"/>
    <dynamics damping="0.01" friction="0.01"/>
  </joint>
  <!-- Roller 15: 337.5°, outside -->
  <link name="wheel_0_roller_15">
    <visual>
      <origin rpy="0 0 0" xyz="0 0 0"/>
      <geometry>
        <cylinder length="0.012" radius="0.006"/>
      </geometry>
      <material name="white"/>
    </visual>
    <collision>
      <geometry>
        <cylinder length="0.012" radius="0.006"/>
      </geometry>
    </collision>
    <inertial>
      <mass value="0.01"/>
      <inertia ixx="0.00001" ixy="0" ixz="0" iyy="0.00001" iyz="0" izz="0.00001"/>
    </inertial>
  </link>
  <joint name="wheel_0_roller_15_joint" type="continuous">
    <parent link="wheel_0"/>
    <child link="wheel_0_roller_15"/>
    <origin rpy="2.7489 1.5708 0" xyz="-0.015307200000000002 0.0369552 0.006"/>
    <axis xyz="0 0 1"/>
    <limit effort="0.0" velocity="0.0"/>
    <dynamics damping="0.01" friction="0.01"/>
  </joint>
  <!-- Main Wheel -->
  <link name="wheel_120">
    <visual>
      <origin rpy="0 0 0" xyz="0 0 0"/>
      <!-- Wheel rotation -->
      <geometry>
        <cylinder length="0.02" radius="0.032"/>
        <!-- 64mm dia, 20mm thick -->
      </geometry>
      <material name="copper"/>
    </visual>
    <collision>
      <geometry>
        <cylinder length="0.02" radius="0.04"/>
      </geometry>
    </collision>
    <inertial>
      <mass value="0.15"/>
      <inertia ixx="0.0002" ixy="0" ixz="0" iyy="0.0002" iyz="0" izz="0.0002"/>
    </inertial>
  </link>
  <!-- Joint to Base -->
  <joint name="wheel_120_joint" type="continuous">
    <parent link="base_link"/>
    <child link="wheel_120"/>
    <origin rpy="0 1.5708 2.0944" xyz="-0.0625 0.10825 -0.01"/>
    <axis xyz="0 0 1"/>
    <limit effort="10.0" velocity="10.0"/>
    <dynamics damping="0.1" friction="0.01"/>
  </joint>
  <!-- Roller 0: 0°, inside -->
  <link name="wheel_120_roller_0">
    <visual>
      <origin rpy="0 0 0" xyz="0 0 0"/>
      <geometry>
        <cylinder length="0.012" radius="0.006"/>
      </geometry>
      <material name="white"/>
    </visual>
    <collision>
      <geometry>
        <cylinder length="0.012" radius="0.006"/>
      </geometry>
    </collision>
    <inertial>
      <mass value="0.01"/>
      <inertia ixx="0.00001" ixy="0" ixz="0" iyy="0.00001" iyz="0" izz="0.00001"/>
    </inertial>
  </link>
  <joint name="wheel_120_roller_0_joint" type="continuous">
    <parent link="wheel_120"/>
    <child link="wheel_120_roller_0"/>
    <origin rpy="0 1.5708 0" xyz="0 0.04 -0.006"/>
    <axis xyz="0 0 1"/>
    <!-- Roller spins around its own axis -->
    <limit effort="0.0" velocity="0.0"/>
    <dynamics damping="0.01" friction="0.01"/>
  </joint>
  <!-- Roller 1: 22.5°, outnside -->
  <link name="wheel_120_roller_1">
    <visual>
      <origin rpy="0 0 0" xyz="0 0 0"/>
      <geometry>
        <cylinder length="0.012" radius="0.006"/>
      </geometry>
      <material name="white"/>
    </visual>
    <collision>
      <geometry>
        <cylinder length="0.012" radius="0.006"/>
      </geometry>
    </collision>
    <inertial>
      <mass value="0.01"/>
      <inertia ixx="0.00001" ixy="0" ixz="0" iyy="0.00001" iyz="0" izz="0.00001"/>
    </inertial>
  </link>
  <joint name="wheel_120_roller_1_joint" type="continuous">
    <parent link="wheel_120"/>
    <child link="wheel_120_roller_1"/>
    <origin rpy="0.3927 1.5708 0" xyz="0.015307200000000002 0.0369552 0.006"/>
    <axis xyz="0 0 1"/>
    <!-- Roller spins around its own axis -->
    <limit effort="0.0" velocity="0.0"/>
    <dynamics damping="0.01" friction="0.01"/>
  </joint>
  <!-- Roller 2: 45°, inside -->
  <link name="wheel_120_roller_2">
    <visual>
      <origin rpy="0 0 0" xyz="0 0 0"/>
      <geometry>
        <cylinder length="0.012" radius="0.006"/>
      </geometry>
      <material name="white"/>
    </visual>
    <collision>
      <geometry>
        <cylinder length="0.012" radius="0.006"/>
      </geometry>
    </collision>
    <inertial>
      <mass value="0.01"/>
      <inertia ixx="0.00001" ixy="0" ixz="0" iyy="0.00001" iyz="0" izz="0.00001"/>
    </inertial>
  </link>
  <joint name="wheel_120_roller_2_joint" type="continuous">
    <parent link="wheel_120"/>
    <child link="wheel_120_roller_2"/>
    <origin rpy="0.7854 1.5708 0" xyz="0.028284 0.028284 -0.006"/>
    <axis xyz="0 0 1"/>
    <limit effort="0.0" velocity="0.0"/>
    <dynamics damping="0.01" friction="0.01"/>
  </joint>
  <!-- Roller 3: 67.5°, outside -->
  <link name="wheel_120_roller_3">
    <visual>
      <origin rpy="0 0 0" xyz="0 0 0"/>
      <geometry>
        <cylinder length="0.012" radius="0.006"/>
      </geometry>
      <material name="white"/>
    </visual>
    <collision>
      <geometry>
        <cylinder length="0.012" radius="0.006"/>
      </geometry>
    </collision>
    <inertial>
      <mass value="0.01"/>
      <inertia ixx="0.00001" ixy="0" ixz="0" iyy="0.00001" iyz="0" izz="0.00001"/>
    </inertial>
  </link>
  <joint name="wheel_120_roller_3_joint" type="continuous">
    <parent link="wheel_120"/>
    <child link="wheel_120_roller_3"/>
    <origin rpy="1.1781 1.5708 0" xyz="0.0369552 0.015307200000000002 0.006"/>
    <axis xyz="0 0 1"/>
    <limit effort="0.0" velocity="0.0"/>
    <dynamics damping="0.01" friction="0.01"/>
  </joint>
  <!-- Roller 4: 90°, inside -->
  <link name="wheel_120_roller_4">
    <visual>
      <origin rpy="0 0 0" xyz="0 0 0"/>
      <geometry>
        <cylinder length="0.012" radius="0.006"/>
      </geometry>
      <material name="white"/>
    </visual>
    <collision>
      <geometry>
        <cylinder length="0.012" radius="0.006"/>
      </geometry>
    </collision>
    <inertial>
      <mass value="0.01"/>
      <inertia ixx="0.00001" ixy="0" ixz="0" iyy="0.00001" iyz="0" izz="0.00001"/>
    </inertial>
  </link>
  <joint name="wheel_120_roller_4_joint" type="continuous">
    <parent link="wheel_120"/>
    <child link="wheel_120_roller_4"/>
    <origin rpy="1.5708 1.5708 0" xyz="0.04 0 -0.006"/>
    <axis xyz="0 0 1"/>
    <limit effort="0.0" velocity="0.0"/>
    <dynamics damping="0.01" friction="0.01"/>
  </joint>
  <!-- Roller 5: 112.5°, outside -->
  <link name="wheel_120_roller_5">
    <visual>
      <origin rpy="0 0 0" xyz="0 0 0"/>
      <geometry>
        <cylinder length="0.012" radius="0.006"/>
      </geometry>
      <material name="white"/>
    </visual>
    <collision>
      <geometry>
        <cylinder length="0.012" radius="0.006"/>
      </geometry>
    </collision>
    <inertial>
      <mass value="0.01"/>
      <inertia ixx="0.00001" ixy="0" ixz="0" iyy="0.00001" iyz="0" izz="0.00001"/>
    </inertial>
  </link>
  <joint name="wheel_120_roller_5_joint" type="continuous">
    <parent link="wheel_120"/>
    <child link="wheel_120_roller_5"/>
    <origin rpy="1.9635 1.5708 0" xyz="0.0369552 -0.015307200000000002 0.006"/>
    <axis xyz="0 0 1"/>
    <limit effort="0.0" velocity="0.0"/>
    <dynamics damping="0.01" friction="0.01"/>
  </joint>
  <!-- Roller 6: 135°, inside -->
  <link name="wheel_120_roller_6">
    <visual>
      <origin rpy="0 0 0" xyz="0 0 0"/>
      <geometry>
        <cylinder length="0.012" radius="0.006"/>
      </geometry>
      <material name="white"/>
    </visual>
    <collision>
      <geometry>
        <cylinder length="0.012" radius="0.006"/>
      </geometry>
    </collision>
    <inertial>
      <mass value="0.01"/>
      <inertia ixx="0.00001" ixy="0" ixz="0" iyy="0.00001" iyz="0" izz="0.00001"/>
    </inertial>
  </link>
  <joint name="wheel_120_roller_6_joint" type="continuous">
    <parent link="wheel_120"/>
    <child link="wheel_120_roller_6"/>
    <origin rpy="2.3562 1.5708 0" xyz="0.028284 -0.028284 -0.006"/>
    <axis xyz="0 0 1"/>
    <limit effort="0.0" velocity="0.0"/>
    <dynamics damping="0.01" friction="0.01"/>
  </joint>
  <!-- Roller 7: 157.5°, outside -->
  <link name="wheel_120_roller_7">
    <visual>
      <origin rpy="0 0 0" xyz="0 0 0"/>
      <geometry>
        <cylinder length="0.012" radius="0.006"/>
      </geometry>
      <material name="white"/>
    </visual>
    <collision>
      <geometry>
        <cylinder length="0.012" radius="0.006"/>
      </geometry>
    </collision>
    <inertial>
      <mass value="0.01"/>
      <inertia ixx="0.00001" ixy="0" ixz="0" iyy="0.00001" iyz="0" izz="0.00001"/>
    </inertial>
  </link>
  <joint name="wheel_120_roller_7_joint" type="continuous">
    <parent link="wheel_120"/>
    <child link="wheel_120_roller_7"/>
    <origin rpy="2.7489 1.5708 0" xyz="0.015307200000000002 -0.0369552 0.006"/>
    <axis xyz="0 0 1"/>
    <limit effort="0.0" velocity="0.0"/>
    <dynamics damping="0.01" friction="0.01"/>
  </joint>
  <!-- Roller 8: 180°, inside -->
  <link name="wheel_120_roller_8">
    <visual>
      <origin rpy="0 0 0" xyz="0 0 0"/>
      <geometry>
        <cylinder length="0.012" radius="0.006"/>
      </geometry>
      <material name="white"/>
    </visual>
    <collision>
      <geometry>
        <cylinder length="0.012" radius="0.006"/>
      </geometry>
    </collision>
    <inertial>
      <mass value="0.01"/>
      <inertia ixx="0.00001" ixy="0" ixz="0" iyy="0.00001" iyz="0" izz="0.00001"/>
    </inertial>
  </link>
  <joint name="wheel_120_roller_8_joint" type="continuous">
    <parent link="wheel_120"/>
    <child link="wheel_120_roller_8"/>
    <origin rpy="0 1.5708 0" xyz="0 -0.04 -0.006"/>
    <axis xyz="0 0 1"/>
    <limit effort="0.0" velocity="0.0"/>
    <dynamics damping="0.01" friction="0.01"/>
  </joint>
  <!-- Roller 9: 202.5°, outside -->
  <link name="wheel_120_roller_9">
    <visual>
      <origin rpy="0 0 0" xyz="0 0 0"/>
      <geometry>
        <cylinder length="0.012" radius="0.006"/>
      </geometry>
      <material name="white"/>
    </visual>
    <collision>
      <geometry>
        <cylinder length="0.012" radius="0.006"/>
      </geometry>
    </collision>
    <inertial>
      <mass value="0.01"/>
      <inertia ixx="0.00001" ixy="0" ixz="0" iyy="0.00001" iyz="0" izz="0.00001"/>
    </inertial>
  </link>
  <joint name="wheel_120_roller_9_joint" type="continuous">
    <parent link="wheel_120"/>
    <child link="wheel_120_roller_9"/>
    <origin rpy="0.3927 1.5708 0" xyz="-0.015307200000000002 -0.0369552 0.006"/>
    <axis xyz="0 0 1"/>
    <limit effort="0.0" velocity="0.0"/>
    <dynamics damping="0.01" friction="0.01"/>
  </joint>
  <!-- Roller 10: 225°, inside -->
  <link name="wheel_120_roller_10">
    <visual>
      <origin rpy="0 0 0" xyz="0 0 0"/>
      <geometry>
        <cylinder length="0.012" radius="0.006"/>
      </geometry>
      <material name="white"/>
    </visual>
    <collision>
      <geometry>
        <cylinder length="0.012" radius="0.006"/>
      </geometry>
    </collision>
    <inertial>
      <mass value="0.01"/>
      <inertia ixx="0.00001" ixy="0" ixz="0" iyy="0.00001" iyz="0" izz="0.00001"/>
    </inertial>
  </link>
  <joint name="wheel_120_roller_10_joint" type="continuous">
    <parent link="wheel_120"/>
    <child link="wheel_120_roller_10"/>
    <origin rpy="0.7854 1.5708 0" xyz="-0.028284 -0.028284 -0.006"/>
    <axis xyz="0 0 1"/>
    <limit effort="0.0" velocity="0.0"/>
    <dynamics damping="0.01" friction="0.01"/>
  </joint>
  <!-- Roller 11: 247.5°, outside -->
  <link name="wheel_120_roller_11">
    <visual>
      <origin rpy="0 0 0" xyz="0 0 0"/>
      <geometry>
        <cylinder length="0.012" radius="0.006"/>
      </geometry>
      <material name="white"/>
    </visual>
    <collision>
      <geometry>
        <cylinder length="0.012" radius="0.006"/>
      </geometry>
    </collision>
    <inertial>
      <mass value="0.01"/>
      <inertia ixx="0.00001" ixy="0" ixz="0" iyy="0.00001" iyz="0" izz="0.00001"/>
    </inertial>
  </link>
  <joint name="wheel_120_roller_11_joint" type="continuous">
    <parent link="wheel_120"/>
    <child link="wheel_120_roller_11"/>
    <origin rpy="1.1781 1.5708 0" xyz="-0.0369552 -0.015307200000000002 0.006"/>
    <axis xyz="0 0 1"/>
    <limit effort="0.0" velocity="0.0"/>
    <dynamics damping="0.01" friction="0.01"/>
  </joint>
  <!-- Roller 12: 270°, inside -->
  <link name="wheel_120_roller_12">
    <visual>
      <origin rpy="0 0 0" xyz="0 0 0"/>
      <geometry>
        <cylinder length="0.012" radius="0.006"/>
      </geometry>
      <material name="white"/>
    </visual>
    <collision>
      <geometry>
        <cylinder length="0.012" radius="0.006"/>
      </geometry>
    </collision>
    <inertial>
      <mass value="0.01"/>
      <inertia ixx="0.00001" ixy="0" ixz="0" iyy="0.00001" iyz="0" izz="0.00001"/>
    </inertial>
  </link>
  <joint name="wheel_120_roller_12_joint" type="continuous">
    <parent link="wheel_120"/>
    <child link="wheel_120_roller_12"/>
    <origin rpy="1.5708 1.5708 0" xyz="-0.04 0 -0.006"/>
    <axis xyz="0 0 1"/>
    <limit effort="0.0" velocity="0.0"/>
    <dynamics damping="0.01" friction="0.01"/>
  </joint>
  <!-- Roller 13: 292.5°, outside -->
  <link name="wheel_120_roller_13">
    <visual>
      <origin rpy="0 0 0" xyz="0 0 0"/>
      <geometry>
        <cylinder length="0.012" radius="0.006"/>
      </geometry>
      <material name="white"/>
    </visual>
    <collision>
      <geometry>
        <cylinder length="0.012" radius="0.006"/>
      </geometry>
    </collision>
    <inertial>
      <mass value="0.01"/>
      <inertia ixx="0.00001" ixy="0" ixz="0" iyy="0.00001" iyz="0" izz="0.00001"/>
    </inertial>
  </link>
  <joint name="wheel_120_roller_13_joint" type="continuous">
    <parent link="wheel_120"/>
    <child link="wheel_120_roller_13"/>
    <origin rpy="1.9635 1.5708 0" xyz="-0.0369552 0.015307200000000002 0.006"/>
    <axis xyz="0 0 1"/>
    <limit effort="0.0" velocity="0.0"/>
    <dynamics damping="0.01" friction="0.01"/>
  </joint>
  <!-- Roller 14: 315°, inside -->
  <link name="wheel_120_roller_14">
    <visual>
      <origin rpy="0 0 0" xyz="0 0 0"/>
      <geometry>
        <cylinder length="0.012" radius="0.006"/>
      </geometry>
      <material name="white"/>
    </visual>
    <collision>
      <geometry>
        <cylinder length="0.012" radius="0.006"/>
      </geometry>
    </collision>
    <inertial>
      <mass value="0.01"/>
      <inertia ixx="0.00001" ixy="0" ixz="0" iyy="0.00001" iyz="0" izz="0.00001"/>
    </inertial>
  </link>
  <joint name="wheel_120_roller_14_joint" type="continuous">
    <parent link="wheel_120"/>
    <child link="wheel_120_roller_14"/>
    <origin rpy="2.3562 1.5708 0" xyz="-0.028284 0.028284 -0.006"/>
    <axis xyz="0 0 1"/>
    <limit effort="0.0" velocity="0.0"/>
    <dynamics damping="0.01" friction="0.01"/>
  </joint>
  <!-- Roller 15: 337.5°, outside -->
  <link name="wheel_120_roller_15">
    <visual>
      <origin rpy="0 0 0" xyz="0 0 0"/>
      <geometry>
        <cylinder length="0.012" radius="0.006"/>
      </geometry>
      <material name="white"/>
    </visual>
    <collision>
      <geometry>
        <cylinder length="0.012" radius="0.006"/>
      </geometry>
    </collision>
    <inertial>
      <mass value="0.01"/>
      <inertia ixx="0.00001" ixy="0" ixz="0" iyy="0.00001" iyz="0" izz="0.00001"/>
    </inertial>
  </link>
  <joint name="wheel_120_roller_15_joint" type="continuous">
    <parent link="wheel_120"/>
    <child link="wheel_120_roller_15"/>
    <origin rpy="2.7489 1.5708 0" xyz="-0.015307200000000002 0.0369552 0.006"/>
    <axis xyz="0 0 1"/>
    <limit effort="0.0" velocity="0.0"/>
    <dynamics damping="0.01" friction="0.01"/>
  </joint>
  <!-- Main Wheel -->
  <link name="wheel_240">
    <visual>
      <origin rpy="0 0 0" xyz="0 0 0"/>
      <!-- Wheel rotation -->
      <geometry>
        <cylinder length="0.02" radius="0.032"/>
        <!-- 64mm dia, 20mm thick -->
      </geometry>
      <material name="copper"/>
    </visual>
    <collision>
      <geometry>
        <cylinder length="0.02" radius="0.04"/>
      </geometry>
    </collision>
    <inertial>
      <mass value="0.15"/>
      <inertia ixx="0.0002" ixy="0" ixz="0" iyy="0.0002" iyz="0" izz="0.0002"/>
    </inertial>
  </link>
  <!-- Joint to Base -->
  <joint name="wheel_240_joint" type="continuous">
    <parent link="base_link"/>
    <child link="wheel_240"/>
    <origin rpy="0 1.5708 -2.0944" xyz="-0.0625 -0.10825 -0.01"/>
    <axis xyz="0 0 1"/>
    <limit effort="10.0" velocity="10.0"/>
    <dynamics damping="0.1" friction="0.01"/>
  </joint>
  <!-- Roller 0: 0°, inside -->
  <link name="wheel_240_roller_0">
    <visual>
      <origin rpy="0 0 0" xyz="0 0 0"/>
      <geometry>
        <cylinder length="0.012" radius="0.006"/>
      </geometry>
      <material name="white"/>
    </visual>
    <collision>
      <geometry>
        <cylinder length="0.012" radius="0.006"/>
      </geometry>
    </collision>
    <inertial>
      <mass value="0.01"/>
      <inertia ixx="0.00001" ixy="0" ixz="0" iyy="0.00001" iyz="0" izz="0.00001"/>
    </inertial>
  </link>
  <joint name="wheel_240_roller_0_joint" type="continuous">
    <parent link="wheel_240"/>
    <child link="wheel_240_roller_0"/>
    <origin rpy="0 1.5708 0" xyz="0 0.04 -0.006"/>
    <axis xyz="0 0 1"/>
    <!-- Roller spins around its own axis -->
    <limit effort="0.0" velocity="0.0"/>
    <dynamics damping="0.01" friction="0.01"/>
  </joint>
  <!-- Roller 1: 22.5°, outnside -->
  <link name="wheel_240_roller_1">
    <visual>
      <origin rpy="0 0 0" xyz="0 0 0"/>
      <geometry>
        <cylinder length="0.012" radius="0.006"/>
      </geometry>
      <material name="white"/>
    </visual>
    <collision>
      <geometry>
        <cylinder length="0.012" radius="0.006"/>
      </geometry>
    </collision>
    <inertial>
      <mass value="0.01"/>
      <inertia ixx="0.00001" ixy="0" ixz="0" iyy="0.00001" iyz="0" izz="0.00001"/>
    </inertial>
  </link>
  <joint name="wheel_240_roller_1_joint" type="continuous">
    <parent link="wheel_240"/>
    <child link="wheel_240_roller_1"/>
    <origin rpy="0.3927 1.5708 0" xyz="0.015307200000000002 0.0369552 0.006"/>
    <axis xyz="0 0 1"/>
    <!-- Roller spins around its own axis -->
    <limit effort="0.0" velocity="0.0"/>
    <dynamics damping="0.01" friction="0.01"/>
  </joint>
  <!-- Roller 2: 45°, inside -->
  <link name="wheel_240_roller_2">
    <visual>
      <origin rpy="0 0 0" xyz="0 0 0"/>
      <geometry>
        <cylinder length="0.012" radius="0.006"/>
      </geometry>
      <material name="white"/>
    </visual>
    <collision>
      <geometry>
        <cylinder length="0.012" radius="0.006"/>
      </geometry>
    </collision>
    <inertial>
      <mass value="0.01"/>
      <inertia ixx="0.00001" ixy="0" ixz="0" iyy="0.00001" iyz="0" izz="0.00001"/>
    </inertial>
  </link>
  <joint name="wheel_240_roller_2_joint" type="continuous">
    <parent link="wheel_240"/>
    <child link="wheel_240_roller_2"/>
    <origin rpy="0.7854 1.5708 0" xyz="0.028284 0.028284 -0.006"/>
    <axis xyz="0 0 1"/>
    <limit effort="0.0" velocity="0.0"/>
    <dynamics damping="0.01" friction="0.01"/>
  </joint>
  <!-- Roller 3: 67.5°, outside -->
  <link name="wheel_240_roller_3">
    <visual>
      <origin rpy="0 0 0" xyz="0 0 0"/>
      <geometry>
        <cylinder length="0.012" radius="0.006"/>
      </geometry>
      <material name="white"/>
    </visual>
    <collision>
      <geometry>
        <cylinder length="0.012" radius="0.006"/>
      </geometry>
    </collision>
    <inertial>
      <mass value="0.01"/>
      <inertia ixx="0.00001" ixy="0" ixz="0" iyy="0.00001" iyz="0" izz="0.00001"/>
    </inertial>
  </link>
  <joint name="wheel_240_roller_3_joint" type="continuous">
    <parent link="wheel_240"/>
    <child link="wheel_240_roller_3"/>
    <origin rpy="1.1781 1.5708 0" xyz="0.0369552 0.015307200000000002 0.006"/>
    <axis xyz="0 0 1"/>
    <limit effort="0.0" velocity="0.0"/>
    <dynamics damping="0.01" friction="0.01"/>
  </joint>
  <!-- Roller 4: 90°, inside -->
  <link name="wheel_240_roller_4">
    <visual>
      <origin rpy="0 0 0" xyz="0 0 0"/>
      <geometry>
        <cylinder length="0.012" radius="0.006"/>
      </geometry>
      <material name="white"/>
    </visual>
    <collision>
      <geometry>
        <cylinder length="0.012" radius="0.006"/>
      </geometry>
    </collision>
    <inertial>
      <mass value="0.01"/>
      <inertia ixx="0.00001" ixy="0" ixz="0" iyy="0.00001" iyz="0" izz="0.00001"/>
    </inertial>
  </link>
  <joint name="wheel_240_roller_4_joint" type="continuous">
    <parent link="wheel_240"/>
    <child link="wheel_240_roller_4"/>
    <origin rpy="1.5708 1.5708 0" xyz="0.04 0 -0.006"/>
    <axis xyz="0 0 1"/>
    <limit effort="0.0" velocity="0.0"/>
    <dynamics damping="0.01" friction="0.01"/>
  </joint>
  <!-- Roller 5: 112.5°, outside -->
  <link name="wheel_240_roller_5">
    <visual>
      <origin rpy="0 0 0" xyz="0 0 0"/>
      <geometry>
        <cylinder length="0.012" radius="0.006"/>
      </geometry>
      <material name="white"/>
    </visual>
    <collision>
      <geometry>
        <cylinder length="0.012" radius="0.006"/>
      </geometry>
    </collision>
    <inertial>
      <mass value="0.01"/>
      <inertia ixx="0.00001" ixy="0" ixz="0" iyy="0.00001" iyz="0" izz="0.00001"/>
    </inertial>
  </link>
  <joint name="wheel_240_roller_5_joint" type="continuous">
    <parent link="wheel_240"/>
    <child link="wheel_240_roller_5"/>
    <origin rpy="1.9635 1.5708 0" xyz="0.0369552 -0.015307200000000002 0.006"/>
    <axis xyz="0 0 1"/>
    <limit effort="0.0" velocity="0.0"/>
    <dynamics damping="0.01" friction="0.01"/>
  </joint>
  <!-- Roller 6: 135°, inside -->
  <link name="wheel_240_roller_6">
    <visual>
      <origin rpy="0 0 0" xyz="0 0 0"/>
      <geometry>
        <cylinder length="0.012" radius="0.006"/>
      </geometry>
      <material name="white"/>
    </visual>
    <collision>
      <geometry>
        <cylinder length="0.012" radius="0.006"/>
      </geometry>
    </collision>
    <inertial>
      <mass value="0.01"/>
      <inertia ixx="0.00001" ixy="0" ixz="0" iyy="0.00001" iyz="0" izz="0.00001"/>
    </inertial>
  </link>
  <joint name="wheel_240_roller_6_joint" type="continuous">
    <parent link="wheel_240"/>
    <child link="wheel_240_roller_6"/>
    <origin rpy="2.3562 1.5708 0" xyz="0.028284 -0.028284 -0.006"/>
    <axis xyz="0 0 1"/>
    <limit effort="0.0" velocity="0.0"/>
    <dynamics damping="0.01" friction="0.01"/>
  </joint>
  <!-- Roller 7: 157.5°, outside -->
  <link name="wheel_240_roller_7">
    <visual>
      <origin rpy="0 0 0" xyz="0 0 0"/>
      <geometry>
        <cylinder length="0.012" radius="0.006"/>
      </geometry>
      <material name="white"/>
    </visual>
    <collision>
      <geometry>
        <cylinder length="0.012" radius="0.006"/>
      </geometry>
    </collision>
    <inertial>
      <mass value="0.01"/>
      <inertia ixx="0.00001" ixy="0" ixz="0" iyy="0.00001" iyz="0" izz="0.00001"/>
    </inertial>
  </link>
  <joint name="wheel_240_roller_7_joint" type="continuous">
    <parent link="wheel_240"/>
    <child link="wheel_240_roller_7"/>
    <origin rpy="2.7489 1.5708 0" xyz="0.015307200000000002 -0.0369552 0.006"/>
    <axis xyz="0 0 1"/>
    <limit effort="0.0" velocity="0.0"/>
    <dynamics damping="0.01" friction="0.01"/>
  </joint>
  <!-- Roller 8: 180°, inside -->
  <link name="wheel_240_roller_8">
    <visual>
      <origin rpy="0 0 0" xyz="0 0 0"/>
      <geometry>
        <cylinder length="0.012" radius="0.006"/>
      </geometry>
      <material name="white"/>
    </visual>
    <collision>
      <geometry>
        <cylinder length="0.012" radius="0.006"/>
      </geometry>
    </collision>
    <inertial>
      <mass value="0.01"/>
      <inertia ixx="0.00001" ixy="0" ixz="0" iyy="0.00001" iyz="0" izz="0.00001"/>
    </inertial>
  </link>
  <joint name="wheel_240_roller_8_joint" type="continuous">
    <parent link="wheel_240"/>
    <child link="wheel_240_roller_8"/>
    <origin rpy="0 1.5708 0" xyz="0 -0.04 -0.006"/>
    <axis xyz="0 0 1"/>
    <limit effort="0.0" velocity="0.0"/>
    <dynamics damping="0.01" friction="0.01"/>
  </joint>
  <!-- Roller 9: 202.5°, outside -->
  <link name="wheel_240_roller_9">
    <visual>
      <origin rpy="0 0 0" xyz="0 0 0"/>
      <geometry>
        <cylinder length="0.012" radius="0.006"/>
      </geometry>
      <material name="white"/>
    </visual>
    <collision>
      <geometry>
        <cylinder length="0.012" radius="0.006"/>
      </geometry>
    </collision>
    <inertial>
      <mass value="0.01"/>
      <inertia ixx="0.00001" ixy="0" ixz="0" iyy="0.00001" iyz="0" izz="0.00001"/>
    </inertial>
  </link>
  <joint name="wheel_240_roller_9_joint" type="continuous">
    <parent link="wheel_240"/>
    <child link="wheel_240_roller_9"/>
    <origin rpy="0.3927 1.5708 0" xyz="-0.015307200000000002 -0.0369552 0.006"/>
    <axis xyz="0 0 1"/>
    <limit effort="0.0" velocity="0.0"/>
    <dynamics damping="0.01" friction="0.01"/>
  </joint>
  <!-- Roller 10: 225°, inside -->
  <link name="wheel_240_roller_10">
    <visual>
      <origin rpy="0 0 0" xyz="0 0 0"/>
      <geometry>
        <cylinder length="0.012" radius="0.006"/>
      </geometry>
      <material name="white"/>
    </visual>
    <collision>
      <geometry>
        <cylinder length="0.012" radius="0.006"/>
      </geometry>
    </collision>
    <inertial>
      <mass value="0.01"/>
      <inertia ixx="0.00001" ixy="0" ixz="0" iyy="0.00001" iyz="0" izz="0.00001"/>
    </inertial>
  </link>
  <joint name="wheel_240_roller_10_joint" type="continuous">
    <parent link="wheel_240"/>
    <child link="wheel_240_roller_10"/>
    <origin rpy="0.7854 1.5708 0" xyz="-0.028284 -0.028284 -0.006"/>
    <axis xyz="0 0 1"/>
    <limit effort="0.0" velocity="0.0"/>
    <dynamics damping="0.01" friction="0.01"/>
  </joint>
  <!-- Roller 11: 247.5°, outside -->
  <link name="wheel_240_roller_11">
    <visual>
      <origin rpy="0 0 0" xyz="0 0 0"/>
      <geometry>
        <cylinder length="0.012" radius="0.006"/>
      </geometry>
      <material name="white"/>
    </visual>
    <collision>
      <geometry>
        <cylinder length="0.012" radius="0.006"/>
      </geometry>
    </collision>
    <inertial>
      <mass value="0.01"/>
      <inertia ixx="0.00001" ixy="0" ixz="0" iyy="0.00001" iyz="0" izz="0.00001"/>
    </inertial>
  </link>
  <joint name="wheel_240_roller_11_joint" type="continuous">
    <parent link="wheel_240"/>
    <child link="wheel_240_roller_11"/>
    <origin rpy="1.1781 1.5708 0" xyz="-0.0369552 -0.015307200000000002 0.006"/>
    <axis xyz="0 0 1"/>
    <limit effort="0.0" velocity="0.0"/>
    <dynamics damping="0.01" friction="0.01"/>
  </joint>
  <!-- Roller 12: 270°, inside -->
  <link name="wheel_240_roller_12">
    <visual>
      <origin rpy="0 0 0" xyz="0 0 0"/>
      <geometry>
        <cylinder length="0.012" radius="0.006"/>
      </geometry>
      <material name="white"/>
    </visual>
    <collision>
      <geometry>
        <cylinder length="0.012" radius="0.006"/>
      </geometry>
    </collision>
    <inertial>
      <mass value="0.01"/>
      <inertia ixx="0.00001" ixy="0" ixz="0" iyy="0.00001" iyz="0" izz="0.00001"/>
    </inertial>
  </link>
  <joint name="wheel_240_roller_12_joint" type="continuous">
    <parent link="wheel_240"/>
    <child link="wheel_240_roller_12"/>
    <origin rpy="1.5708 1.5708 0" xyz="-0.04 0 -0.006"/>
    <axis xyz="0 0 1"/>
    <limit effort="0.0" velocity="0.0"/>
    <dynamics damping="0.01" friction="0.01"/>
  </joint>
  <!-- Roller 13: 292.5°, outside -->
  <link name="wheel_240_roller_13">
    <visual>
      <origin rpy="0 0 0" xyz="0 0 0"/>
      <geometry>
        <cylinder length="0.012" radius="0.006"/>
      </geometry>
      <material name="white"/>
    </visual>
    <collision>
      <geometry>
        <cylinder length="0.012" radius="0.006"/>
      </geometry>
    </collision>
    <inertial>
      <mass value="0.01"/>
      <inertia ixx="0.00001" ixy="0" ixz="0" iyy="0.00001" iyz="0" izz="0.00001"/>
    </inertial>
  </link>
  <joint name="wheel_240_roller_13_joint" type="continuous">
    <parent link="wheel_240"/>
    <child link="wheel_240_roller_13"/>
    <origin rpy="1.9635 1.5708 0" xyz="-0.0369552 0.015307200000000002 0.006"/>
    <axis xyz="0 0 1"/>
    <limit effort="0.0" velocity="0.0"/>
    <dynamics damping="0.01" friction="0.01"/>
  </joint>
  <!-- Roller 14: 315°, inside -->
  <link name="wheel_240_roller_14">
    <visual>
      <origin rpy="0 0 0" xyz="0 0 0"/>
      <geometry>
        <cylinder length="0.012" radius="0.006"/>
      </geometry>
      <material name="white"/>
    </visual>
    <collision>
      <geometry>
        <cylinder length="0.012" radius="0.006"/>
      </geometry>
    </collision>
    <inertial>
      <mass value="0.01"/>
      <inertia ixx="0.00001" ixy="0" ixz="0" iyy="0.00001" iyz="0" izz="0.00001"/>
    </inertial>
  </link>
  <joint name="wheel_240_roller_14_joint" type="continuous">
    <parent link="wheel_240"/>
    <child link="wheel_240_roller_14"/>
    <origin rpy="2.3562 1.5708 0" xyz="-0.028284 0.028284 -0.006"/>
    <axis xyz="0 0 1"/>
    <limit effort="0.0" velocity="0.0"/>
    <dynamics damping="0.01" friction="0.01"/>
  </joint>
  <!-- Roller 15: 337.5°, outside -->
  <link name="wheel_240_roller_15">
    <visual>
      <origin rpy="0 0 0" xyz="0 0 0"/>
      <geometry>
        <cylinder length="0.012" radius="0.006"/>
      </geometry>
      <material name="white"/>
    </visual>
    <collision>
      <geometry>
        <cylinder length="0.012" radius="0.006"/>
      </geometry>
    </collision>
    <inertial>
      <mass value="0.01"/>
      <inertia ixx="0.00001" ixy="0" ixz="0" iyy="0.00001" iyz="0" izz="0.00001"/>
    </inertial>
  </link>
  <joint name="wheel_240_roller_15_joint" type="continuous">
    <parent link="wheel_240"/>
    <child link="wheel_240_roller_15"/>
    <origin rpy="2.7489 1.5708 0" xyz="-0.015307200000000002 0.0369552 0.006"/>
    <axis xyz="0 0 1"/>
    <limit effort="0.0" velocity="0.0"/>
    <dynamics damping="0.01" friction="0.01"/>
  </joint>
  <!-- 240° -->
  <!-- WEBOTS SPECIFIC TAGS -->
  <webots>
    <device reference="wheel_0_joint" type="RotationalMotor"/>
    <device reference="wheel_120_joint" type="RotationalMotor"/>
    <device reference="wheel_240_joint" type="RotationalMotor"/>
    <plugin type="omni_1_webots.motor_driver.MotorDriver"/>
  </webots>
</robot>
