#VRML_SIM R2025a utf8
# license: Apache License 2.0
# license url: http://www.apache.org/licenses/LICENSE-2.0
# This is a proto file for Webots for the omni_1
# Extracted from: /home/lazar/code/ros/omni-1-ws/src/omni-1-webots/resource/omni_1.urdf

PROTO omni_1 [
  field  SFVec3f     translation     0 0 0
  field  SFRotation  rotation        0 0 1 0
  field  SFString    name            "omni_1"  # Is `Robot.name`.
  field  SFString    controller      "void"    # Is `Robot.controller`.
  field  MFString    controllerArgs  []        # Is `Robot.controllerArgs`.
  field  SFString    customData      ""        # Is `Robot.customData`.
  field  SFBool      supervisor      FALSE     # Is `Robot.supervisor`.
  field  SFBool      synchronization TRUE      # Is `Robot.synchronization`.
  field  SFBool      selfCollision   FALSE     # Is `Robot.selfCollision`.
]
{
  Robot {
    translation IS translation
    rotation IS rotation
    controller IS controller
    controllerArgs IS controllerArgs
    customData IS customData
    supervisor IS supervisor
    synchronization IS synchronization
    selfCollision IS selfCollision
    children [
      Shape {
        appearance DEF white PBRAppearance {
          baseColor 0.500000 0.500000 0.500000
          roughness 1.000000
          metalness 0
        }
        geometry Cylinder {
          radius 0.11
          height 0.064
        }
      }
      HingeJoint {
        jointParameters HingeJointParameters {
          axis 1.000000 0.000000 -0.000004
          anchor 0.125000 0.000000 -0.010000
          dampingConstant 0.1
          staticFriction 0.01
        }
        device [
          RotationalMotor {
            name "wheel_0_joint"
            maxVelocity 10.0
            maxTorque 10.0
          }
          PositionSensor {
            name "wheel_0_joint_sensor"
          }
        ]
        endPoint Solid {
          translation 0.125000 0.000000 -0.010000
          rotation 0.000000 1.000000 0.000000 1.570800
          children [
            Shape {
              appearance DEF copper PBRAppearance {
                baseColor 0.500000 0.500000 0.500000
                roughness 1.000000
                metalness 0
              }
              geometry Cylinder {
                radius 0.032
                height 0.02
              }
            }
            HingeJoint {
              jointParameters HingeJointParameters {
                axis 1.000000 0.000000 -0.000004
                anchor 0.000000 0.040000 -0.006000
                dampingConstant 0.01
                staticFriction 0.01
              }
              device [
                RotationalMotor {
                  name "wheel_0_roller_0_joint"
                  maxTorque 10000
                }
                PositionSensor {
                  name "wheel_0_roller_0_joint_sensor"
                }
              ]
              endPoint Solid {
                translation 0.000000 0.040000 -0.006000
                rotation 0.000000 1.000000 0.000000 1.570800
                children [
                  Shape {
                    appearance USE white
                    geometry Cylinder {
                      radius 0.006
                      height 0.012
                    }
                  }
                ]
                name "wheel_0_roller_0"
                boundingObject Cylinder {
                  radius 0.006
                  height 0.012
                }
                physics Physics {
                  density -1
                  mass 0.010000
                  centerOfMass [ 0.000000 0.000000 0.000000 ]
                  inertiaMatrix [
                    1.000000e-05 1.000000e-05 1.000000e-05
                    0.000000e+00 0.000000e+00 0.000000e+00
                  ]
                }
              }
            }
            HingeJoint {
              jointParameters HingeJointParameters {
                axis 0.923879 -0.382684 -0.000003
                anchor 0.015307 0.036955 0.006000
                dampingConstant 0.01
                staticFriction 0.01
              }
              device [
                RotationalMotor {
                  name "wheel_0_roller_1_joint"
                  maxTorque 10000
                }
                PositionSensor {
                  name "wheel_0_roller_1_joint_sensor"
                }
              ]
              endPoint Solid {
                translation 0.015307 0.036955 0.006000
                rotation 0.191480 0.962637 -0.191481 1.608869
                children [
                  Shape {
                    appearance USE white
                    geometry Cylinder {
                      radius 0.006
                      height 0.012
                    }
                  }
                ]
                name "wheel_0_roller_1"
                boundingObject Cylinder {
                  radius 0.006
                  height 0.012
                }
                physics Physics {
                  density -1
                  mass 0.010000
                  centerOfMass [ 0.000000 0.000000 0.000000 ]
                  inertiaMatrix [
                    1.000000e-05 1.000000e-05 1.000000e-05
                    0.000000e+00 0.000000e+00 0.000000e+00
                  ]
                }
              }
            }
            HingeJoint {
              jointParameters HingeJointParameters {
                axis 0.707105 -0.707108 -0.000003
                anchor 0.028284 0.028284 -0.006000
                dampingConstant 0.01
                staticFriction 0.01
              }
              device [
                RotationalMotor {
                  name "wheel_0_roller_2_joint"
                  maxTorque 10000
                }
                PositionSensor {
                  name "wheel_0_roller_2_joint_sensor"
                }
              ]
              endPoint Solid {
                translation 0.028284 0.028284 -0.006000
                rotation 0.357406 0.862856 -0.357408 1.717775
                children [
                  Shape {
                    appearance USE white
                    geometry Cylinder {
                      radius 0.006
                      height 0.012
                    }
                  }
                ]
                name "wheel_0_roller_2"
                boundingObject Cylinder {
                  radius 0.006
                  height 0.012
                }
                physics Physics {
                  density -1
                  mass 0.010000
                  centerOfMass [ 0.000000 0.000000 0.000000 ]
                  inertiaMatrix [
                    1.000000e-05 1.000000e-05 1.000000e-05
                    0.000000e+00 0.000000e+00 0.000000e+00
                  ]
                }
              }
            }
            HingeJoint {
              jointParameters HingeJointParameters {
                axis 0.382681 -0.923881 -0.000001
                anchor 0.036955 0.015307 0.006000
                dampingConstant 0.01
                staticFriction 0.01
              }
              device [
                RotationalMotor {
                  name "wheel_0_roller_3_joint"
                  maxTorque 10000
                }
                PositionSensor {
                  name "wheel_0_roller_3_joint_sensor"
                }
              ]
              endPoint Solid {
                translation 0.036955 0.015307 0.006000
                rotation 0.485652 0.726830 -0.485654 1.884582
                children [
                  Shape {
                    appearance USE white
                    geometry Cylinder {
                      radius 0.006
                      height 0.012
                    }
                  }
                ]
                name "wheel_0_roller_3"
                boundingObject Cylinder {
                  radius 0.006
                  height 0.012
                }
                physics Physics {
                  density -1
                  mass 0.010000
                  centerOfMass [ 0.000000 0.000000 0.000000 ]
                  inertiaMatrix [
                    1.000000e-05 1.000000e-05 1.000000e-05
                    0.000000e+00 0.000000e+00 0.000000e+00
                  ]
                }
              }
            }
            HingeJoint {
              jointParameters HingeJointParameters {
                axis -0.000004 -1.000000 0.000000
                anchor 0.040000 0.000000 -0.006000
                dampingConstant 0.01
                staticFriction 0.01
              }
              device [
                RotationalMotor {
                  name "wheel_0_roller_4_joint"
                  maxTorque 10000
                }
                PositionSensor {
                  name "wheel_0_roller_4_joint_sensor"
                }
              ]
              endPoint Solid {
                translation 0.040000 0.000000 -0.006000
                rotation 0.577350 0.577350 -0.577352 2.094399
                children [
                  Shape {
                    appearance USE white
                    geometry Cylinder {
                      radius 0.006
                      height 0.012
                    }
                  }
                ]
                name "wheel_0_roller_4"
                boundingObject Cylinder {
                  radius 0.006
                  height 0.012
                }
                physics Physics {
                  density -1
                  mass 0.010000
                  centerOfMass [ 0.000000 0.000000 0.000000 ]
                  inertiaMatrix [
                    1.000000e-05 1.000000e-05 1.000000e-05
                    0.000000e+00 0.000000e+00 0.000000e+00
                  ]
                }
              }
            }
            HingeJoint {
              jointParameters HingeJointParameters {
                axis -0.382688 -0.923878 0.000001
                anchor 0.036955 -0.015307 0.006000
                dampingConstant 0.01
                staticFriction 0.01
              }
              device [
                RotationalMotor {
                  name "wheel_0_roller_5_joint"
                  maxTorque 10000
                }
                PositionSensor {
                  name "wheel_0_roller_5_joint_sensor"
                }
              ]
              endPoint Solid {
                translation 0.036955 -0.015307 0.006000
                rotation 0.639337 0.427191 -0.639340 2.334145
                children [
                  Shape {
                    appearance USE white
                    geometry Cylinder {
                      radius 0.006
                      height 0.012
                    }
                  }
                ]
                name "wheel_0_roller_5"
                boundingObject Cylinder {
                  radius 0.006
                  height 0.012
                }
                physics Physics {
                  density -1
                  mass 0.010000
                  centerOfMass [ 0.000000 0.000000 0.000000 ]
                  inertiaMatrix [
                    1.000000e-05 1.000000e-05 1.000000e-05
                    0.000000e+00 0.000000e+00 0.000000e+00
                  ]
                }
              }
            }
            HingeJoint {
              jointParameters HingeJointParameters {
                axis -0.707111 -0.707103 0.000003
                anchor 0.028284 -0.028284 -0.006000
                dampingConstant 0.01
                staticFriction 0.01
              }
              device [
                RotationalMotor {
                  name "wheel_0_roller_6_joint"
                  maxTorque 10000
                }
                PositionSensor {
                  name "wheel_0_roller_6_joint_sensor"
                }
              ]
              endPoint Solid {
                translation 0.028284 -0.028284 -0.006000
                rotation 0.678597 0.281083 -0.678600 2.593569
                children [
                  Shape {
                    appearance USE white
                    geometry Cylinder {
                      radius 0.006
                      height 0.012
                    }
                  }
                ]
                name "wheel_0_roller_6"
                boundingObject Cylinder {
                  radius 0.006
                  height 0.012
                }
                physics Physics {
                  density -1
                  mass 0.010000
                  centerOfMass [ 0.000000 0.000000 0.000000 ]
                  inertiaMatrix [
                    1.000000e-05 1.000000e-05 1.000000e-05
                    0.000000e+00 0.000000e+00 0.000000e+00
                  ]
                }
              }
            }
            HingeJoint {
              jointParameters HingeJointParameters {
                axis -0.923882 -0.382677 0.000003
                anchor 0.015307 -0.036955 0.006000
                dampingConstant 0.01
                staticFriction 0.01
              }
              device [
                RotationalMotor {
                  name "wheel_0_roller_7_joint"
                  maxTorque 10000
                }
                PositionSensor {
                  name "wheel_0_roller_7_joint_sensor"
                }
              ]
              endPoint Solid {
                translation 0.015307 -0.036955 0.006000
                rotation 0.700213 0.139279 -0.700216 2.864816
                children [
                  Shape {
                    appearance USE white
                    geometry Cylinder {
                      radius 0.006
                      height 0.012
                    }
                  }
                ]
                name "wheel_0_roller_7"
                boundingObject Cylinder {
                  radius 0.006
                  height 0.012
                }
                physics Physics {
                  density -1
                  mass 0.010000
                  centerOfMass [ 0.000000 0.000000 0.000000 ]
                  inertiaMatrix [
                    1.000000e-05 1.000000e-05 1.000000e-05
                    0.000000e+00 0.000000e+00 0.000000e+00
                  ]
                }
              }
            }
            HingeJoint {
              jointParameters HingeJointParameters {
                axis 1.000000 0.000000 -0.000004
                anchor 0.000000 -0.040000 -0.006000
                dampingConstant 0.01
                staticFriction 0.01
              }
              device [
                RotationalMotor {
                  name "wheel_0_roller_8_joint"
                  maxTorque 10000
                }
                PositionSensor {
                  name "wheel_0_roller_8_joint_sensor"
                }
              ]
              endPoint Solid {
                translation 0.000000 -0.040000 -0.006000
                rotation 0.000000 1.000000 0.000000 1.570800
                children [
                  Shape {
                    appearance USE white
                    geometry Cylinder {
                      radius 0.006
                      height 0.012
                    }
                  }
                ]
                name "wheel_0_roller_8"
                boundingObject Cylinder {
                  radius 0.006
                  height 0.012
                }
                physics Physics {
                  density -1
                  mass 0.010000
                  centerOfMass [ 0.000000 0.000000 0.000000 ]
                  inertiaMatrix [
                    1.000000e-05 1.000000e-05 1.000000e-05
                    0.000000e+00 0.000000e+00 0.000000e+00
                  ]
                }
              }
            }
            HingeJoint {
              jointParameters HingeJointParameters {
                axis 0.923879 -0.382684 -0.000003
                anchor -0.015307 -0.036955 0.006000
                dampingConstant 0.01
                staticFriction 0.01
              }
              device [
                RotationalMotor {
                  name "wheel_0_roller_9_joint"
                  maxTorque 10000
                }
                PositionSensor {
                  name "wheel_0_roller_9_joint_sensor"
                }
              ]
              endPoint Solid {
                translation -0.015307 -0.036955 0.006000
                rotation 0.191480 0.962637 -0.191481 1.608869
                children [
                  Shape {
                    appearance USE white
                    geometry Cylinder {
                      radius 0.006
                      height 0.012
                    }
                  }
                ]
                name "wheel_0_roller_9"
                boundingObject Cylinder {
                  radius 0.006
                  height 0.012
                }
                physics Physics {
                  density -1
                  mass 0.010000
                  centerOfMass [ 0.000000 0.000000 0.000000 ]
                  inertiaMatrix [
                    1.000000e-05 1.000000e-05 1.000000e-05
                    0.000000e+00 0.000000e+00 0.000000e+00
                  ]
                }
              }
            }
            HingeJoint {
              jointParameters HingeJointParameters {
                axis 0.707105 -0.707108 -0.000003
                anchor -0.028284 -0.028284 -0.006000
                dampingConstant 0.01
                staticFriction 0.01
              }
              device [
                RotationalMotor {
                  name "wheel_0_roller_10_joint"
                  maxTorque 10000
                }
                PositionSensor {
                  name "wheel_0_roller_10_joint_sensor"
                }
              ]
              endPoint Solid {
                translation -0.028284 -0.028284 -0.006000
                rotation 0.357406 0.862856 -0.357408 1.717775
                children [
                  Shape {
                    appearance USE white
                    geometry Cylinder {
                      radius 0.006
                      height 0.012
                    }
                  }
                ]
                name "wheel_0_roller_10"
                boundingObject Cylinder {
                  radius 0.006
                  height 0.012
                }
                physics Physics {
                  density -1
                  mass 0.010000
                  centerOfMass [ 0.000000 0.000000 0.000000 ]
                  inertiaMatrix [
                    1.000000e-05 1.000000e-05 1.000000e-05
                    0.000000e+00 0.000000e+00 0.000000e+00
                  ]
                }
              }
            }
            HingeJoint {
              jointParameters HingeJointParameters {
                axis 0.382681 -0.923881 -0.000001
                anchor -0.036955 -0.015307 0.006000
                dampingConstant 0.01
                staticFriction 0.01
              }
              device [
                RotationalMotor {
                  name "wheel_0_roller_11_joint"
                  maxTorque 10000
                }
                PositionSensor {
                  name "wheel_0_roller_11_joint_sensor"
                }
              ]
              endPoint Solid {
                translation -0.036955 -0.015307 0.006000
                rotation 0.485652 0.726830 -0.485654 1.884582
                children [
                  Shape {
                    appearance USE white
                    geometry Cylinder {
                      radius 0.006
                      height 0.012
                    }
                  }
                ]
                name "wheel_0_roller_11"
                boundingObject Cylinder {
                  radius 0.006
                  height 0.012
                }
                physics Physics {
                  density -1
                  mass 0.010000
                  centerOfMass [ 0.000000 0.000000 0.000000 ]
                  inertiaMatrix [
                    1.000000e-05 1.000000e-05 1.000000e-05
                    0.000000e+00 0.000000e+00 0.000000e+00
                  ]
                }
              }
            }
            HingeJoint {
              jointParameters HingeJointParameters {
                axis -0.000004 -1.000000 0.000000
                anchor -0.040000 0.000000 -0.006000
                dampingConstant 0.01
                staticFriction 0.01
              }
              device [
                RotationalMotor {
                  name "wheel_0_roller_12_joint"
                  maxTorque 10000
                }
                PositionSensor {
                  name "wheel_0_roller_12_joint_sensor"
                }
              ]
              endPoint Solid {
                translation -0.040000 0.000000 -0.006000
                rotation 0.577350 0.577350 -0.577352 2.094399
                children [
                  Shape {
                    appearance USE white
                    geometry Cylinder {
                      radius 0.006
                      height 0.012
                    }
                  }
                ]
                name "wheel_0_roller_12"
                boundingObject Cylinder {
                  radius 0.006
                  height 0.012
                }
                physics Physics {
                  density -1
                  mass 0.010000
                  centerOfMass [ 0.000000 0.000000 0.000000 ]
                  inertiaMatrix [
                    1.000000e-05 1.000000e-05 1.000000e-05
                    0.000000e+00 0.000000e+00 0.000000e+00
                  ]
                }
              }
            }
            HingeJoint {
              jointParameters HingeJointParameters {
                axis -0.382688 -0.923878 0.000001
                anchor -0.036955 0.015307 0.006000
                dampingConstant 0.01
                staticFriction 0.01
              }
              device [
                RotationalMotor {
                  name "wheel_0_roller_13_joint"
                  maxTorque 10000
                }
                PositionSensor {
                  name "wheel_0_roller_13_joint_sensor"
                }
              ]
              endPoint Solid {
                translation -0.036955 0.015307 0.006000
                rotation 0.639337 0.427191 -0.639340 2.334145
                children [
                  Shape {
                    appearance USE white
                    geometry Cylinder {
                      radius 0.006
                      height 0.012
                    }
                  }
                ]
                name "wheel_0_roller_13"
                boundingObject Cylinder {
                  radius 0.006
                  height 0.012
                }
                physics Physics {
                  density -1
                  mass 0.010000
                  centerOfMass [ 0.000000 0.000000 0.000000 ]
                  inertiaMatrix [
                    1.000000e-05 1.000000e-05 1.000000e-05
                    0.000000e+00 0.000000e+00 0.000000e+00
                  ]
                }
              }
            }
            HingeJoint {
              jointParameters HingeJointParameters {
                axis -0.707111 -0.707103 0.000003
                anchor -0.028284 0.028284 -0.006000
                dampingConstant 0.01
                staticFriction 0.01
              }
              device [
                RotationalMotor {
                  name "wheel_0_roller_14_joint"
                  maxTorque 10000
                }
                PositionSensor {
                  name "wheel_0_roller_14_joint_sensor"
                }
              ]
              endPoint Solid {
                translation -0.028284 0.028284 -0.006000
                rotation 0.678597 0.281083 -0.678600 2.593569
                children [
                  Shape {
                    appearance USE white
                    geometry Cylinder {
                      radius 0.006
                      height 0.012
                    }
                  }
                ]
                name "wheel_0_roller_14"
                boundingObject Cylinder {
                  radius 0.006
                  height 0.012
                }
                physics Physics {
                  density -1
                  mass 0.010000
                  centerOfMass [ 0.000000 0.000000 0.000000 ]
                  inertiaMatrix [
                    1.000000e-05 1.000000e-05 1.000000e-05
                    0.000000e+00 0.000000e+00 0.000000e+00
                  ]
                }
              }
            }
            HingeJoint {
              jointParameters HingeJointParameters {
                axis -0.923882 -0.382677 0.000003
                anchor -0.015307 0.036955 0.006000
                dampingConstant 0.01
                staticFriction 0.01
              }
              device [
                RotationalMotor {
                  name "wheel_0_roller_15_joint"
                  maxTorque 10000
                }
                PositionSensor {
                  name "wheel_0_roller_15_joint_sensor"
                }
              ]
              endPoint Solid {
                translation -0.015307 0.036955 0.006000
                rotation 0.700213 0.139279 -0.700216 2.864816
                children [
                  Shape {
                    appearance USE white
                    geometry Cylinder {
                      radius 0.006
                      height 0.012
                    }
                  }
                ]
                name "wheel_0_roller_15"
                boundingObject Cylinder {
                  radius 0.006
                  height 0.012
                }
                physics Physics {
                  density -1
                  mass 0.010000
                  centerOfMass [ 0.000000 0.000000 0.000000 ]
                  inertiaMatrix [
                    1.000000e-05 1.000000e-05 1.000000e-05
                    0.000000e+00 0.000000e+00 0.000000e+00
                  ]
                }
              }
            }
          ]
          name "wheel_0"
          boundingObject Cylinder {
            radius 0.04
            height 0.02
          }
          physics Physics {
            density -1
            mass 0.150000
            centerOfMass [ 0.000000 0.000000 0.000000 ]
            inertiaMatrix [
              2.000000e-04 2.000000e-04 2.000000e-04
              0.000000e+00 0.000000e+00 0.000000e+00
            ]
          }
        }
      }
      HingeJoint {
        jointParameters HingeJointParameters {
          axis -0.500004 0.866023 -0.000004
          anchor -0.062500 0.108250 -0.010000
          dampingConstant 0.1
          staticFriction 0.01
        }
        device [
          RotationalMotor {
            name "wheel_120_joint"
            maxVelocity 10.0
            maxTorque 10.0
          }
          PositionSensor {
            name "wheel_120_joint_sensor"
          }
        ]
        endPoint Solid {
          translation -0.062500 0.108250 -0.010000
          rotation -0.654655 0.377963 0.654653 2.418863
          children [
            Shape {
              appearance USE copper
              geometry Cylinder {
                radius 0.032
                height 0.02
              }
            }
            HingeJoint {
              jointParameters HingeJointParameters {
                axis 1.000000 0.000000 -0.000004
                anchor 0.000000 0.040000 -0.006000
                dampingConstant 0.01
                staticFriction 0.01
              }
              device [
                RotationalMotor {
                  name "wheel_120_roller_0_joint"
                  maxTorque 10000
                }
                PositionSensor {
                  name "wheel_120_roller_0_joint_sensor"
                }
              ]
              endPoint Solid {
                translation 0.000000 0.040000 -0.006000
                rotation 0.000000 1.000000 0.000000 1.570800
                children [
                  Shape {
                    appearance USE white
                    geometry Cylinder {
                      radius 0.006
                      height 0.012
                    }
                  }
                ]
                name "wheel_120_roller_0"
                boundingObject Cylinder {
                  radius 0.006
                  height 0.012
                }
                physics Physics {
                  density -1
                  mass 0.010000
                  centerOfMass [ 0.000000 0.000000 0.000000 ]
                  inertiaMatrix [
                    1.000000e-05 1.000000e-05 1.000000e-05
                    0.000000e+00 0.000000e+00 0.000000e+00
                  ]
                }
              }
            }
            HingeJoint {
              jointParameters HingeJointParameters {
                axis 0.923879 -0.382684 -0.000003
                anchor 0.015307 0.036955 0.006000
                dampingConstant 0.01
                staticFriction 0.01
              }
              device [
                RotationalMotor {
                  name "wheel_120_roller_1_joint"
                  maxTorque 10000
                }
                PositionSensor {
                  name "wheel_120_roller_1_joint_sensor"
                }
              ]
              endPoint Solid {
                translation 0.015307 0.036955 0.006000
                rotation 0.191480 0.962637 -0.191481 1.608869
                children [
                  Shape {
                    appearance USE white
                    geometry Cylinder {
                      radius 0.006
                      height 0.012
                    }
                  }
                ]
                name "wheel_120_roller_1"
                boundingObject Cylinder {
                  radius 0.006
                  height 0.012
                }
                physics Physics {
                  density -1
                  mass 0.010000
                  centerOfMass [ 0.000000 0.000000 0.000000 ]
                  inertiaMatrix [
                    1.000000e-05 1.000000e-05 1.000000e-05
                    0.000000e+00 0.000000e+00 0.000000e+00
                  ]
                }
              }
            }
            HingeJoint {
              jointParameters HingeJointParameters {
                axis 0.707105 -0.707108 -0.000003
                anchor 0.028284 0.028284 -0.006000
                dampingConstant 0.01
                staticFriction 0.01
              }
              device [
                RotationalMotor {
                  name "wheel_120_roller_2_joint"
                  maxTorque 10000
                }
                PositionSensor {
                  name "wheel_120_roller_2_joint_sensor"
                }
              ]
              endPoint Solid {
                translation 0.028284 0.028284 -0.006000
                rotation 0.357406 0.862856 -0.357408 1.717775
                children [
                  Shape {
                    appearance USE white
                    geometry Cylinder {
                      radius 0.006
                      height 0.012
                    }
                  }
                ]
                name "wheel_120_roller_2"
                boundingObject Cylinder {
                  radius 0.006
                  height 0.012
                }
                physics Physics {
                  density -1
                  mass 0.010000
                  centerOfMass [ 0.000000 0.000000 0.000000 ]
                  inertiaMatrix [
                    1.000000e-05 1.000000e-05 1.000000e-05
                    0.000000e+00 0.000000e+00 0.000000e+00
                  ]
                }
              }
            }
            HingeJoint {
              jointParameters HingeJointParameters {
                axis 0.382681 -0.923881 -0.000001
                anchor 0.036955 0.015307 0.006000
                dampingConstant 0.01
                staticFriction 0.01
              }
              device [
                RotationalMotor {
                  name "wheel_120_roller_3_joint"
                  maxTorque 10000
                }
                PositionSensor {
                  name "wheel_120_roller_3_joint_sensor"
                }
              ]
              endPoint Solid {
                translation 0.036955 0.015307 0.006000
                rotation 0.485652 0.726830 -0.485654 1.884582
                children [
                  Shape {
                    appearance USE white
                    geometry Cylinder {
                      radius 0.006
                      height 0.012
                    }
                  }
                ]
                name "wheel_120_roller_3"
                boundingObject Cylinder {
                  radius 0.006
                  height 0.012
                }
                physics Physics {
                  density -1
                  mass 0.010000
                  centerOfMass [ 0.000000 0.000000 0.000000 ]
                  inertiaMatrix [
                    1.000000e-05 1.000000e-05 1.000000e-05
                    0.000000e+00 0.000000e+00 0.000000e+00
                  ]
                }
              }
            }
            HingeJoint {
              jointParameters HingeJointParameters {
                axis -0.000004 -1.000000 0.000000
                anchor 0.040000 0.000000 -0.006000
                dampingConstant 0.01
                staticFriction 0.01
              }
              device [
                RotationalMotor {
                  name "wheel_120_roller_4_joint"
                  maxTorque 10000
                }
                PositionSensor {
                  name "wheel_120_roller_4_joint_sensor"
                }
              ]
              endPoint Solid {
                translation 0.040000 0.000000 -0.006000
                rotation 0.577350 0.577350 -0.577352 2.094399
                children [
                  Shape {
                    appearance USE white
                    geometry Cylinder {
                      radius 0.006
                      height 0.012
                    }
                  }
                ]
                name "wheel_120_roller_4"
                boundingObject Cylinder {
                  radius 0.006
                  height 0.012
                }
                physics Physics {
                  density -1
                  mass 0.010000
                  centerOfMass [ 0.000000 0.000000 0.000000 ]
                  inertiaMatrix [
                    1.000000e-05 1.000000e-05 1.000000e-05
                    0.000000e+00 0.000000e+00 0.000000e+00
                  ]
                }
              }
            }
            HingeJoint {
              jointParameters HingeJointParameters {
                axis -0.382688 -0.923878 0.000001
                anchor 0.036955 -0.015307 0.006000
                dampingConstant 0.01
                staticFriction 0.01
              }
              device [
                RotationalMotor {
                  name "wheel_120_roller_5_joint"
                  maxTorque 10000
                }
                PositionSensor {
                  name "wheel_120_roller_5_joint_sensor"
                }
              ]
              endPoint Solid {
                translation 0.036955 -0.015307 0.006000
                rotation 0.639337 0.427191 -0.639340 2.334145
                children [
                  Shape {
                    appearance USE white
                    geometry Cylinder {
                      radius 0.006
                      height 0.012
                    }
                  }
                ]
                name "wheel_120_roller_5"
                boundingObject Cylinder {
                  radius 0.006
                  height 0.012
                }
                physics Physics {
                  density -1
                  mass 0.010000
                  centerOfMass [ 0.000000 0.000000 0.000000 ]
                  inertiaMatrix [
                    1.000000e-05 1.000000e-05 1.000000e-05
                    0.000000e+00 0.000000e+00 0.000000e+00
                  ]
                }
              }
            }
            HingeJoint {
              jointParameters HingeJointParameters {
                axis -0.707111 -0.707103 0.000003
                anchor 0.028284 -0.028284 -0.006000
                dampingConstant 0.01
                staticFriction 0.01
              }
              device [
                RotationalMotor {
                  name "wheel_120_roller_6_joint"
                  maxTorque 10000
                }
                PositionSensor {
                  name "wheel_120_roller_6_joint_sensor"
                }
              ]
              endPoint Solid {
                translation 0.028284 -0.028284 -0.006000
                rotation 0.678597 0.281083 -0.678600 2.593569
                children [
                  Shape {
                    appearance USE white
                    geometry Cylinder {
                      radius 0.006
                      height 0.012
                    }
                  }
                ]
                name "wheel_120_roller_6"
                boundingObject Cylinder {
                  radius 0.006
                  height 0.012
                }
                physics Physics {
                  density -1
                  mass 0.010000
                  centerOfMass [ 0.000000 0.000000 0.000000 ]
                  inertiaMatrix [
                    1.000000e-05 1.000000e-05 1.000000e-05
                    0.000000e+00 0.000000e+00 0.000000e+00
                  ]
                }
              }
            }
            HingeJoint {
              jointParameters HingeJointParameters {
                axis -0.923882 -0.382677 0.000003
                anchor 0.015307 -0.036955 0.006000
                dampingConstant 0.01
                staticFriction 0.01
              }
              device [
                RotationalMotor {
                  name "wheel_120_roller_7_joint"
                  maxTorque 10000
                }
                PositionSensor {
                  name "wheel_120_roller_7_joint_sensor"
                }
              ]
              endPoint Solid {
                translation 0.015307 -0.036955 0.006000
                rotation 0.700213 0.139279 -0.700216 2.864816
                children [
                  Shape {
                    appearance USE white
                    geometry Cylinder {
                      radius 0.006
                      height 0.012
                    }
                  }
                ]
                name "wheel_120_roller_7"
                boundingObject Cylinder {
                  radius 0.006
                  height 0.012
                }
                physics Physics {
                  density -1
                  mass 0.010000
                  centerOfMass [ 0.000000 0.000000 0.000000 ]
                  inertiaMatrix [
                    1.000000e-05 1.000000e-05 1.000000e-05
                    0.000000e+00 0.000000e+00 0.000000e+00
                  ]
                }
              }
            }
            HingeJoint {
              jointParameters HingeJointParameters {
                axis 1.000000 0.000000 -0.000004
                anchor 0.000000 -0.040000 -0.006000
                dampingConstant 0.01
                staticFriction 0.01
              }
              device [
                RotationalMotor {
                  name "wheel_120_roller_8_joint"
                  maxTorque 10000
                }
                PositionSensor {
                  name "wheel_120_roller_8_joint_sensor"
                }
              ]
              endPoint Solid {
                translation 0.000000 -0.040000 -0.006000
                rotation 0.000000 1.000000 0.000000 1.570800
                children [
                  Shape {
                    appearance USE white
                    geometry Cylinder {
                      radius 0.006
                      height 0.012
                    }
                  }
                ]
                name "wheel_120_roller_8"
                boundingObject Cylinder {
                  radius 0.006
                  height 0.012
                }
                physics Physics {
                  density -1
                  mass 0.010000
                  centerOfMass [ 0.000000 0.000000 0.000000 ]
                  inertiaMatrix [
                    1.000000e-05 1.000000e-05 1.000000e-05
                    0.000000e+00 0.000000e+00 0.000000e+00
                  ]
                }
              }
            }
            HingeJoint {
              jointParameters HingeJointParameters {
                axis 0.923879 -0.382684 -0.000003
                anchor -0.015307 -0.036955 0.006000
                dampingConstant 0.01
                staticFriction 0.01
              }
              device [
                RotationalMotor {
                  name "wheel_120_roller_9_joint"
                  maxTorque 10000
                }
                PositionSensor {
                  name "wheel_120_roller_9_joint_sensor"
                }
              ]
              endPoint Solid {
                translation -0.015307 -0.036955 0.006000
                rotation 0.191480 0.962637 -0.191481 1.608869
                children [
                  Shape {
                    appearance USE white
                    geometry Cylinder {
                      radius 0.006
                      height 0.012
                    }
                  }
                ]
                name "wheel_120_roller_9"
                boundingObject Cylinder {
                  radius 0.006
                  height 0.012
                }
                physics Physics {
                  density -1
                  mass 0.010000
                  centerOfMass [ 0.000000 0.000000 0.000000 ]
                  inertiaMatrix [
                    1.000000e-05 1.000000e-05 1.000000e-05
                    0.000000e+00 0.000000e+00 0.000000e+00
                  ]
                }
              }
            }
            HingeJoint {
              jointParameters HingeJointParameters {
                axis 0.707105 -0.707108 -0.000003
                anchor -0.028284 -0.028284 -0.006000
                dampingConstant 0.01
                staticFriction 0.01
              }
              device [
                RotationalMotor {
                  name "wheel_120_roller_10_joint"
                  maxTorque 10000
                }
                PositionSensor {
                  name "wheel_120_roller_10_joint_sensor"
                }
              ]
              endPoint Solid {
                translation -0.028284 -0.028284 -0.006000
                rotation 0.357406 0.862856 -0.357408 1.717775
                children [
                  Shape {
                    appearance USE white
                    geometry Cylinder {
                      radius 0.006
                      height 0.012
                    }
                  }
                ]
                name "wheel_120_roller_10"
                boundingObject Cylinder {
                  radius 0.006
                  height 0.012
                }
                physics Physics {
                  density -1
                  mass 0.010000
                  centerOfMass [ 0.000000 0.000000 0.000000 ]
                  inertiaMatrix [
                    1.000000e-05 1.000000e-05 1.000000e-05
                    0.000000e+00 0.000000e+00 0.000000e+00
                  ]
                }
              }
            }
            HingeJoint {
              jointParameters HingeJointParameters {
                axis 0.382681 -0.923881 -0.000001
                anchor -0.036955 -0.015307 0.006000
                dampingConstant 0.01
                staticFriction 0.01
              }
              device [
                RotationalMotor {
                  name "wheel_120_roller_11_joint"
                  maxTorque 10000
                }
                PositionSensor {
                  name "wheel_120_roller_11_joint_sensor"
                }
              ]
              endPoint Solid {
                translation -0.036955 -0.015307 0.006000
                rotation 0.485652 0.726830 -0.485654 1.884582
                children [
                  Shape {
                    appearance USE white
                    geometry Cylinder {
                      radius 0.006
                      height 0.012
                    }
                  }
                ]
                name "wheel_120_roller_11"
                boundingObject Cylinder {
                  radius 0.006
                  height 0.012
                }
                physics Physics {
                  density -1
                  mass 0.010000
                  centerOfMass [ 0.000000 0.000000 0.000000 ]
                  inertiaMatrix [
                    1.000000e-05 1.000000e-05 1.000000e-05
                    0.000000e+00 0.000000e+00 0.000000e+00
                  ]
                }
              }
            }
            HingeJoint {
              jointParameters HingeJointParameters {
                axis -0.000004 -1.000000 0.000000
                anchor -0.040000 0.000000 -0.006000
                dampingConstant 0.01
                staticFriction 0.01
              }
              device [
                RotationalMotor {
                  name "wheel_120_roller_12_joint"
                  maxTorque 10000
                }
                PositionSensor {
                  name "wheel_120_roller_12_joint_sensor"
                }
              ]
              endPoint Solid {
                translation -0.040000 0.000000 -0.006000
                rotation 0.577350 0.577350 -0.577352 2.094399
                children [
                  Shape {
                    appearance USE white
                    geometry Cylinder {
                      radius 0.006
                      height 0.012
                    }
                  }
                ]
                name "wheel_120_roller_12"
                boundingObject Cylinder {
                  radius 0.006
                  height 0.012
                }
                physics Physics {
                  density -1
                  mass 0.010000
                  centerOfMass [ 0.000000 0.000000 0.000000 ]
                  inertiaMatrix [
                    1.000000e-05 1.000000e-05 1.000000e-05
                    0.000000e+00 0.000000e+00 0.000000e+00
                  ]
                }
              }
            }
            HingeJoint {
              jointParameters HingeJointParameters {
                axis -0.382688 -0.923878 0.000001
                anchor -0.036955 0.015307 0.006000
                dampingConstant 0.01
                staticFriction 0.01
              }
              device [
                RotationalMotor {
                  name "wheel_120_roller_13_joint"
                  maxTorque 10000
                }
                PositionSensor {
                  name "wheel_120_roller_13_joint_sensor"
                }
              ]
              endPoint Solid {
                translation -0.036955 0.015307 0.006000
                rotation 0.639337 0.427191 -0.639340 2.334145
                children [
                  Shape {
                    appearance USE white
                    geometry Cylinder {
                      radius 0.006
                      height 0.012
                    }
                  }
                ]
                name "wheel_120_roller_13"
                boundingObject Cylinder {
                  radius 0.006
                  height 0.012
                }
                physics Physics {
                  density -1
                  mass 0.010000
                  centerOfMass [ 0.000000 0.000000 0.000000 ]
                  inertiaMatrix [
                    1.000000e-05 1.000000e-05 1.000000e-05
                    0.000000e+00 0.000000e+00 0.000000e+00
                  ]
                }
              }
            }
            HingeJoint {
              jointParameters HingeJointParameters {
                axis -0.707111 -0.707103 0.000003
                anchor -0.028284 0.028284 -0.006000
                dampingConstant 0.01
                staticFriction 0.01
              }
              device [
                RotationalMotor {
                  name "wheel_120_roller_14_joint"
                  maxTorque 10000
                }
                PositionSensor {
                  name "wheel_120_roller_14_joint_sensor"
                }
              ]
              endPoint Solid {
                translation -0.028284 0.028284 -0.006000
                rotation 0.678597 0.281083 -0.678600 2.593569
                children [
                  Shape {
                    appearance USE white
                    geometry Cylinder {
                      radius 0.006
                      height 0.012
                    }
                  }
                ]
                name "wheel_120_roller_14"
                boundingObject Cylinder {
                  radius 0.006
                  height 0.012
                }
                physics Physics {
                  density -1
                  mass 0.010000
                  centerOfMass [ 0.000000 0.000000 0.000000 ]
                  inertiaMatrix [
                    1.000000e-05 1.000000e-05 1.000000e-05
                    0.000000e+00 0.000000e+00 0.000000e+00
                  ]
                }
              }
            }
            HingeJoint {
              jointParameters HingeJointParameters {
                axis -0.923882 -0.382677 0.000003
                anchor -0.015307 0.036955 0.006000
                dampingConstant 0.01
                staticFriction 0.01
              }
              device [
                RotationalMotor {
                  name "wheel_120_roller_15_joint"
                  maxTorque 10000
                }
                PositionSensor {
                  name "wheel_120_roller_15_joint_sensor"
                }
              ]
              endPoint Solid {
                translation -0.015307 0.036955 0.006000
                rotation 0.700213 0.139279 -0.700216 2.864816
                children [
                  Shape {
                    appearance USE white
                    geometry Cylinder {
                      radius 0.006
                      height 0.012
                    }
                  }
                ]
                name "wheel_120_roller_15"
                boundingObject Cylinder {
                  radius 0.006
                  height 0.012
                }
                physics Physics {
                  density -1
                  mass 0.010000
                  centerOfMass [ 0.000000 0.000000 0.000000 ]
                  inertiaMatrix [
                    1.000000e-05 1.000000e-05 1.000000e-05
                    0.000000e+00 0.000000e+00 0.000000e+00
                  ]
                }
              }
            }
          ]
          name "wheel_120"
          boundingObject Cylinder {
            radius 0.04
            height 0.02
          }
          physics Physics {
            density -1
            mass 0.150000
            centerOfMass [ 0.000000 0.000000 0.000000 ]
            inertiaMatrix [
              2.000000e-04 2.000000e-04 2.000000e-04
              0.000000e+00 0.000000e+00 0.000000e+00
            ]
          }
        }
      }
      HingeJoint {
        jointParameters HingeJointParameters {
          axis -0.500004 -0.866023 -0.000004
          anchor -0.062500 -0.108250 -0.010000
          dampingConstant 0.1
          staticFriction 0.01
        }
        device [
          RotationalMotor {
            name "wheel_240_joint"
            maxVelocity 10.0
            maxTorque 10.0
          }
          PositionSensor {
            name "wheel_240_joint_sensor"
          }
        ]
        endPoint Solid {
          translation -0.062500 -0.108250 -0.010000
          rotation 0.654655 0.377963 -0.654653 2.418863
          children [
            Shape {
              appearance USE copper
              geometry Cylinder {
                radius 0.032
                height 0.02
              }
            }
            HingeJoint {
              jointParameters HingeJointParameters {
                axis 1.000000 0.000000 -0.000004
                anchor 0.000000 0.040000 -0.006000
                dampingConstant 0.01
                staticFriction 0.01
              }
              device [
                RotationalMotor {
                  name "wheel_240_roller_0_joint"
                  maxTorque 10000
                }
                PositionSensor {
                  name "wheel_240_roller_0_joint_sensor"
                }
              ]
              endPoint Solid {
                translation 0.000000 0.040000 -0.006000
                rotation 0.000000 1.000000 0.000000 1.570800
                children [
                  Shape {
                    appearance USE white
                    geometry Cylinder {
                      radius 0.006
                      height 0.012
                    }
                  }
                ]
                name "wheel_240_roller_0"
                boundingObject Cylinder {
                  radius 0.006
                  height 0.012
                }
                physics Physics {
                  density -1
                  mass 0.010000
                  centerOfMass [ 0.000000 0.000000 0.000000 ]
                  inertiaMatrix [
                    1.000000e-05 1.000000e-05 1.000000e-05
                    0.000000e+00 0.000000e+00 0.000000e+00
                  ]
                }
              }
            }
            HingeJoint {
              jointParameters HingeJointParameters {
                axis 0.923879 -0.382684 -0.000003
                anchor 0.015307 0.036955 0.006000
                dampingConstant 0.01
                staticFriction 0.01
              }
              device [
                RotationalMotor {
                  name "wheel_240_roller_1_joint"
                  maxTorque 10000
                }
                PositionSensor {
                  name "wheel_240_roller_1_joint_sensor"
                }
              ]
              endPoint Solid {
                translation 0.015307 0.036955 0.006000
                rotation 0.191480 0.962637 -0.191481 1.608869
                children [
                  Shape {
                    appearance USE white
                    geometry Cylinder {
                      radius 0.006
                      height 0.012
                    }
                  }
                ]
                name "wheel_240_roller_1"
                boundingObject Cylinder {
                  radius 0.006
                  height 0.012
                }
                physics Physics {
                  density -1
                  mass 0.010000
                  centerOfMass [ 0.000000 0.000000 0.000000 ]
                  inertiaMatrix [
                    1.000000e-05 1.000000e-05 1.000000e-05
                    0.000000e+00 0.000000e+00 0.000000e+00
                  ]
                }
              }
            }
            HingeJoint {
              jointParameters HingeJointParameters {
                axis 0.707105 -0.707108 -0.000003
                anchor 0.028284 0.028284 -0.006000
                dampingConstant 0.01
                staticFriction 0.01
              }
              device [
                RotationalMotor {
                  name "wheel_240_roller_2_joint"
                  maxTorque 10000
                }
                PositionSensor {
                  name "wheel_240_roller_2_joint_sensor"
                }
              ]
              endPoint Solid {
                translation 0.028284 0.028284 -0.006000
                rotation 0.357406 0.862856 -0.357408 1.717775
                children [
                  Shape {
                    appearance USE white
                    geometry Cylinder {
                      radius 0.006
                      height 0.012
                    }
                  }
                ]
                name "wheel_240_roller_2"
                boundingObject Cylinder {
                  radius 0.006
                  height 0.012
                }
                physics Physics {
                  density -1
                  mass 0.010000
                  centerOfMass [ 0.000000 0.000000 0.000000 ]
                  inertiaMatrix [
                    1.000000e-05 1.000000e-05 1.000000e-05
                    0.000000e+00 0.000000e+00 0.000000e+00
                  ]
                }
              }
            }
            HingeJoint {
              jointParameters HingeJointParameters {
                axis 0.382681 -0.923881 -0.000001
                anchor 0.036955 0.015307 0.006000
                dampingConstant 0.01
                staticFriction 0.01
              }
              device [
                RotationalMotor {
                  name "wheel_240_roller_3_joint"
                  maxTorque 10000
                }
                PositionSensor {
                  name "wheel_240_roller_3_joint_sensor"
                }
              ]
              endPoint Solid {
                translation 0.036955 0.015307 0.006000
                rotation 0.485652 0.726830 -0.485654 1.884582
                children [
                  Shape {
                    appearance USE white
                    geometry Cylinder {
                      radius 0.006
                      height 0.012
                    }
                  }
                ]
                name "wheel_240_roller_3"
                boundingObject Cylinder {
                  radius 0.006
                  height 0.012
                }
                physics Physics {
                  density -1
                  mass 0.010000
                  centerOfMass [ 0.000000 0.000000 0.000000 ]
                  inertiaMatrix [
                    1.000000e-05 1.000000e-05 1.000000e-05
                    0.000000e+00 0.000000e+00 0.000000e+00
                  ]
                }
              }
            }
            HingeJoint {
              jointParameters HingeJointParameters {
                axis -0.000004 -1.000000 0.000000
                anchor 0.040000 0.000000 -0.006000
                dampingConstant 0.01
                staticFriction 0.01
              }
              device [
                RotationalMotor {
                  name "wheel_240_roller_4_joint"
                  maxTorque 10000
                }
                PositionSensor {
                  name "wheel_240_roller_4_joint_sensor"
                }
              ]
              endPoint Solid {
                translation 0.040000 0.000000 -0.006000
                rotation 0.577350 0.577350 -0.577352 2.094399
                children [
                  Shape {
                    appearance USE white
                    geometry Cylinder {
                      radius 0.006
                      height 0.012
                    }
                  }
                ]
                name "wheel_240_roller_4"
                boundingObject Cylinder {
                  radius 0.006
                  height 0.012
                }
                physics Physics {
                  density -1
                  mass 0.010000
                  centerOfMass [ 0.000000 0.000000 0.000000 ]
                  inertiaMatrix [
                    1.000000e-05 1.000000e-05 1.000000e-05
                    0.000000e+00 0.000000e+00 0.000000e+00
                  ]
                }
              }
            }
            HingeJoint {
              jointParameters HingeJointParameters {
                axis -0.382688 -0.923878 0.000001
                anchor 0.036955 -0.015307 0.006000
                dampingConstant 0.01
                staticFriction 0.01
              }
              device [
                RotationalMotor {
                  name "wheel_240_roller_5_joint"
                  maxTorque 10000
                }
                PositionSensor {
                  name "wheel_240_roller_5_joint_sensor"
                }
              ]
              endPoint Solid {
                translation 0.036955 -0.015307 0.006000
                rotation 0.639337 0.427191 -0.639340 2.334145
                children [
                  Shape {
                    appearance USE white
                    geometry Cylinder {
                      radius 0.006
                      height 0.012
                    }
                  }
                ]
                name "wheel_240_roller_5"
                boundingObject Cylinder {
                  radius 0.006
                  height 0.012
                }
                physics Physics {
                  density -1
                  mass 0.010000
                  centerOfMass [ 0.000000 0.000000 0.000000 ]
                  inertiaMatrix [
                    1.000000e-05 1.000000e-05 1.000000e-05
                    0.000000e+00 0.000000e+00 0.000000e+00
                  ]
                }
              }
            }
            HingeJoint {
              jointParameters HingeJointParameters {
                axis -0.707111 -0.707103 0.000003
                anchor 0.028284 -0.028284 -0.006000
                dampingConstant 0.01
                staticFriction 0.01
              }
              device [
                RotationalMotor {
                  name "wheel_240_roller_6_joint"
                  maxTorque 10000
                }
                PositionSensor {
                  name "wheel_240_roller_6_joint_sensor"
                }
              ]
              endPoint Solid {
                translation 0.028284 -0.028284 -0.006000
                rotation 0.678597 0.281083 -0.678600 2.593569
                children [
                  Shape {
                    appearance USE white
                    geometry Cylinder {
                      radius 0.006
                      height 0.012
                    }
                  }
                ]
                name "wheel_240_roller_6"
                boundingObject Cylinder {
                  radius 0.006
                  height 0.012
                }
                physics Physics {
                  density -1
                  mass 0.010000
                  centerOfMass [ 0.000000 0.000000 0.000000 ]
                  inertiaMatrix [
                    1.000000e-05 1.000000e-05 1.000000e-05
                    0.000000e+00 0.000000e+00 0.000000e+00
                  ]
                }
              }
            }
            HingeJoint {
              jointParameters HingeJointParameters {
                axis -0.923882 -0.382677 0.000003
                anchor 0.015307 -0.036955 0.006000
                dampingConstant 0.01
                staticFriction 0.01
              }
              device [
                RotationalMotor {
                  name "wheel_240_roller_7_joint"
                  maxTorque 10000
                }
                PositionSensor {
                  name "wheel_240_roller_7_joint_sensor"
                }
              ]
              endPoint Solid {
                translation 0.015307 -0.036955 0.006000
                rotation 0.700213 0.139279 -0.700216 2.864816
                children [
                  Shape {
                    appearance USE white
                    geometry Cylinder {
                      radius 0.006
                      height 0.012
                    }
                  }
                ]
                name "wheel_240_roller_7"
                boundingObject Cylinder {
                  radius 0.006
                  height 0.012
                }
                physics Physics {
                  density -1
                  mass 0.010000
                  centerOfMass [ 0.000000 0.000000 0.000000 ]
                  inertiaMatrix [
                    1.000000e-05 1.000000e-05 1.000000e-05
                    0.000000e+00 0.000000e+00 0.000000e+00
                  ]
                }
              }
            }
            HingeJoint {
              jointParameters HingeJointParameters {
                axis 1.000000 0.000000 -0.000004
                anchor 0.000000 -0.040000 -0.006000
                dampingConstant 0.01
                staticFriction 0.01
              }
              device [
                RotationalMotor {
                  name "wheel_240_roller_8_joint"
                  maxTorque 10000
                }
                PositionSensor {
                  name "wheel_240_roller_8_joint_sensor"
                }
              ]
              endPoint Solid {
                translation 0.000000 -0.040000 -0.006000
                rotation 0.000000 1.000000 0.000000 1.570800
                children [
                  Shape {
                    appearance USE white
                    geometry Cylinder {
                      radius 0.006
                      height 0.012
                    }
                  }
                ]
                name "wheel_240_roller_8"
                boundingObject Cylinder {
                  radius 0.006
                  height 0.012
                }
                physics Physics {
                  density -1
                  mass 0.010000
                  centerOfMass [ 0.000000 0.000000 0.000000 ]
                  inertiaMatrix [
                    1.000000e-05 1.000000e-05 1.000000e-05
                    0.000000e+00 0.000000e+00 0.000000e+00
                  ]
                }
              }
            }
            HingeJoint {
              jointParameters HingeJointParameters {
                axis 0.923879 -0.382684 -0.000003
                anchor -0.015307 -0.036955 0.006000
                dampingConstant 0.01
                staticFriction 0.01
              }
              device [
                RotationalMotor {
                  name "wheel_240_roller_9_joint"
                  maxTorque 10000
                }
                PositionSensor {
                  name "wheel_240_roller_9_joint_sensor"
                }
              ]
              endPoint Solid {
                translation -0.015307 -0.036955 0.006000
                rotation 0.191480 0.962637 -0.191481 1.608869
                children [
                  Shape {
                    appearance USE white
                    geometry Cylinder {
                      radius 0.006
                      height 0.012
                    }
                  }
                ]
                name "wheel_240_roller_9"
                boundingObject Cylinder {
                  radius 0.006
                  height 0.012
                }
                physics Physics {
                  density -1
                  mass 0.010000
                  centerOfMass [ 0.000000 0.000000 0.000000 ]
                  inertiaMatrix [
                    1.000000e-05 1.000000e-05 1.000000e-05
                    0.000000e+00 0.000000e+00 0.000000e+00
                  ]
                }
              }
            }
            HingeJoint {
              jointParameters HingeJointParameters {
                axis 0.707105 -0.707108 -0.000003
                anchor -0.028284 -0.028284 -0.006000
                dampingConstant 0.01
                staticFriction 0.01
              }
              device [
                RotationalMotor {
                  name "wheel_240_roller_10_joint"
                  maxTorque 10000
                }
                PositionSensor {
                  name "wheel_240_roller_10_joint_sensor"
                }
              ]
              endPoint Solid {
                translation -0.028284 -0.028284 -0.006000
                rotation 0.357406 0.862856 -0.357408 1.717775
                children [
                  Shape {
                    appearance USE white
                    geometry Cylinder {
                      radius 0.006
                      height 0.012
                    }
                  }
                ]
                name "wheel_240_roller_10"
                boundingObject Cylinder {
                  radius 0.006
                  height 0.012
                }
                physics Physics {
                  density -1
                  mass 0.010000
                  centerOfMass [ 0.000000 0.000000 0.000000 ]
                  inertiaMatrix [
                    1.000000e-05 1.000000e-05 1.000000e-05
                    0.000000e+00 0.000000e+00 0.000000e+00
                  ]
                }
              }
            }
            HingeJoint {
              jointParameters HingeJointParameters {
                axis 0.382681 -0.923881 -0.000001
                anchor -0.036955 -0.015307 0.006000
                dampingConstant 0.01
                staticFriction 0.01
              }
              device [
                RotationalMotor {
                  name "wheel_240_roller_11_joint"
                  maxTorque 10000
                }
                PositionSensor {
                  name "wheel_240_roller_11_joint_sensor"
                }
              ]
              endPoint Solid {
                translation -0.036955 -0.015307 0.006000
                rotation 0.485652 0.726830 -0.485654 1.884582
                children [
                  Shape {
                    appearance USE white
                    geometry Cylinder {
                      radius 0.006
                      height 0.012
                    }
                  }
                ]
                name "wheel_240_roller_11"
                boundingObject Cylinder {
                  radius 0.006
                  height 0.012
                }
                physics Physics {
                  density -1
                  mass 0.010000
                  centerOfMass [ 0.000000 0.000000 0.000000 ]
                  inertiaMatrix [
                    1.000000e-05 1.000000e-05 1.000000e-05
                    0.000000e+00 0.000000e+00 0.000000e+00
                  ]
                }
              }
            }
            HingeJoint {
              jointParameters HingeJointParameters {
                axis -0.000004 -1.000000 0.000000
                anchor -0.040000 0.000000 -0.006000
                dampingConstant 0.01
                staticFriction 0.01
              }
              device [
                RotationalMotor {
                  name "wheel_240_roller_12_joint"
                  maxTorque 10000
                }
                PositionSensor {
                  name "wheel_240_roller_12_joint_sensor"
                }
              ]
              endPoint Solid {
                translation -0.040000 0.000000 -0.006000
                rotation 0.577350 0.577350 -0.577352 2.094399
                children [
                  Shape {
                    appearance USE white
                    geometry Cylinder {
                      radius 0.006
                      height 0.012
                    }
                  }
                ]
                name "wheel_240_roller_12"
                boundingObject Cylinder {
                  radius 0.006
                  height 0.012
                }
                physics Physics {
                  density -1
                  mass 0.010000
                  centerOfMass [ 0.000000 0.000000 0.000000 ]
                  inertiaMatrix [
                    1.000000e-05 1.000000e-05 1.000000e-05
                    0.000000e+00 0.000000e+00 0.000000e+00
                  ]
                }
              }
            }
            HingeJoint {
              jointParameters HingeJointParameters {
                axis -0.382688 -0.923878 0.000001
                anchor -0.036955 0.015307 0.006000
                dampingConstant 0.01
                staticFriction 0.01
              }
              device [
                RotationalMotor {
                  name "wheel_240_roller_13_joint"
                  maxTorque 10000
                }
                PositionSensor {
                  name "wheel_240_roller_13_joint_sensor"
                }
              ]
              endPoint Solid {
                translation -0.036955 0.015307 0.006000
                rotation 0.639337 0.427191 -0.639340 2.334145
                children [
                  Shape {
                    appearance USE white
                    geometry Cylinder {
                      radius 0.006
                      height 0.012
                    }
                  }
                ]
                name "wheel_240_roller_13"
                boundingObject Cylinder {
                  radius 0.006
                  height 0.012
                }
                physics Physics {
                  density -1
                  mass 0.010000
                  centerOfMass [ 0.000000 0.000000 0.000000 ]
                  inertiaMatrix [
                    1.000000e-05 1.000000e-05 1.000000e-05
                    0.000000e+00 0.000000e+00 0.000000e+00
                  ]
                }
              }
            }
            HingeJoint {
              jointParameters HingeJointParameters {
                axis -0.707111 -0.707103 0.000003
                anchor -0.028284 0.028284 -0.006000
                dampingConstant 0.01
                staticFriction 0.01
              }
              device [
                RotationalMotor {
                  name "wheel_240_roller_14_joint"
                  maxTorque 10000
                }
                PositionSensor {
                  name "wheel_240_roller_14_joint_sensor"
                }
              ]
              endPoint Solid {
                translation -0.028284 0.028284 -0.006000
                rotation 0.678597 0.281083 -0.678600 2.593569
                children [
                  Shape {
                    appearance USE white
                    geometry Cylinder {
                      radius 0.006
                      height 0.012
                    }
                  }
                ]
                name "wheel_240_roller_14"
                boundingObject Cylinder {
                  radius 0.006
                  height 0.012
                }
                physics Physics {
                  density -1
                  mass 0.010000
                  centerOfMass [ 0.000000 0.000000 0.000000 ]
                  inertiaMatrix [
                    1.000000e-05 1.000000e-05 1.000000e-05
                    0.000000e+00 0.000000e+00 0.000000e+00
                  ]
                }
              }
            }
            HingeJoint {
              jointParameters HingeJointParameters {
                axis -0.923882 -0.382677 0.000003
                anchor -0.015307 0.036955 0.006000
                dampingConstant 0.01
                staticFriction 0.01
              }
              device [
                RotationalMotor {
                  name "wheel_240_roller_15_joint"
                  maxTorque 10000
                }
                PositionSensor {
                  name "wheel_240_roller_15_joint_sensor"
                }
              ]
              endPoint Solid {
                translation -0.015307 0.036955 0.006000
                rotation 0.700213 0.139279 -0.700216 2.864816
                children [
                  Shape {
                    appearance USE white
                    geometry Cylinder {
                      radius 0.006
                      height 0.012
                    }
                  }
                ]
                name "wheel_240_roller_15"
                boundingObject Cylinder {
                  radius 0.006
                  height 0.012
                }
                physics Physics {
                  density -1
                  mass 0.010000
                  centerOfMass [ 0.000000 0.000000 0.000000 ]
                  inertiaMatrix [
                    1.000000e-05 1.000000e-05 1.000000e-05
                    0.000000e+00 0.000000e+00 0.000000e+00
                  ]
                }
              }
            }
          ]
          name "wheel_240"
          boundingObject Cylinder {
            radius 0.04
            height 0.02
          }
          physics Physics {
            density -1
            mass 0.150000
            centerOfMass [ 0.000000 0.000000 0.000000 ]
            inertiaMatrix [
              2.000000e-04 2.000000e-04 2.000000e-04
              0.000000e+00 0.000000e+00 0.000000e+00
            ]
          }
        }
      }
    ]
    name IS name
    boundingObject Cylinder {
      radius 0.11
      height 0.064
    }
    physics Physics {
      density -1
      mass 1.000000
      centerOfMass [ 0.000000 0.000000 0.000000 ]
      inertiaMatrix [
        1.000000e-03 1.000000e-03 1.000000e-03
        0.000000e+00 0.000000e+00 0.000000e+00
      ]
    }
  }
}
