#VRML_SIM R2025a utf8
# license: Apache License 2.0
# license url: http://www.apache.org/licenses/LICENSE-2.0
# This is a proto file for Webots for the omni_1
# Extracted from: /home/hostuser/omni-1-ws/src/omni_1_description/urdf/omni_1.urdf

PROTO omni_1 [
  field  SFVec3f     translation     0 0 0
  field  SFRotation  rotation        0 0 1 0
  field  SFString    name            "omni_1"  # Is `Robot.name`.
  field  SFString    controller      "void"  # Is `Robot.controller`.
  field  MFString    controllerArgs  []      # Is `Robot.controllerArgs`.
  field  SFString    customData      ""      # Is `Robot.customData`.
  field  SFBool      supervisor      FALSE   # Is `Robot.supervisor`.
  field  SFBool      synchronization TRUE    # Is `Robot.synchronization`.
  field  SFBool      selfCollision   FALSE   # Is `Robot.selfCollision`.
]
{
  Robot {
    translation IS translation
    rotation IS rotation
    controller IS controller
    controllerArgs IS controllerArgs
    customData IS customData
    supervisor IS supervisor
    synchronization IS synchronization
    selfCollision IS selfCollision
    children [
      Transform {
        scale 0.001000 0.001000 0.001000
        children [
          Shape {
            appearance DEF silver PBRAppearance {
              baseColor 0.500000 0.500000 0.500000
              roughness 1.000000
              metalness 0
            }
            geometry DEF base_link Mesh {
              url "/home/hostuser/omni-1-ws/src/omni_1_description/meshes/base_link.stl"
            }
          }
        ]
      }
      HingeJoint {
        jointParameters HingeJointParameters {
          axis 0.000000 -1.000000 0.000000
          anchor 0.000000 -0.100000 0.000000
        }
        device [
          RotationalMotor {
            name "wheel-frame0"
            maxVelocity 100.0
            maxTorque 100.0
          }
          PositionSensor {
            name "wheel-frame0_sensor"
          }
        ]
        endPoint Solid {
          translation 0.000000 -0.100000 0.000000
          children [
            Transform {
              scale 0.001000 0.001000 0.001000
              children [
                Shape {
                  appearance DEF grey PBRAppearance {
                    baseColor 0.500000 0.500000 0.500000
                    roughness 1.000000
                    metalness 0
                  }
                  geometry DEF wheel-frame0 Mesh {
                    url "/home/hostuser/omni-1-ws/src/omni_1_description/meshes/wheel-frame0.stl"
                  }
                }
              ]
            }
            HingeJoint {
              jointParameters HingeJointParameters {
                anchor 0.000000 0.013000 0.024000
                dampingConstant 0.01
                staticFriction 0.1
              }
              device [
                RotationalMotor {
                  name "wheel0-roller0"
                  maxTorque 10000
                }
                PositionSensor {
                  name "wheel0-roller0_sensor"
                }
              ]
              endPoint Solid {
                translation 0.000000 0.013000 0.024000
                children [
                  Transform {
                    translation 0.000000 0.000000 -0.024000
                    scale 0.001000 0.001000 0.001000
                    children [
                      Shape {
                        appearance DEF black PBRAppearance {
                          baseColor 0.500000 0.500000 0.500000
                          roughness 1.000000
                          metalness 0
                        }
                        geometry DEF roller Mesh {
                          url "/home/hostuser/omni-1-ws/src/omni_1_description/meshes/roller.stl"
                        }
                      }
                    ]
                  }
                ]
                name "roller-0-0"
                boundingObject Pose {
                  translation 0.000000 0.000000 -0.024000
                  children [
                    USE roller
                  ]
                }
                physics Physics {
                  density -1
                  mass 0.020000
                  centerOfMass [ 0.000000 0.000000 0.000000 ]
                  inertiaMatrix [
                    2.700000e-06 2.700000e-06 1.000000e-06
                    0.000000e+00 0.000000e+00 0.000000e+00
                  ]
                }
              }
            }
            HingeJoint {
              jointParameters HingeJointParameters {
                axis -0.500000 0.000000 -0.866025
                anchor 0.020785 0.013000 -0.012000
                dampingConstant 0.01
                staticFriction 0.1
              }
              device [
                RotationalMotor {
                  name "wheel0-roller1"
                  maxTorque 10000
                }
                PositionSensor {
                  name "wheel0-roller1_sensor"
                }
              ]
              endPoint Solid {
                translation 0.020785 0.013000 -0.012000
                rotation 0.000000 1.000000 0.000000 2.094395
                children [
                  Transform {
                    translation 0.000000 0.000000 -0.024000
                    scale 0.001000 0.001000 0.001000
                    children [
                      Shape {
                        appearance USE black
                        geometry USE roller
                      }
                    ]
                  }
                ]
                name "roller-0-1"
                boundingObject Pose {
                  translation 0.000000 0.000000 -0.024000
                  children [
                    USE roller
                  ]
                }
                physics Physics {
                  density -1
                  mass 0.020000
                  centerOfMass [ 0.000000 0.000000 0.000000 ]
                  inertiaMatrix [
                    2.700000e-06 2.700000e-06 1.000000e-06
                    0.000000e+00 0.000000e+00 0.000000e+00
                  ]
                }
              }
            }
            HingeJoint {
              jointParameters HingeJointParameters {
                axis -0.500000 0.000000 0.866025
                anchor -0.020785 0.013000 -0.012000
                dampingConstant 0.01
                staticFriction 0.1
              }
              device [
                RotationalMotor {
                  name "wheel0-roller2"
                  maxTorque 10000
                }
                PositionSensor {
                  name "wheel0-roller2_sensor"
                }
              ]
              endPoint Solid {
                translation -0.020785 0.013000 -0.012000
                rotation -0.000000 1.000000 -0.000000 4.188790
                children [
                  Transform {
                    translation 0.000000 0.000000 -0.024000
                    scale 0.001000 0.001000 0.001000
                    children [
                      Shape {
                        appearance USE black
                        geometry USE roller
                      }
                    ]
                  }
                ]
                name "roller-0-2"
                boundingObject Pose {
                  translation 0.000000 0.000000 -0.024000
                  children [
                    USE roller
                  ]
                }
                physics Physics {
                  density -1
                  mass 0.020000
                  centerOfMass [ 0.000000 0.000000 0.000000 ]
                  inertiaMatrix [
                    2.700000e-06 2.700000e-06 1.000000e-06
                    0.000000e+00 0.000000e+00 0.000000e+00
                  ]
                }
              }
            }
            HingeJoint {
              jointParameters HingeJointParameters {
                axis 0.500000 0.000000 -0.866025
                anchor 0.020785 -0.013000 0.012000
                dampingConstant 0.01
                staticFriction 0.1
              }
              device [
                RotationalMotor {
                  name "wheel0-roller3"
                  maxTorque 10000
                }
                PositionSensor {
                  name "wheel0-roller3_sensor"
                }
              ]
              endPoint Solid {
                translation 0.020785 -0.013000 0.012000
                rotation 0.000000 1.000000 0.000000 1.047198
                children [
                  Transform {
                    translation 0.000000 0.000000 -0.024000
                    scale 0.001000 0.001000 0.001000
                    children [
                      Shape {
                        appearance USE black
                        geometry USE roller
                      }
                    ]
                  }
                ]
                name "roller-0-3"
                boundingObject Pose {
                  translation 0.000000 0.000000 -0.024000
                  children [
                    USE roller
                  ]
                }
                physics Physics {
                  density -1
                  mass 0.020000
                  centerOfMass [ 0.000000 0.000000 0.000000 ]
                  inertiaMatrix [
                    2.700000e-06 2.700000e-06 1.000000e-06
                    0.000000e+00 0.000000e+00 0.000000e+00
                  ]
                }
              }
            }
            HingeJoint {
              jointParameters HingeJointParameters {
                axis -1.000000 0.000000 0.000000
                anchor 0.000000 -0.013000 -0.024000
                dampingConstant 0.01
                staticFriction 0.1
              }
              device [
                RotationalMotor {
                  name "wheel0-roller4"
                  maxTorque 10000
                }
                PositionSensor {
                  name "wheel0-roller4_sensor"
                }
              ]
              endPoint Solid {
                translation 0.000000 -0.013000 -0.024000
                rotation -0.000000 1.000000 -0.000000 3.141593
                children [
                  Transform {
                    translation 0.000000 0.000000 -0.024000
                    scale 0.001000 0.001000 0.001000
                    children [
                      Shape {
                        appearance USE black
                        geometry USE roller
                      }
                    ]
                  }
                ]
                name "roller-0-4"
                boundingObject Pose {
                  translation 0.000000 0.000000 -0.024000
                  children [
                    USE roller
                  ]
                }
                physics Physics {
                  density -1
                  mass 0.020000
                  centerOfMass [ 0.000000 0.000000 0.000000 ]
                  inertiaMatrix [
                    2.700000e-06 2.700000e-06 1.000000e-06
                    0.000000e+00 0.000000e+00 0.000000e+00
                  ]
                }
              }
            }
            HingeJoint {
              jointParameters HingeJointParameters {
                axis 0.500000 0.000000 0.866025
                anchor -0.020785 -0.013000 0.012000
                dampingConstant 0.01
                staticFriction 0.1
              }
              device [
                RotationalMotor {
                  name "wheel0-roller5"
                  maxTorque 10000
                }
                PositionSensor {
                  name "wheel0-roller5_sensor"
                }
              ]
              endPoint Solid {
                translation -0.020785 -0.013000 0.012000
                rotation -0.000000 1.000000 -0.000000 5.235988
                children [
                  Transform {
                    translation 0.000000 0.000000 -0.024000
                    scale 0.001000 0.001000 0.001000
                    children [
                      Shape {
                        appearance USE black
                        geometry USE roller
                      }
                    ]
                  }
                ]
                name "roller-0-5"
                boundingObject Pose {
                  translation 0.000000 0.000000 -0.024000
                  children [
                    USE roller
                  ]
                }
                physics Physics {
                  density -1
                  mass 0.020000
                  centerOfMass [ 0.000000 0.000000 0.000000 ]
                  inertiaMatrix [
                    2.700000e-06 2.700000e-06 1.000000e-06
                    0.000000e+00 0.000000e+00 0.000000e+00
                  ]
                }
              }
            }
          ]
          name "wheel-frame0"
          boundingObject USE wheel-frame0
          physics Physics {
            density -1
            mass 0.500000
            centerOfMass [ 0.000000 0.000000 0.000000 ]
            inertiaMatrix [
              1.700000e-04 1.800000e-04 1.700000e-04
              0.000000e+00 0.000000e+00 0.000000e+00
            ]
          }
        }
      }
      HingeJoint {
        jointParameters HingeJointParameters {
          axis 0.866025 0.500000 0.000000
          anchor 0.086603 0.050000 0.000000
        }
        device [
          RotationalMotor {
            name "wheel-frame120"
            maxVelocity 100.0
            maxTorque 100.0
          }
          PositionSensor {
            name "wheel-frame120_sensor"
          }
        ]
        endPoint Solid {
          translation 0.086603 0.050000 0.000000
          rotation 0.000000 0.000000 1.000000 2.094395
          children [
            Transform {
              scale 0.001000 0.001000 0.001000
              children [
                Shape {
                  appearance USE grey
                  geometry DEF wheel-frame120 Mesh {
                    url "/home/hostuser/omni-1-ws/src/omni_1_description/meshes/wheel-frame120.stl"
                  }
                }
              ]
            }
            HingeJoint {
              jointParameters HingeJointParameters {
                anchor 0.000000 0.013000 0.024000
                dampingConstant 0.01
                staticFriction 0.1
              }
              device [
                RotationalMotor {
                  name "wheel120-roller0"
                  maxTorque 10000
                }
                PositionSensor {
                  name "wheel120-roller0_sensor"
                }
              ]
              endPoint Solid {
                translation 0.000000 0.013000 0.024000
                children [
                  Transform {
                    translation 0.000000 0.000000 -0.024000
                    scale 0.001000 0.001000 0.001000
                    children [
                      Shape {
                        appearance USE black
                        geometry USE roller
                      }
                    ]
                  }
                ]
                name "roller-1-0"
                boundingObject Pose {
                  translation 0.000000 0.000000 -0.024000
                  children [
                    USE roller
                  ]
                }
                physics Physics {
                  density -1
                  mass 0.020000
                  centerOfMass [ 0.000000 0.000000 0.000000 ]
                  inertiaMatrix [
                    2.700000e-06 2.700000e-06 1.000000e-06
                    0.000000e+00 0.000000e+00 0.000000e+00
                  ]
                }
              }
            }
            HingeJoint {
              jointParameters HingeJointParameters {
                axis -0.500000 0.000000 -0.866025
                anchor 0.020785 0.013000 -0.012000
                dampingConstant 0.01
                staticFriction 0.1
              }
              device [
                RotationalMotor {
                  name "wheel120-roller1"
                  maxTorque 10000
                }
                PositionSensor {
                  name "wheel120-roller1_sensor"
                }
              ]
              endPoint Solid {
                translation 0.020785 0.013000 -0.012000
                rotation 0.000000 1.000000 0.000000 2.094395
                children [
                  Transform {
                    translation 0.000000 0.000000 -0.024000
                    scale 0.001000 0.001000 0.001000
                    children [
                      Shape {
                        appearance USE black
                        geometry USE roller
                      }
                    ]
                  }
                ]
                name "roller-1-1"
                boundingObject Pose {
                  translation 0.000000 0.000000 -0.024000
                  children [
                    USE roller
                  ]
                }
                physics Physics {
                  density -1
                  mass 0.020000
                  centerOfMass [ 0.000000 0.000000 0.000000 ]
                  inertiaMatrix [
                    2.700000e-06 2.700000e-06 1.000000e-06
                    0.000000e+00 0.000000e+00 0.000000e+00
                  ]
                }
              }
            }
            HingeJoint {
              jointParameters HingeJointParameters {
                axis -0.500000 0.000000 0.866025
                anchor -0.020785 0.013000 -0.012000
                dampingConstant 0.01
                staticFriction 0.1
              }
              device [
                RotationalMotor {
                  name "wheel120-roller2"
                  maxTorque 10000
                }
                PositionSensor {
                  name "wheel120-roller2_sensor"
                }
              ]
              endPoint Solid {
                translation -0.020785 0.013000 -0.012000
                rotation -0.000000 1.000000 -0.000000 4.188790
                children [
                  Transform {
                    translation 0.000000 0.000000 -0.024000
                    scale 0.001000 0.001000 0.001000
                    children [
                      Shape {
                        appearance USE black
                        geometry USE roller
                      }
                    ]
                  }
                ]
                name "roller-1-2"
                boundingObject Pose {
                  translation 0.000000 0.000000 -0.024000
                  children [
                    USE roller
                  ]
                }
                physics Physics {
                  density -1
                  mass 0.020000
                  centerOfMass [ 0.000000 0.000000 0.000000 ]
                  inertiaMatrix [
                    2.700000e-06 2.700000e-06 1.000000e-06
                    0.000000e+00 0.000000e+00 0.000000e+00
                  ]
                }
              }
            }
            HingeJoint {
              jointParameters HingeJointParameters {
                axis 0.500000 0.000000 -0.866025
                anchor 0.020785 -0.013000 0.012000
                dampingConstant 0.01
                staticFriction 0.1
              }
              device [
                RotationalMotor {
                  name "wheel120-roller3"
                  maxTorque 10000
                }
                PositionSensor {
                  name "wheel120-roller3_sensor"
                }
              ]
              endPoint Solid {
                translation 0.020785 -0.013000 0.012000
                rotation 0.000000 1.000000 0.000000 1.047198
                children [
                  Transform {
                    translation 0.000000 0.000000 -0.024000
                    scale 0.001000 0.001000 0.001000
                    children [
                      Shape {
                        appearance USE black
                        geometry USE roller
                      }
                    ]
                  }
                ]
                name "roller-1-3"
                boundingObject Pose {
                  translation 0.000000 0.000000 -0.024000
                  children [
                    USE roller
                  ]
                }
                physics Physics {
                  density -1
                  mass 0.020000
                  centerOfMass [ 0.000000 0.000000 0.000000 ]
                  inertiaMatrix [
                    2.700000e-06 2.700000e-06 1.000000e-06
                    0.000000e+00 0.000000e+00 0.000000e+00
                  ]
                }
              }
            }
            HingeJoint {
              jointParameters HingeJointParameters {
                axis -1.000000 0.000000 0.000000
                anchor 0.000000 -0.013000 -0.024000
                dampingConstant 0.01
                staticFriction 0.1
              }
              device [
                RotationalMotor {
                  name "wheel120-roller4"
                  maxTorque 10000
                }
                PositionSensor {
                  name "wheel120-roller4_sensor"
                }
              ]
              endPoint Solid {
                translation 0.000000 -0.013000 -0.024000
                rotation -0.000000 1.000000 -0.000000 3.141593
                children [
                  Transform {
                    translation 0.000000 0.000000 -0.024000
                    scale 0.001000 0.001000 0.001000
                    children [
                      Shape {
                        appearance USE black
                        geometry USE roller
                      }
                    ]
                  }
                ]
                name "roller-1-4"
                boundingObject Pose {
                  translation 0.000000 0.000000 -0.024000
                  children [
                    USE roller
                  ]
                }
                physics Physics {
                  density -1
                  mass 0.020000
                  centerOfMass [ 0.000000 0.000000 0.000000 ]
                  inertiaMatrix [
                    2.700000e-06 2.700000e-06 1.000000e-06
                    0.000000e+00 0.000000e+00 0.000000e+00
                  ]
                }
              }
            }
            HingeJoint {
              jointParameters HingeJointParameters {
                axis 0.500000 0.000000 0.866025
                anchor -0.020785 -0.013000 0.012000
                dampingConstant 0.01
                staticFriction 0.1
              }
              device [
                RotationalMotor {
                  name "wheel120-roller5"
                  maxTorque 10000
                }
                PositionSensor {
                  name "wheel120-roller5_sensor"
                }
              ]
              endPoint Solid {
                translation -0.020785 -0.013000 0.012000
                rotation -0.000000 1.000000 -0.000000 5.235988
                children [
                  Transform {
                    translation 0.000000 0.000000 -0.024000
                    scale 0.001000 0.001000 0.001000
                    children [
                      Shape {
                        appearance USE black
                        geometry USE roller
                      }
                    ]
                  }
                ]
                name "roller-1-5"
                boundingObject Pose {
                  translation 0.000000 0.000000 -0.024000
                  children [
                    USE roller
                  ]
                }
                physics Physics {
                  density -1
                  mass 0.020000
                  centerOfMass [ 0.000000 0.000000 0.000000 ]
                  inertiaMatrix [
                    2.700000e-06 2.700000e-06 1.000000e-06
                    0.000000e+00 0.000000e+00 0.000000e+00
                  ]
                }
              }
            }
          ]
          name "wheel-frame120"
          boundingObject USE wheel-frame120
          physics Physics {
            density -1
            mass 0.500000
            centerOfMass [ 0.000000 0.000000 0.000000 ]
            inertiaMatrix [
              1.700000e-04 1.800000e-04 1.700000e-04
              0.000000e+00 0.000000e+00 0.000000e+00
            ]
          }
        }
      }
      HingeJoint {
        jointParameters HingeJointParameters {
          axis -0.866025 0.500000 0.000000
          anchor -0.086603 0.050000 0.000000
        }
        device [
          RotationalMotor {
            name "wheel-frame240"
            maxVelocity 100.0
            maxTorque 100.0
          }
          PositionSensor {
            name "wheel-frame240_sensor"
          }
        ]
        endPoint Solid {
          translation -0.086603 0.050000 0.000000
          rotation -0.000000 0.000000 1.000000 4.188790
          children [
            Transform {
              scale 0.001000 0.001000 0.001000
              children [
                Shape {
                  appearance USE grey
                  geometry DEF wheel-frame240 Mesh {
                    url "/home/hostuser/omni-1-ws/src/omni_1_description/meshes/wheel-frame240.stl"
                  }
                }
              ]
            }
            HingeJoint {
              jointParameters HingeJointParameters {
                anchor 0.000000 0.013000 0.024000
                dampingConstant 0.01
                staticFriction 0.1
              }
              device [
                RotationalMotor {
                  name "wheel240-roller0"
                  maxTorque 10000
                }
                PositionSensor {
                  name "wheel240-roller0_sensor"
                }
              ]
              endPoint Solid {
                translation 0.000000 0.013000 0.024000
                children [
                  Transform {
                    translation 0.000000 0.000000 -0.024000
                    scale 0.001000 0.001000 0.001000
                    children [
                      Shape {
                        appearance USE black
                        geometry USE roller
                      }
                    ]
                  }
                ]
                name "roller-2-0"
                boundingObject Pose {
                  translation 0.000000 0.000000 -0.024000
                  children [
                    USE roller
                  ]
                }
                physics Physics {
                  density -1
                  mass 0.020000
                  centerOfMass [ 0.000000 0.000000 0.000000 ]
                  inertiaMatrix [
                    2.700000e-06 2.700000e-06 1.000000e-06
                    0.000000e+00 0.000000e+00 0.000000e+00
                  ]
                }
              }
            }
            HingeJoint {
              jointParameters HingeJointParameters {
                axis -0.500000 0.000000 -0.866025
                anchor 0.020785 0.013000 -0.012000
                dampingConstant 0.01
                staticFriction 0.1
              }
              device [
                RotationalMotor {
                  name "wheel240-roller1"
                  maxTorque 10000
                }
                PositionSensor {
                  name "wheel240-roller1_sensor"
                }
              ]
              endPoint Solid {
                translation 0.020785 0.013000 -0.012000
                rotation 0.000000 1.000000 0.000000 2.094395
                children [
                  Transform {
                    translation 0.000000 0.000000 -0.024000
                    scale 0.001000 0.001000 0.001000
                    children [
                      Shape {
                        appearance USE black
                        geometry USE roller
                      }
                    ]
                  }
                ]
                name "roller-2-1"
                boundingObject Pose {
                  translation 0.000000 0.000000 -0.024000
                  children [
                    USE roller
                  ]
                }
                physics Physics {
                  density -1
                  mass 0.020000
                  centerOfMass [ 0.000000 0.000000 0.000000 ]
                  inertiaMatrix [
                    2.700000e-06 2.700000e-06 1.000000e-06
                    0.000000e+00 0.000000e+00 0.000000e+00
                  ]
                }
              }
            }
            HingeJoint {
              jointParameters HingeJointParameters {
                axis -0.500000 0.000000 0.866025
                anchor -0.020785 0.013000 -0.012000
                dampingConstant 0.01
                staticFriction 0.1
              }
              device [
                RotationalMotor {
                  name "wheel240-roller2"
                  maxTorque 10000
                }
                PositionSensor {
                  name "wheel240-roller2_sensor"
                }
              ]
              endPoint Solid {
                translation -0.020785 0.013000 -0.012000
                rotation -0.000000 1.000000 -0.000000 4.188790
                children [
                  Transform {
                    translation 0.000000 0.000000 -0.024000
                    scale 0.001000 0.001000 0.001000
                    children [
                      Shape {
                        appearance USE black
                        geometry USE roller
                      }
                    ]
                  }
                ]
                name "roller-2-2"
                boundingObject Pose {
                  translation 0.000000 0.000000 -0.024000
                  children [
                    USE roller
                  ]
                }
                physics Physics {
                  density -1
                  mass 0.020000
                  centerOfMass [ 0.000000 0.000000 0.000000 ]
                  inertiaMatrix [
                    2.700000e-06 2.700000e-06 1.000000e-06
                    0.000000e+00 0.000000e+00 0.000000e+00
                  ]
                }
              }
            }
            HingeJoint {
              jointParameters HingeJointParameters {
                axis 0.500000 0.000000 -0.866025
                anchor 0.020785 -0.013000 0.012000
                dampingConstant 0.01
                staticFriction 0.1
              }
              device [
                RotationalMotor {
                  name "wheel240-roller3"
                  maxTorque 10000
                }
                PositionSensor {
                  name "wheel240-roller3_sensor"
                }
              ]
              endPoint Solid {
                translation 0.020785 -0.013000 0.012000
                rotation 0.000000 1.000000 0.000000 1.047198
                children [
                  Transform {
                    translation 0.000000 0.000000 -0.024000
                    scale 0.001000 0.001000 0.001000
                    children [
                      Shape {
                        appearance USE black
                        geometry USE roller
                      }
                    ]
                  }
                ]
                name "roller-2-3"
                boundingObject Pose {
                  translation 0.000000 0.000000 -0.024000
                  children [
                    USE roller
                  ]
                }
                physics Physics {
                  density -1
                  mass 0.020000
                  centerOfMass [ 0.000000 0.000000 0.000000 ]
                  inertiaMatrix [
                    2.700000e-06 2.700000e-06 1.000000e-06
                    0.000000e+00 0.000000e+00 0.000000e+00
                  ]
                }
              }
            }
            HingeJoint {
              jointParameters HingeJointParameters {
                axis -1.000000 0.000000 0.000000
                anchor 0.000000 -0.013000 -0.024000
                dampingConstant 0.01
                staticFriction 0.1
              }
              device [
                RotationalMotor {
                  name "wheel240-roller4"
                  maxTorque 10000
                }
                PositionSensor {
                  name "wheel240-roller4_sensor"
                }
              ]
              endPoint Solid {
                translation 0.000000 -0.013000 -0.024000
                rotation -0.000000 1.000000 -0.000000 3.141593
                children [
                  Transform {
                    translation 0.000000 0.000000 -0.024000
                    scale 0.001000 0.001000 0.001000
                    children [
                      Shape {
                        appearance USE black
                        geometry USE roller
                      }
                    ]
                  }
                ]
                name "roller-2-4"
                boundingObject Pose {
                  translation 0.000000 0.000000 -0.024000
                  children [
                    USE roller
                  ]
                }
                physics Physics {
                  density -1
                  mass 0.020000
                  centerOfMass [ 0.000000 0.000000 0.000000 ]
                  inertiaMatrix [
                    2.700000e-06 2.700000e-06 1.000000e-06
                    0.000000e+00 0.000000e+00 0.000000e+00
                  ]
                }
              }
            }
            HingeJoint {
              jointParameters HingeJointParameters {
                axis 0.500000 0.000000 0.866025
                anchor -0.020785 -0.013000 0.012000
                dampingConstant 0.01
                staticFriction 0.1
              }
              device [
                RotationalMotor {
                  name "wheel240-roller5"
                  maxTorque 10000
                }
                PositionSensor {
                  name "wheel240-roller5_sensor"
                }
              ]
              endPoint Solid {
                translation -0.020785 -0.013000 0.012000
                rotation -0.000000 1.000000 -0.000000 5.235988
                children [
                  Transform {
                    translation 0.000000 0.000000 -0.024000
                    scale 0.001000 0.001000 0.001000
                    children [
                      Shape {
                        appearance USE black
                        geometry USE roller
                      }
                    ]
                  }
                ]
                name "roller-2-5"
                boundingObject Pose {
                  translation 0.000000 0.000000 -0.024000
                  children [
                    USE roller
                  ]
                }
                physics Physics {
                  density -1
                  mass 0.020000
                  centerOfMass [ 0.000000 0.000000 0.000000 ]
                  inertiaMatrix [
                    2.700000e-06 2.700000e-06 1.000000e-06
                    0.000000e+00 0.000000e+00 0.000000e+00
                  ]
                }
              }
            }
          ]
          name "wheel-frame240"
          boundingObject USE wheel-frame240
          physics Physics {
            density -1
            mass 0.500000
            centerOfMass [ 0.000000 0.000000 0.000000 ]
            inertiaMatrix [
              1.700000e-04 1.800000e-04 1.700000e-04
              0.000000e+00 0.000000e+00 0.000000e+00
            ]
          }
        }
      }
    ]
    name IS name
    boundingObject USE base_link
    physics Physics {
      density -1
      mass 4.800000
      centerOfMass [ 0.000000 0.000000 3.800000 ]
    }
  }
}
