#VRML_SIM R2025a utf8
# license: Apache License 2.0
# license url: http://www.apache.org/licenses/LICENSE-2.0
# This is a proto file for Webots for the omni-1
# Extracted from: /home/hostuser/omni-1-ws/src/omni_1_description/urdf/omni_1.urdf

PROTO omni-1 [
  field  SFVec3f     translation     0 0 0
  field  SFRotation  rotation        0 0 1 0
  field  SFString    name            "omni-1"  # Is `Robot.name`.
  field  SFString    controller      "extern"  # Is `Robot.controller`.
  field  MFString    controllerArgs  []        # Is `Robot.controllerArgs`.
  field  SFString    customData      ""        # Is `Robot.customData`.
  field  SFBool      supervisor      FALSE     # Is `Robot.supervisor`.
  field  SFBool      synchronization TRUE      # Is `Robot.synchronization`.
  field  SFBool      selfCollision   FALSE     # Is `Robot.selfCollision`.
]
{
  Robot {
    translation IS translation
    rotation IS rotation
    controller IS controller
    controllerArgs IS controllerArgs
    customData IS customData
    supervisor IS supervisor
    synchronization IS synchronization
    selfCollision IS selfCollision
    children [
      ContactProperties {
          material1 "black"
          material2 "default"
          coulombFriction 1.0
          bounce 0.0
          forceDependentSlip 0.1
          maxContactJoints 30
        }
      Shape {
        appearance DEF silver PBRAppearance {
          baseColor 0.800000 0.800000 0.800000
          roughness 0.400000
          metalness 0.4
        }
        geometry DEF base_link Mesh {
          url "/home/hostuser/omni-1-ws/src/omni_1_description/meshes/base_link.stl"
        }
      }
      HingeJoint {
        jointParameters HingeJointParameters {
          axis 0.000000 -1.000000 0.000000
          anchor 0.000000 -0.100000 0.000000
        }
        device [
          RotationalMotor {
            name "wheel-frame60"
            maxVelocity 20.0
            maxTorque 10.0
          }
          PositionSensor {
            name "wheel-frame60_sensor"
          }
        ]
        endPoint Solid {
          translation 0.000000 -0.100000 0.000000
          children [
            Shape {
              appearance DEF grey PBRAppearance {
                baseColor 0.400000 0.400000 0.400000
                roughness 1.000000
                metalness 0
              }
              geometry DEF wheel_frame Mesh {
                url "/home/hostuser/omni-1-ws/src/omni_1_description/meshes/wheel_frame.stl"
              }
            }
            HingeJoint {
              jointParameters HingeJointParameters {
                anchor 0.000000 0.013000 0.024000
                dampingConstant 0
                staticFriction 0.01
              }
              device [
                RotationalMotor {
                  name "wheel60-roller0"
                  maxVelocity 100.0
                  maxTorque 0
                }
                PositionSensor {
                  name "wheel60-roller0_sensor"
                }
              ]
              endPoint Solid {
                translation 0.000000 0.013000 0.024000
                children [
                  Pose {
                    translation 0.000000 0.000000 -0.024000
                    children [
                      Shape {
                        appearance DEF black PBRAppearance {
                          baseColor 0.200000 0.200000 0.200000
                          roughness 1.000000
                          metalness 0
                          physics Material {
                            name "black"
                          }
                        }
                        geometry DEF roller Mesh {
                          url "/home/hostuser/omni-1-ws/src/omni_1_description/meshes/roller.stl"
                        }
                      }
                    ]
                  }
                ]
                name "roller-0-0"
                boundingObject Pose {
                  translation 0.000000 0.000000 -0.024000
                  children [
                    USE roller
                  ]
                }
                physics Physics {
                  density -1
                  mass 0.0020000
                  centerOfMass [ 0.000000 0.000000 0.000000 ]
                  inertiaMatrix [
                    2.700000e-06 2.700000e-06 1.000000e-06
                    0.000000e+00 0.000000e+00 0.000000e+00
                  ]
                  damping Damping {
                    linear  0.01
                    angular 0.01
                  }
                  restitution 0.0
                }
              }
            }
            HingeJoint {
              jointParameters HingeJointParameters {
                axis -0.500000 0.000000 -0.866025
                anchor 0.020785 0.013000 -0.012000
                dampingConstant 0
                staticFriction 0.01
              }
              device [
                RotationalMotor {
                  name "wheel60-roller1"
                  maxTorque 0
                  maxVelocity 100.0
                }
                PositionSensor {
                  name "wheel60-roller1_sensor"
                }
              ]
              endPoint Solid {
                translation 0.020785 0.013000 -0.012000
                rotation 0.000000 1.000000 0.000000 2.094395
                children [
                  Pose {
                    translation 0.000000 0.000000 -0.024000
                    children [
                      Shape {
                        appearance USE black
                        geometry USE roller
                      }
                    ]
                  }
                ]
                name "roller-0-1"
                boundingObject Pose {
                  translation 0.000000 0.000000 -0.024000
                  children [
                    USE roller
                  ]
                }
                physics Physics {
                  density -1
                  mass 0.0020000
                  centerOfMass [ 0.000000 0.000000 0.000000 ]
                  inertiaMatrix [
                    2.700000e-06 2.700000e-06 1.000000e-06
                    0.000000e+00 0.000000e+00 0.000000e+00
                  ]
                  damping Damping {
                    linear  0.01
                    angular 0.01
                  }
                  restitution 0.0
                }
              }
            }
            HingeJoint {
              jointParameters HingeJointParameters {
                axis -0.500000 0.000000 0.866025
                anchor -0.020785 0.013000 -0.012000
                dampingConstant 0
                staticFriction 0.01
              }
              device [
                RotationalMotor {
                  name "wheel60-roller2"
                  maxTorque 0
                  maxVelocity 100.0
                }
                PositionSensor {
                  name "wheel60-roller2_sensor"
                }
              ]
              endPoint Solid {
                translation -0.020785 0.013000 -0.012000
                rotation -0.000000 1.000000 -0.000000 4.188790
                children [
                  Pose {
                    translation 0.000000 0.000000 -0.024000
                    children [
                      Shape {
                        appearance USE black
                        geometry USE roller
                      }
                    ]
                  }
                ]
                name "roller-0-2"
                boundingObject Pose {
                  translation 0.000000 0.000000 -0.024000
                  children [
                    USE roller
                  ]
                }
                physics Physics {
                  density -1
                  mass 0.0020000
                  centerOfMass [ 0.000000 0.000000 0.000000 ]
                  inertiaMatrix [
                    2.700000e-06 2.700000e-06 1.000000e-06
                    0.000000e+00 0.000000e+00 0.000000e+00
                  ]
                  damping Damping {
                    linear  0.01
                    angular 0.01
                  }
                  restitution 0.0
                }
              }
            }
            HingeJoint {
              jointParameters HingeJointParameters {
                axis 0.500000 0.000000 -0.866025
                anchor 0.020785 -0.013000 0.012000
                dampingConstant 0
                staticFriction 0.01
              }
              device [
                RotationalMotor {
                  name "wheel60-roller3"
                  maxTorque 0
                  maxVelocity 100.0
                }
                PositionSensor {
                  name "wheel60-roller3_sensor"
                }
              ]
              endPoint Solid {
                translation 0.020785 -0.013000 0.012000
                rotation 0.000000 1.000000 0.000000 1.047198
                children [
                  Pose {
                    translation 0.000000 0.000000 -0.024000
                    children [
                      Shape {
                        appearance USE black
                        geometry USE roller
                      }
                    ]
                  }
                ]
                name "roller-0-3"
                boundingObject Pose {
                  translation 0.000000 0.000000 -0.024000
                  children [
                    USE roller
                  ]
                }
                physics Physics {
                  density -1
                  mass 0.0020000
                  centerOfMass [ 0.000000 0.000000 0.000000 ]
                  inertiaMatrix [
                    2.700000e-06 2.700000e-06 1.000000e-06
                    0.000000e+00 0.000000e+00 0.000000e+00
                  ]
                  damping Damping {
                    linear  0.01
                    angular 0.01
                  }
                  restitution 0.0
                }
              }
            }
            HingeJoint {
              jointParameters HingeJointParameters {
                axis -1.000000 0.000000 0.000000
                anchor 0.000000 -0.013000 -0.024000
                dampingConstant 0
                staticFriction 0.01
              }
              device [
                RotationalMotor {
                  name "wheel60-roller4"
                  maxTorque 0
                  maxVelocity 100.0
                }
                PositionSensor {
                  name "wheel60-roller4_sensor"
                }
              ]
              endPoint Solid {
                translation 0.000000 -0.013000 -0.024000
                rotation -0.000000 1.000000 -0.000000 3.141593
                children [
                  Pose {
                    translation 0.000000 0.000000 -0.024000
                    children [
                      Shape {
                        appearance USE black
                        geometry USE roller
                      }
                    ]
                  }
                ]
                name "roller-0-4"
                boundingObject Pose {
                  translation 0.000000 0.000000 -0.024000
                  children [
                    USE roller
                  ]
                }
                physics Physics {
                  density -1
                  mass 0.0020000
                  centerOfMass [ 0.000000 0.000000 0.000000 ]
                  inertiaMatrix [
                    2.700000e-06 2.700000e-06 1.000000e-06
                    0.000000e+00 0.000000e+00 0.000000e+00
                  ]
                  damping Damping {
                    linear  0.01
                    angular 0.01
                  }
                  restitution 0.0
                }
              }
            }
            HingeJoint {
              jointParameters HingeJointParameters {
                axis 0.500000 0.000000 0.866025
                anchor -0.020785 -0.013000 0.012000
                dampingConstant 0
                staticFriction 0.01
              }
              device [
                RotationalMotor {
                  name "wheel60-roller5"
                  maxTorque 0
                  maxVelocity 100.0
                }
                PositionSensor {
                  name "wheel60-roller5_sensor"
                }
              ]
              endPoint Solid {
                translation -0.020785 -0.013000 0.012000
                rotation -0.000000 1.000000 -0.000000 5.235988
                children [
                  Pose {
                    translation 0.000000 0.000000 -0.024000
                    children [
                      Shape {
                        appearance USE black
                        geometry USE roller
                      }
                    ]
                  }
                ]
                name "roller-0-5"
                boundingObject Pose {
                  translation 0.000000 0.000000 -0.024000
                  children [
                    USE roller
                  ]
                }
                physics Physics {
                  density -1
                  mass 0.0020000
                  centerOfMass [ 0.000000 0.000000 0.000000 ]
                  inertiaMatrix [
                    2.700000e-06 2.700000e-06 1.000000e-06
                    0.000000e+00 0.000000e+00 0.000000e+00
                  ]
                  damping Damping {
                    linear  0.01
                    angular 0.01
                  }
                  restitution 0.0
                }
              }
            }
          ]
          name "wheel-frame60"
          boundingObject USE wheel_frame
          physics Physics {
            density -1
            mass 0.100000
            centerOfMass [ 0.000000 0.000000 0.000000 ]
            inertiaMatrix [
              1.700000e-04 1.800000e-04 1.700000e-04
              0.000000e+00 0.000000e+00 0.000000e+00
            ]
          }
        }
      }
      HingeJoint {
        jointParameters HingeJointParameters {
          axis 0.866025 0.500000 0.000000
          anchor 0.086603 0.050000 0.000000
        }
        device [
          RotationalMotor {
            name "wheel-frame180"
            maxVelocity 20.0
            maxTorque 10.0
          }
          PositionSensor {
            name "wheel-frame180_sensor"
          }
        ]
        endPoint Solid {
          translation 0.086603 0.050000 0.000000
          rotation 0.000000 0.000000 1.000000 2.094395
          children [
            Shape {
              appearance USE grey
              geometry USE wheel_frame
            }
            HingeJoint {
              jointParameters HingeJointParameters {
                anchor 0.000000 0.013000 0.024000
                dampingConstant 0
                staticFriction 0.01
              }
              device [
                RotationalMotor {
                  name "wheel180-roller0"
                  maxTorque 0
                  maxVelocity 100.0
                }
                PositionSensor {
                  name "wheel180-roller0_sensor"
                }
              ]
              endPoint Solid {
                translation 0.000000 0.013000 0.024000
                children [
                  Pose {
                    translation 0.000000 0.000000 -0.024000
                    children [
                      Shape {
                        appearance USE black
                        geometry USE roller
                      }
                    ]
                  }
                ]
                name "roller-1-0"
                boundingObject Pose {
                  translation 0.000000 0.000000 -0.024000
                  children [
                    USE roller
                  ]
                }
                physics Physics {
                  density -1
                  mass 0.0020000
                  centerOfMass [ 0.000000 0.000000 0.000000 ]
                  inertiaMatrix [
                    2.700000e-06 2.700000e-06 1.000000e-06
                    0.000000e+00 0.000000e+00 0.000000e+00
                  ]
                  damping Damping {
                    linear  0.01
                    angular 0.01
                  }
                  restitution 0.0
                }
              }
            }
            HingeJoint {
              jointParameters HingeJointParameters {
                axis -0.500000 0.000000 -0.866025
                anchor 0.020785 0.013000 -0.012000
                dampingConstant 0
                staticFriction 0.01
              }
              device [
                RotationalMotor {
                  name "wheel180-roller1"
                  maxTorque 0
                  maxVelocity 100.0
                }
                PositionSensor {
                  name "wheel180-roller1_sensor"
                }
              ]
              endPoint Solid {
                translation 0.020785 0.013000 -0.012000
                rotation 0.000000 1.000000 0.000000 2.094395
                children [
                  Pose {
                    translation 0.000000 0.000000 -0.024000
                    children [
                      Shape {
                        appearance USE black
                        geometry USE roller
                      }
                    ]
                  }
                ]
                name "roller-1-1"
                boundingObject Pose {
                  translation 0.000000 0.000000 -0.024000
                  children [
                    USE roller
                  ]
                }
                physics Physics {
                  density -1
                  mass 0.0020000
                  centerOfMass [ 0.000000 0.000000 0.000000 ]
                  inertiaMatrix [
                    2.700000e-06 2.700000e-06 1.000000e-06
                    0.000000e+00 0.000000e+00 0.000000e+00
                  ]
                  damping Damping {
                    linear  0.01
                    angular 0.01
                  }
                  restitution 0.0
                }
              }
            }
            HingeJoint {
              jointParameters HingeJointParameters {
                axis -0.500000 0.000000 0.866025
                anchor -0.020785 0.013000 -0.012000
                dampingConstant 0
                staticFriction 0.01
              }
              device [
                RotationalMotor {
                  name "wheel180-roller2"
                  maxTorque 0
                  maxVelocity 100.0
                }
                PositionSensor {
                  name "wheel180-roller2_sensor"
                }
              ]
              endPoint Solid {
                translation -0.020785 0.013000 -0.012000
                rotation -0.000000 1.000000 -0.000000 4.188790
                children [
                  Pose {
                    translation 0.000000 0.000000 -0.024000
                    children [
                      Shape {
                        appearance USE black
                        geometry USE roller
                      }
                    ]
                  }
                ]
                name "roller-1-2"
                boundingObject Pose {
                  translation 0.000000 0.000000 -0.024000
                  children [
                    USE roller
                  ]
                }
                physics Physics {
                  density -1
                  mass 0.0020000
                  centerOfMass [ 0.000000 0.000000 0.000000 ]
                  inertiaMatrix [
                    2.700000e-06 2.700000e-06 1.000000e-06
                    0.000000e+00 0.000000e+00 0.000000e+00
                  ]
                  damping Damping {
                    linear  0.01
                    angular 0.01
                  }
                  restitution 0.0
                }
              }
            }
            HingeJoint {
              jointParameters HingeJointParameters {
                axis 0.500000 0.000000 -0.866025
                anchor 0.020785 -0.013000 0.012000
                dampingConstant 0
                staticFriction 0.01
              }
              device [
                RotationalMotor {
                  name "wheel180-roller3"
                  maxTorque 0
                  maxVelocity 100.0
                }
                PositionSensor {
                  name "wheel180-roller3_sensor"
                }
              ]
              endPoint Solid {
                translation 0.020785 -0.013000 0.012000
                rotation 0.000000 1.000000 0.000000 1.047198
                children [
                  Pose {
                    translation 0.000000 0.000000 -0.024000
                    children [
                      Shape {
                        appearance USE black
                        geometry USE roller
                      }
                    ]
                  }
                ]
                name "roller-1-3"
                boundingObject Pose {
                  translation 0.000000 0.000000 -0.024000
                  children [
                    USE roller
                  ]
                }
                physics Physics {
                  density -1
                  mass 0.0020000
                  centerOfMass [ 0.000000 0.000000 0.000000 ]
                  inertiaMatrix [
                    2.700000e-06 2.700000e-06 1.000000e-06
                    0.000000e+00 0.000000e+00 0.000000e+00
                  ]
                  damping Damping {
                    linear  0.01
                    angular 0.01
                  }
                  restitution 0.0
                }
              }
            }
            HingeJoint {
              jointParameters HingeJointParameters {
                axis -1.000000 0.000000 0.000000
                anchor 0.000000 -0.013000 -0.024000
                dampingConstant 0
                staticFriction 0.01
              }
              device [
                RotationalMotor {
                  name "wheel180-roller4"
                  maxTorque 0
                  maxVelocity 100.0
                }
                PositionSensor {
                  name "wheel180-roller4_sensor"
                }
              ]
              endPoint Solid {
                translation 0.000000 -0.013000 -0.024000
                rotation -0.000000 1.000000 -0.000000 3.141593
                children [
                  Pose {
                    translation 0.000000 0.000000 -0.024000
                    children [
                      Shape {
                        appearance USE black
                        geometry USE roller
                      }
                    ]
                  }
                ]
                name "roller-1-4"
                boundingObject Pose {
                  translation 0.000000 0.000000 -0.024000
                  children [
                    USE roller
                  ]
                }
                physics Physics {
                  density -1
                  mass 0.0020000
                  centerOfMass [ 0.000000 0.000000 0.000000 ]
                  inertiaMatrix [
                    2.700000e-06 2.700000e-06 1.000000e-06
                    0.000000e+00 0.000000e+00 0.000000e+00
                  ]
                  damping Damping {
                    linear  0.01
                    angular 0.01
                  }
                  restitution 0.0
                }
              }
            }
            HingeJoint {
              jointParameters HingeJointParameters {
                axis 0.500000 0.000000 0.866025
                anchor -0.020785 -0.013000 0.012000
                dampingConstant 0
                staticFriction 0.01
              }
              device [
                RotationalMotor {
                  name "wheel180-roller5"
                  maxTorque 0
                  maxVelocity 100.0
                }
                PositionSensor {
                  name "wheel180-roller5_sensor"
                }
              ]
              endPoint Solid {
                translation -0.020785 -0.013000 0.012000
                rotation -0.000000 1.000000 -0.000000 5.235988
                children [
                  Pose {
                    translation 0.000000 0.000000 -0.024000
                    children [
                      Shape {
                        appearance USE black
                        geometry USE roller
                      }
                    ]
                  }
                ]
                name "roller-1-5"
                boundingObject Pose {
                  translation 0.000000 0.000000 -0.024000
                  children [
                    USE roller
                  ]
                }
                physics Physics {
                  density -1
                  mass 0.0020000
                  centerOfMass [ 0.000000 0.000000 0.000000 ]
                  inertiaMatrix [
                    2.700000e-06 2.700000e-06 1.000000e-06
                    0.000000e+00 0.000000e+00 0.000000e+00
                  ]
                  damping Damping {
                    linear  0.01
                    angular 0.01
                  }
                  restitution 0.0
                }
              }
            }
          ]
          name "wheel-frame180"
          boundingObject USE wheel_frame
          physics Physics {
            density -1
            mass 0.100000
            centerOfMass [ 0.000000 0.000000 0.000000 ]
            inertiaMatrix [
              1.700000e-04 1.800000e-04 1.700000e-04
              0.000000e+00 0.000000e+00 0.000000e+00
            ]
          }
        }
      }
      HingeJoint {
        jointParameters HingeJointParameters {
          axis -0.866025 0.500000 0.000000
          anchor -0.086603 0.050000 0.000000
        }
        device [
          RotationalMotor {
            name "wheel-frame300"
            maxVelocity 20.0
            maxTorque 10.0
          }
          PositionSensor {
            name "wheel-frame300_sensor"
          }
        ]
        endPoint Solid {
          translation -0.086603 0.050000 0.000000
          rotation -0.000000 0.000000 1.000000 4.188790
          children [
            Shape {
              appearance USE grey
              geometry USE wheel_frame
            }
            HingeJoint {
              jointParameters HingeJointParameters {
                anchor 0.000000 0.013000 0.024000
                dampingConstant 0
                staticFriction 0.01
              }
              device [
                RotationalMotor {
                  name "wheel300-roller0"
                  maxTorque 0
                  maxVelocity 100.0
                }
                PositionSensor {
                  name "wheel300-roller0_sensor"
                }
              ]
              endPoint Solid {
                translation 0.000000 0.013000 0.024000
                children [
                  Pose {
                    translation 0.000000 0.000000 -0.024000
                    children [
                      Shape {
                        appearance USE black
                        geometry USE roller
                      }
                    ]
                  }
                ]
                name "roller-2-0"
                boundingObject Pose {
                  translation 0.000000 0.000000 -0.024000
                  children [
                    USE roller
                  ]
                }
                physics Physics {
                  density -1
                  mass 0.0020000
                  centerOfMass [ 0.000000 0.000000 0.000000 ]
                  inertiaMatrix [
                    2.700000e-06 2.700000e-06 1.000000e-06
                    0.000000e+00 0.000000e+00 0.000000e+00
                  ]
                  damping Damping {
                    linear  0.01
                    angular 0.01
                  }
                  restitution 0.0
                }
              }
            }
            HingeJoint {
              jointParameters HingeJointParameters {
                axis -0.500000 0.000000 -0.866025
                anchor 0.020785 0.013000 -0.012000
                dampingConstant 0
                staticFriction 0.01
              }
              device [
                RotationalMotor {
                  name "wheel300-roller1"
                  maxTorque 0
                  maxVelocity 100.0
                }
                PositionSensor {
                  name "wheel300-roller1_sensor"
                }
              ]
              endPoint Solid {
                translation 0.020785 0.013000 -0.012000
                rotation 0.000000 1.000000 0.000000 2.094395
                children [
                  Pose {
                    translation 0.000000 0.000000 -0.024000
                    children [
                      Shape {
                        appearance USE black
                        geometry USE roller
                      }
                    ]
                  }
                ]
                name "roller-2-1"
                boundingObject Pose {
                  translation 0.000000 0.000000 -0.024000
                  children [
                    USE roller
                  ]
                }
                physics Physics {
                  density -1
                  mass 0.0020000
                  centerOfMass [ 0.000000 0.000000 0.000000 ]
                  inertiaMatrix [
                    2.700000e-06 2.700000e-06 1.000000e-06
                    0.000000e+00 0.000000e+00 0.000000e+00
                  ]
                  damping Damping {
                    linear  0.01
                    angular 0.01
                  }
                  restitution 0.0
                }
              }
            }
            HingeJoint {
              jointParameters HingeJointParameters {
                axis -0.500000 0.000000 0.866025
                anchor -0.020785 0.013000 -0.012000
                dampingConstant 0
                staticFriction 0.01
              }
              device [
                RotationalMotor {
                  name "wheel300-roller2"
                  maxTorque 0
                  maxVelocity 100.0
                }
                PositionSensor {
                  name "wheel300-roller2_sensor"
                }
              ]
              endPoint Solid {
                translation -0.020785 0.013000 -0.012000
                rotation -0.000000 1.000000 -0.000000 4.188790
                children [
                  Pose {
                    translation 0.000000 0.000000 -0.024000
                    children [
                      Shape {
                        appearance USE black
                        geometry USE roller
                      }
                    ]
                  }
                ]
                name "roller-2-2"
                boundingObject Pose {
                  translation 0.000000 0.000000 -0.024000
                  children [
                    USE roller
                  ]
                }
                physics Physics {
                  density -1
                  mass 0.0020000
                  centerOfMass [ 0.000000 0.000000 0.000000 ]
                  inertiaMatrix [
                    2.700000e-06 2.700000e-06 1.000000e-06
                    0.000000e+00 0.000000e+00 0.000000e+00
                  ]
                  damping Damping {
                    linear  0.01
                    angular 0.01
                  }
                  restitution 0.0
                }
              }
            }
            HingeJoint {
              jointParameters HingeJointParameters {
                axis 0.500000 0.000000 -0.866025
                anchor 0.020785 -0.013000 0.012000
                dampingConstant 0
                staticFriction 0.01
              }
              device [
                RotationalMotor {
                  name "wheel300-roller3"
                  maxTorque 0
                  maxVelocity 100.0
                }
                PositionSensor {
                  name "wheel300-roller3_sensor"
                }
              ]
              endPoint Solid {
                translation 0.020785 -0.013000 0.012000
                rotation 0.000000 1.000000 0.000000 1.047198
                children [
                  Pose {
                    translation 0.000000 0.000000 -0.024000
                    children [
                      Shape {
                        appearance USE black
                        geometry USE roller
                      }
                    ]
                  }
                ]
                name "roller-2-3"
                boundingObject Pose {
                  translation 0.000000 0.000000 -0.024000
                  children [
                    USE roller
                  ]
                }
                physics Physics {
                  density -1
                  mass 0.0020000
                  centerOfMass [ 0.000000 0.000000 0.000000 ]
                  inertiaMatrix [
                    2.700000e-06 2.700000e-06 1.000000e-06
                    0.000000e+00 0.000000e+00 0.000000e+00
                  ]
                  damping Damping {
                    linear  0.01
                    angular 0.01
                  }
                  restitution 0.0
                }
              }
            }
            HingeJoint {
              jointParameters HingeJointParameters {
                axis -1.000000 0.000000 0.000000
                anchor 0.000000 -0.013000 -0.024000
                dampingConstant 0
                staticFriction 0.01
              }
              device [
                RotationalMotor {
                  name "wheel300-roller4"
                  maxTorque 0
                  maxVelocity 100.0
                }
                PositionSensor {
                  name "wheel300-roller4_sensor"
                }
              ]
              endPoint Solid {
                translation 0.000000 -0.013000 -0.024000
                rotation -0.000000 1.000000 -0.000000 3.141593
                children [
                  Pose {
                    translation 0.000000 0.000000 -0.024000
                    children [
                      Shape {
                        appearance USE black
                        geometry USE roller
                      }
                    ]
                  }
                ]
                name "roller-2-4"
                boundingObject Pose {
                  translation 0.000000 0.000000 -0.024000
                  children [
                    USE roller
                  ]
                }
                physics Physics {
                  density -1
                  mass 0.0020000
                  centerOfMass [ 0.000000 0.000000 0.000000 ]
                  inertiaMatrix [
                    2.700000e-06 2.700000e-06 1.000000e-06
                    0.000000e+00 0.000000e+00 0.000000e+00
                  ]
                  damping Damping {
                    linear  0.01
                    angular 0.01
                  }
                  restitution 0.0
                }
              }
            }
            HingeJoint {
              jointParameters HingeJointParameters {
                axis 0.500000 0.000000 0.866025
                anchor -0.020785 -0.013000 0.012000
                dampingConstant 0
                staticFriction 0.01
              }
              device [
                RotationalMotor {
                  name "wheel300-roller5"
                  maxTorque 0
                  maxVelocity 100.0
                }
                PositionSensor {
                  name "wheel300-roller5_sensor"
                }
              ]
              endPoint Solid {
                translation -0.020785 -0.013000 0.012000
                rotation -0.000000 1.000000 -0.000000 5.235988
                children [
                  Pose {
                    translation 0.000000 0.000000 -0.024000
                    children [
                      Shape {
                        appearance USE black
                        geometry USE roller
                      }
                    ]
                  }
                ]
                name "roller-2-5"
                boundingObject Pose {
                  translation 0.000000 0.000000 -0.024000
                  children [
                    USE roller
                  ]
                }
                physics Physics {
                  density -1
                  mass 0.0020000
                  centerOfMass [ 0.000000 0.000000 0.000000 ]
                  inertiaMatrix [
                    2.700000e-06 2.700000e-06 1.000000e-06
                    0.000000e+00 0.000000e+00 0.000000e+00
                  ]
                  damping Damping {
                    linear  0.01
                    angular 0.01
                  }
                  restitution 0.0
                }
              }
            }
          ]
          name "wheel-frame300"
          boundingObject USE wheel_frame
          physics Physics {
            density -1
            mass 0.100000
            centerOfMass [ 0.000000 0.000000 0.000000 ]
            inertiaMatrix [
              1.700000e-04 1.800000e-04 1.700000e-04
              0.000000e+00 0.000000e+00 0.000000e+00
            ]
          }
        }
      }
    ]
    name IS name
    boundingObject USE base_link
    physics Physics {
      density -1
      mass 0.7
      centerOfMass [ 0.000000 0.000000 0.000000 ]
      inertiaMatrix [
        0.065 0.065 0.065
        0.000000e+00 0.000000e+00 0.000000e+00
      ]
    }
  }
}
