<?xml version="1.0" ?>
<robot name="urdf">

<material name="silver">
  <color rgba="0.700 0.700 0.700 1.000"/>
</material>

<link name="base_link">
  <inertial>
    <origin xyz="0 0 3.8" rpy="0 0 0"/>
    <mass value="4.8"/>
    <inertia ixx="-71.670522" iyy="-71.670522" izz="0.0224" ixy="-0.0" iyz="-0.0" ixz="-0.0"/>
  </inertial>
  <visual>
    <origin xyz="0 0 0" rpy="0 0 0"/>
    <geometry>
      <mesh filename="package://omni_1_description/meshes/base_link.stl" scale="0.001 0.001 0.001"/>
    </geometry>
    <material name="silver"/>
  </visual>
  <collision>
    <origin xyz="0 0 0" rpy="0 0 0"/>
    <geometry>
      <mesh filename="package://omni_1_description/meshes/base_link.stl" scale="0.001 0.001 0.001"/>
    </geometry>
  </collision>
</link>

<link name="wheel-frame0">
  <inertial>
    <origin xyz="0 0 0" rpy="0 0 0"/>
    <mass value="0.5"/>
    <inertia ixx="1.7e-4" iyy="1.8e-4" izz="1.7e-4" ixy="0.0" iyz="0.0" ixz="0.0"/>
  </inertial>
  <visual>
    <origin xyz="0.0 0.0 0.0" rpy="0 0 0"/>
    <geometry>
      <mesh filename="package://omni_1_description/meshes/wheel-frame0.stl" scale="0.001 0.001 0.001"/>
    </geometry>
    <material name="silver"/>
  </visual>
  <collision>
    <origin xyz="0.0 0.0 0.0" rpy="0 0 0"/>
    <geometry>
      <mesh filename="package://omni_1_description/meshes/wheel-frame0.stl" scale="0.001 0.001 0.001"/>
    </geometry>
  </collision>
</link>

<link name="wheel-frame120">
  <inertial>
    <origin xyz="0 0 0" rpy="0 0 0"/>
    <mass value="0.5"/>
    <inertia ixx="1.7e-4" iyy="1.8e-4" izz="1.7e-4" ixy="0.0" iyz="0.0" ixz="0.0"/>
  </inertial>
  <visual>
    <origin xyz="0.0 0.0 0.0" rpy="0 0 0"/>
    <geometry>
      <mesh filename="package://omni_1_description/meshes/wheel-frame120.stl" scale="0.001 0.001 0.001"/>
    </geometry>
    <material name="silver"/>
  </visual>
  <collision>
    <origin xyz="0.0 0.0 0.0" rpy="0 0 0"/>
    <geometry>
      <mesh filename="package://omni_1_description/meshes/wheel-frame120.stl" scale="0.001 0.001 0.001"/>
    </geometry>
  </collision>
</link>

<link name="wheel-frame240">
  <inertial>
    <origin xyz="0 0 0" rpy="0 0 0"/>
    <mass value="0.5"/>
    <inertia ixx="1.7e-4" iyy="1.8e-4" izz="1.7e-4" ixy="0.0" iyz="0.0" ixz="0.0"/>
  </inertial>
  <visual>
    <origin xyz="0.0 0.0 0.0" rpy="0 0 0"/>
    <geometry>
      <mesh filename="package://omni_1_description/meshes/wheel-frame240.stl" scale="0.001 0.001 0.001"/>
    </geometry>
    <material name="silver"/>
  </visual>
  <collision>
    <origin xyz="0.0 0.0 0.0" rpy="0 0 0"/>
    <geometry>
      <mesh filename="package://omni_1_description/meshes/wheel-frame240.stl" scale="0.001 0.001 0.001"/>
    </geometry>
  </collision>
</link>

<joint name="wheel-frame0" type="revolute">
  <origin xyz="0.0 -0.1 0.0" rpy="0 0 0"/>
  <parent link="base_link"/>
  <child link="wheel-frame0"/>
  <axis xyz="0.0 -1.0 0.0"/>
  <limit upper="3.14159" lower="-3.14159" effort="100" velocity="100"/>
</joint>
 
<joint name="wheel-frame120" type="revolute">
  <origin xyz="0.08660254038 0.05 0.0" rpy="0 0 2.094395102"/>
  <parent link="base_link"/>
  <child link="wheel-frame120"/>
  <axis xyz="0.0 -1.0 0.0"/>
  <limit upper="3.14159" lower="-3.14159" effort="100" velocity="100"/>
</joint>

<joint name="wheel-frame240" type="revolute">
  <origin xyz="-0.08660254038 0.05 0.0" rpy="0 0 4.188790205"/>
  <parent link="base_link"/>
  <child link="wheel-frame240"/>
  <axis xyz="0.0 -1.0 0.0"/>
  <limit upper="3.14159" lower="-3.14159" effort="100" velocity="100"/>
</joint>

</robot>
