<?xml version="1.0" ?>
<robot name="omni-1">

  <material name="silver">
    <color rgba="0.8 0.8 0.8 1.0"/>
  </material>

  <material name="grey">
    <color rgba="0.4 0.4 0.4 1.0"/>
  </material>

  <material name="black">
    <color rgba="0.1 0.1 0.1 1.0"/>
  </material>

  <link name="base_link">
    <inertial>
      <origin xyz="0 0 3.8" rpy="0 0 0"/>
      <mass value="4.8"/>
      <inertia ixx="71.670522" iyy="71.670522" izz="0.0224" ixy="-0.0" iyz="-0.0" ixz="-0.0"/>
    </inertial>
    <visual>
      <origin xyz="0 0 0" rpy="0 0 0"/>
      <geometry>
        <mesh filename="package://omni_1_description/meshes/base_link.stl" scale="1 1 1"/>
      </geometry>
      <material name="silver"/>
    </visual>
    <collision>
      <origin xyz="0 0 0" rpy="0 0 0"/>
      <geometry>
        <mesh filename="package://omni_1_description/meshes/base_link.stl" scale="1 1 1"/>
      </geometry>
    </collision>
  </link>

  <link name="wheel-frame0">
    <inertial>
      <origin xyz="0 0 0" rpy="0 0 0"/>
      <mass value="0.5"/>
      <inertia ixx="1.7e-4" iyy="1.8e-4" izz="1.7e-4" ixy="0.0" iyz="0.0" ixz="0.0"/>
    </inertial>
    <visual>
      <origin xyz="0.0 0.0 0.0" rpy="0 0 0"/>
      <geometry>
        <mesh filename="package://omni_1_description/meshes/wheel_frame.stl" scale="1 1 1"/>
      </geometry>
      <material name="grey"/>
    </visual>
    <collision>
      <origin xyz="0.0 0.0 0.0" rpy="0 0 0"/>
      <geometry>
        <mesh filename="package://omni_1_description/meshes/wheel_frame.stl" scale="1 1 1"/>
      </geometry>
    </collision>
  </link>

  <link name="wheel-frame120">
    <inertial>
      <origin xyz="0 0 0" rpy="0 0 0"/>
      <mass value="0.5"/>
      <inertia ixx="1.7e-4" iyy="1.8e-4" izz="1.7e-4" ixy="0.0" iyz="0.0" ixz="0.0"/>
    </inertial>
    <visual>
      <origin xyz="0.0 0.0 0.0" rpy="0 0 0"/>
      <geometry>
        <mesh filename="package://omni_1_description/meshes/wheel_frame.stl" scale="1 1 1"/>
      </geometry>
      <material name="grey"/>
    </visual>
    <collision>
      <origin xyz="0.0 0.0 0.0" rpy="0 0 0"/>
      <geometry>
        <mesh filename="package://omni_1_description/meshes/wheel_frame.stl" scale="1 1 1"/>
      </geometry>
    </collision>
  </link>

  <link name="wheel-frame240">
    <inertial>
      <origin xyz="0 0 0" rpy="0 0 0"/>
      <mass value="0.5"/>
      <inertia ixx="1.7e-4" iyy="1.8e-4" izz="1.7e-4" ixy="0.0" iyz="0.0" ixz="0.0"/>
    </inertial>
    <visual>
      <origin xyz="0.0 0.0 0.0" rpy="0 0 0"/>
      <geometry>
        <mesh filename="package://omni_1_description/meshes/wheel_frame.stl" scale="1 1 1"/>
      </geometry>
      <material name="grey"/>
    </visual>
    <collision>
      <origin xyz="0.0 0.0 0.0" rpy="0 0 0"/>
      <geometry>
        <mesh filename="package://omni_1_description/meshes/wheel_frame.stl" scale="1 1 1"/>
      </geometry>
    </collision>
  </link>

  <link name="roller-0-0">
    <inertial>
      <origin xyz="0 0 0" rpy="0 0 0"/>
      <mass value="0.02"/>
      <inertia ixx="2.7e-6" iyy="2.7e-6" izz="1.0e-6" ixy="0.0" iyz="0.0" ixz="0.0"/>
    </inertial>
    <visual>
      <origin xyz="0.0 0.0 -0.024" rpy="0 0 0"/>
      <geometry>
        <mesh filename="package://omni_1_description/meshes/roller.stl" scale="1 1 1"/>
      </geometry>
      <material name="black"/>
    </visual>
    <collision>
      <origin xyz="0.0 0.0 -0.024" rpy="0 0 0"/>
      <geometry>
        <mesh filename="package://omni_1_description/meshes/roller.stl" scale="1 1 1"/>
      </geometry>
    </collision>
  </link>

  <link name="roller-0-1">
    <inertial>
      <origin xyz="0 0 0" rpy="0 0 0"/>
      <mass value="0.02"/>
      <inertia ixx="2.7e-6" iyy="2.7e-6" izz="1.0e-6" ixy="0.0" iyz="0.0" ixz="0.0"/>
    </inertial>
    <visual>
      <origin xyz="0.0 0.0 -0.024" rpy="0 0 0"/>
      <geometry>
        <mesh filename="package://omni_1_description/meshes/roller.stl" scale="1 1 1"/>
      </geometry>
      <material name="black"/>
    </visual>
    <collision>
      <origin xyz="0.0 0.0 -0.024" rpy="0 0 0"/>
      <geometry>
        <mesh filename="package://omni_1_description/meshes/roller.stl" scale="1 1 1"/>
      </geometry>
    </collision>
  </link>

  <link name="roller-0-2">
    <inertial>
      <origin xyz="0 0 0" rpy="0 0 0"/>
      <mass value="0.02"/>
      <inertia ixx="2.7e-6" iyy="2.7e-6" izz="1.0e-6" ixy="0.0" iyz="0.0" ixz="0.0"/>
    </inertial>
    <visual>
      <origin xyz="0.0 0.0 -0.024" rpy="0 0 0"/>
      <geometry>
        <mesh filename="package://omni_1_description/meshes/roller.stl" scale="1 1 1"/>
      </geometry>
      <material name="black"/>
    </visual>
    <collision>
      <origin xyz="0.0 0.0 -0.024" rpy="0 0 0"/>
      <geometry>
        <mesh filename="package://omni_1_description/meshes/roller.stl" scale="1 1 1"/>
      </geometry>
    </collision>
  </link>

  <link name="roller-0-3">
    <inertial>
      <origin xyz="0 0 0" rpy="0 0 0"/>
      <mass value="0.02"/>
      <inertia ixx="2.7e-6" iyy="2.7e-6" izz="1.0e-6" ixy="0.0" iyz="0.0" ixz="0.0"/>
    </inertial>
    <visual>
      <origin xyz="0.0 0.0 -0.024" rpy="0 0 0"/>
      <geometry>
        <mesh filename="package://omni_1_description/meshes/roller.stl" scale="1 1 1"/>
      </geometry>
      <material name="black"/>
    </visual>
    <collision>
      <origin xyz="0.0 0.0 -0.024" rpy="0 0 0"/>
      <geometry>
        <mesh filename="package://omni_1_description/meshes/roller.stl" scale="1 1 1"/>
      </geometry>
    </collision>
  </link>

  <link name="roller-0-4">
    <inertial>
      <origin xyz="0 0 0" rpy="0 0 0"/>
      <mass value="0.02"/>
      <inertia ixx="2.7e-6" iyy="2.7e-6" izz="1.0e-6" ixy="0.0" iyz="0.0" ixz="0.0"/>
    </inertial>
    <visual>
      <origin xyz="0.0 0.0 -0.024" rpy="0 0 0"/>
      <geometry>
        <mesh filename="package://omni_1_description/meshes/roller.stl" scale="1 1 1"/>
      </geometry>
      <material name="black"/>
    </visual>
    <collision>
      <origin xyz="0.0 0.0 -0.024" rpy="0 0 0"/>
      <geometry>
        <mesh filename="package://omni_1_description/meshes/roller.stl" scale="1 1 1"/>
      </geometry>
    </collision>
  </link>

  <link name="roller-0-5">
    <inertial>
      <origin xyz="0 0 0" rpy="0 0 0"/>
      <mass value="0.02"/>
      <inertia ixx="2.7e-6" iyy="2.7e-6" izz="1.0e-6" ixy="0.0" iyz="0.0" ixz="0.0"/>
    </inertial>
    <visual>
      <origin xyz="0.0 0.0 -0.024" rpy="0 0 0"/>
      <geometry>
        <mesh filename="package://omni_1_description/meshes/roller.stl" scale="1 1 1"/>
      </geometry>
      <material name="black"/>
    </visual>
    <collision>
      <origin xyz="0.0 0.0 -0.024" rpy="0 0 0"/>
      <geometry>
        <mesh filename="package://omni_1_description/meshes/roller.stl" scale="1 1 1"/>
      </geometry>
    </collision>
  </link>

  <link name="roller-2-0">
    <inertial>
      <origin xyz="0 0 0" rpy="0 0 0"/>
      <mass value="0.02"/>
      <inertia ixx="2.7e-6" iyy="2.7e-6" izz="1.0e-6" ixy="0.0" iyz="0.0" ixz="0.0"/>
    </inertial>
    <visual>
      <origin xyz="0.0 0.0 -0.024" rpy="0 0 0"/>
      <geometry>
        <mesh filename="package://omni_1_description/meshes/roller.stl" scale="1 1 1"/>
      </geometry>
      <material name="black"/>
    </visual>
    <collision>
      <origin xyz="0.0 0.0 -0.024" rpy="0 0 0"/>
      <geometry>
        <mesh filename="package://omni_1_description/meshes/roller.stl" scale="1 1 1"/>
      </geometry>
    </collision>
  </link>

  <link name="roller-2-1">
    <inertial>
      <origin xyz="0 0 0" rpy="0 0 0"/>
      <mass value="0.02"/>
      <inertia ixx="2.7e-6" iyy="2.7e-6" izz="1.0e-6" ixy="0.0" iyz="0.0" ixz="0.0"/>
    </inertial>
    <visual>
      <origin xyz="0.0 0.0 -0.024" rpy="0 0 0"/>
      <geometry>
        <mesh filename="package://omni_1_description/meshes/roller.stl" scale="1 1 1"/>
      </geometry>
      <material name="black"/>
    </visual>
    <collision>
      <origin xyz="0.0 0.0 -0.024" rpy="0 0 0"/>
      <geometry>
        <mesh filename="package://omni_1_description/meshes/roller.stl" scale="1 1 1"/>
      </geometry>
    </collision>
  </link>

  <link name="roller-2-2">
    <inertial>
      <origin xyz="0 0 0" rpy="0 0 0"/>
      <mass value="0.02"/>
      <inertia ixx="2.7e-6" iyy="2.7e-6" izz="1.0e-6" ixy="0.0" iyz="0.0" ixz="0.0"/>
    </inertial>
    <visual>
      <origin xyz="0.0 0.0 -0.024" rpy="0 0 0"/>
      <geometry>
        <mesh filename="package://omni_1_description/meshes/roller.stl" scale="1 1 1"/>
      </geometry>
      <material name="black"/>
    </visual>
    <collision>
      <origin xyz="0.0 0.0 -0.024" rpy="0 0 0"/>
      <geometry>
        <mesh filename="package://omni_1_description/meshes/roller.stl" scale="1 1 1"/>
      </geometry>
    </collision>
  </link>

  <link name="roller-2-3">
    <inertial>
      <origin xyz="0 0 0" rpy="0 0 0"/>
      <mass value="0.02"/>
      <inertia ixx="2.7e-6" iyy="2.7e-6" izz="1.0e-6" ixy="0.0" iyz="0.0" ixz="0.0"/>
    </inertial>
    <visual>
      <origin xyz="0.0 0.0 -0.024" rpy="0 0 0"/>
      <geometry>
        <mesh filename="package://omni_1_description/meshes/roller.stl" scale="1 1 1"/>
      </geometry>
      <material name="black"/>
    </visual>
    <collision>
      <origin xyz="0.0 0.0 -0.024" rpy="0 0 0"/>
      <geometry>
        <mesh filename="package://omni_1_description/meshes/roller.stl" scale="1 1 1"/>
      </geometry>
    </collision>
  </link>

  <link name="roller-2-4">
    <inertial>
      <origin xyz="0 0 0" rpy="0 0 0"/>
      <mass value="0.02"/>
      <inertia ixx="2.7e-6" iyy="2.7e-6" izz="1.0e-6" ixy="0.0" iyz="0.0" ixz="0.0"/>
    </inertial>
    <visual>
      <origin xyz="0.0 0.0 -0.024" rpy="0 0 0"/>
      <geometry>
        <mesh filename="package://omni_1_description/meshes/roller.stl" scale="1 1 1"/>
      </geometry>
      <material name="black"/>
    </visual>
    <collision>
      <origin xyz="0.0 0.0 -0.024" rpy="0 0 0"/>
      <geometry>
        <mesh filename="package://omni_1_description/meshes/roller.stl" scale="1 1 1"/>
      </geometry>
    </collision>
  </link>

  <link name="roller-2-5">
    <inertial>
      <origin xyz="0 0 0" rpy="0 0 0"/>
      <mass value="0.02"/>
      <inertia ixx="2.7e-6" iyy="2.7e-6" izz="1.0e-6" ixy="0.0" iyz="0.0" ixz="0.0"/>
    </inertial>
    <visual>
      <origin xyz="0.0 0.0 -0.024" rpy="0 0 0"/>
      <geometry>
        <mesh filename="package://omni_1_description/meshes/roller.stl" scale="1 1 1"/>
      </geometry>
      <material name="black"/>
    </visual>
    <collision>
      <origin xyz="0.0 0.0 -0.024" rpy="0 0 0"/>
      <geometry>
        <mesh filename="package://omni_1_description/meshes/roller.stl" scale="1 1 1"/>
      </geometry>
    </collision>
  </link>

  <link name="roller-1-0">
    <inertial>
      <origin xyz="0 0 0" rpy="0 0 0"/>
      <mass value="0.02"/>
      <inertia ixx="2.7e-6" iyy="2.7e-6" izz="1.0e-6" ixy="0.0" iyz="0.0" ixz="0.0"/>
    </inertial>
    <visual>
      <origin xyz="0.0 0.0 -0.024" rpy="0 0 0"/>
      <geometry>
        <mesh filename="package://omni_1_description/meshes/roller.stl" scale="1 1 1"/>
      </geometry>
      <material name="black"/>
    </visual>
    <collision>
      <origin xyz="0.0 0.0 -0.024" rpy="0 0 0"/>
      <geometry>
        <mesh filename="package://omni_1_description/meshes/roller.stl" scale="1 1 1"/>
      </geometry>
    </collision>
  </link>

  <link name="roller-1-1">
    <inertial>
      <origin xyz="0 0 0" rpy="0 0 0"/>
      <mass value="0.02"/>
      <inertia ixx="2.7e-6" iyy="2.7e-6" izz="1.0e-6" ixy="0.0" iyz="0.0" ixz="0.0"/>
    </inertial>
    <visual>
      <origin xyz="0.0 0.0 -0.024" rpy="0 0 0"/>
      <geometry>
        <mesh filename="package://omni_1_description/meshes/roller.stl" scale="1 1 1"/>
      </geometry>
      <material name="black"/>
    </visual>
    <collision>
      <origin xyz="0.0 0.0 -0.024" rpy="0 0 0"/>
      <geometry>
        <mesh filename="package://omni_1_description/meshes/roller.stl" scale="1 1 1"/>
      </geometry>
    </collision>
  </link>

  <link name="roller-1-2">
    <inertial>
      <origin xyz="0 0 0" rpy="0 0 0"/>
      <mass value="0.02"/>
      <inertia ixx="2.7e-6" iyy="2.7e-6" izz="1.0e-6" ixy="0.0" iyz="0.0" ixz="0.0"/>
    </inertial>
    <visual>
      <origin xyz="0.0 0.0 -0.024" rpy="0 0 0"/>
      <geometry>
        <mesh filename="package://omni_1_description/meshes/roller.stl" scale="1 1 1"/>
      </geometry>
      <material name="black"/>
    </visual>
    <collision>
      <origin xyz="0.0 0.0 -0.024" rpy="0 0 0"/>
      <geometry>
        <mesh filename="package://omni_1_description/meshes/roller.stl" scale="1 1 1"/>
      </geometry>
    </collision>
  </link>

  <link name="roller-1-3">
    <inertial>
      <origin xyz="0 0 0" rpy="0 0 0"/>
      <mass value="0.02"/>
      <inertia ixx="2.7e-6" iyy="2.7e-6" izz="1.0e-6" ixy="0.0" iyz="0.0" ixz="0.0"/>
    </inertial>
    <visual>
      <origin xyz="0.0 0.0 -0.024" rpy="0 0 0"/>
      <geometry>
        <mesh filename="package://omni_1_description/meshes/roller.stl" scale="1 1 1"/>
      </geometry>
      <material name="black"/>
    </visual>
    <collision>
      <origin xyz="0.0 0.0 -0.024" rpy="0 0 0"/>
      <geometry>
        <mesh filename="package://omni_1_description/meshes/roller.stl" scale="1 1 1"/>
      </geometry>
    </collision>
  </link>

  <link name="roller-1-4">
    <inertial>
      <origin xyz="0 0 0" rpy="0 0 0"/>
      <mass value="0.02"/>
      <inertia ixx="2.7e-6" iyy="2.7e-6" izz="1.0e-6" ixy="0.0" iyz="0.0" ixz="0.0"/>
    </inertial>
    <visual>
      <origin xyz="0.0 0.0 -0.024" rpy="0 0 0"/>
      <geometry>
        <mesh filename="package://omni_1_description/meshes/roller.stl" scale="1 1 1"/>
      </geometry>
      <material name="black"/>
    </visual>
    <collision>
      <origin xyz="0.0 0.0 -0.024" rpy="0 0 0"/>
      <geometry>
        <mesh filename="package://omni_1_description/meshes/roller.stl" scale="1 1 1"/>
      </geometry>
    </collision>
  </link>

  <link name="roller-1-5">
    <inertial>
      <origin xyz="0 0 0" rpy="0 0 0"/>
      <mass value="0.02"/>
      <inertia ixx="2.7e-6" iyy="2.7e-6" izz="1.0e-6" ixy="0.0" iyz="0.0" ixz="0.0"/>
    </inertial>
    <visual>
      <origin xyz="0.0 0.0 -0.024" rpy="0 0 0"/>
      <geometry>
        <mesh filename="package://omni_1_description/meshes/roller.stl" scale="1 1 1"/>
      </geometry>
      <material name="black"/>
    </visual>
    <collision>
      <origin xyz="0.0 0.0 -0.024" rpy="0 0 0"/>
      <geometry>
        <mesh filename="package://omni_1_description/meshes/roller.stl" scale="1 1 1"/>
      </geometry>
    </collision>
  </link>

  <joint name="wheel-frame0" type="continuous">
    <origin xyz="0.0 -0.1 0.0" rpy="0 0 0"/>
    <parent link="base_link"/>
    <child link="wheel-frame0"/>
    <axis xyz="0.0 -1.0 0.0"/>
    <limit effort="100" velocity="100"/>
  </joint>
  
  <joint name="wheel-frame120" type="continuous">
    <origin xyz="0.08660254038 0.05 0.0" rpy="0 0 2.094395102"/>
    <parent link="base_link"/>
    <child link="wheel-frame120"/>
    <axis xyz="0.0 -1.0 0.0"/>
    <limit effort="100" velocity="100"/>
  </joint>

  <joint name="wheel-frame240" type="continuous">
    <origin xyz="-0.08660254038 0.05 0.0" rpy="0 0 4.188790205"/>
    <parent link="base_link"/>
    <child link="wheel-frame240"/>
    <axis xyz="0.0 -1.0 0.0"/>
    <limit effort="100" velocity="100"/>
  </joint>

  <joint name="wheel240-roller0" type="continuous">
    <origin xyz="0.0 0.013 0.024" rpy="0 0 0"/>
    <parent link="wheel-frame240"/>
    <child link="roller-2-0"/>
    <axis xyz="1.0 0.0 0.0"/>
    <dynamics damping="0.01" friction="0.1" />
  </joint>

  <joint name="wheel240-roller1" type="continuous">
    <origin xyz="0.0207846 0.013 -0.012" rpy="0 2.094395102 0"/>
    <parent link="wheel-frame240"/>
    <child link="roller-2-1"/>
    <axis xyz="1.0 0.0 0.0"/>
    <dynamics damping="0.01" friction="0.1" />
  </joint>

  <joint name="wheel240-roller2" type="continuous">
    <origin xyz="-0.0207846 0.013 -0.012" rpy="0 4.188790205 0"/>
    <parent link="wheel-frame240"/>
    <child link="roller-2-2"/>
    <axis xyz="1.0 0.0 0.0"/>
    <dynamics damping="0.01" friction="0.1" />
  </joint>

  <joint name="wheel240-roller3" type="continuous">
    <origin xyz="0.0207846 -0.013 0.012" rpy="0 1.0471975512 0"/>
    <parent link="wheel-frame240"/>
    <child link="roller-2-3"/>
    <axis xyz="1.0 0.0 0.0"/>
    <dynamics damping="0.01" friction="0.1" />
  </joint>

  <joint name="wheel240-roller4" type="continuous">
    <origin xyz="0.0 -0.013 -0.024" rpy="0 3.1415926536 0"/>
    <parent link="wheel-frame240"/>
    <child link="roller-2-4"/>
    <axis xyz="1.0 0.0 0.0"/>
    <dynamics damping="0.01" friction="0.1" />
  </joint>

  <joint name="wheel240-roller5" type="continuous">
    <origin xyz="-0.0207846 -0.013 0.012" rpy="0 5.235987756 0"/>
    <parent link="wheel-frame240"/>
    <child link="roller-2-5"/>
    <axis xyz="1.0 0.0 0.0"/>
    <dynamics damping="0.01" friction="0.1" />
  </joint>

  <joint name="wheel120-roller0" type="continuous">
    <origin xyz="0.0 0.013 0.024" rpy="0 0 0"/>
    <parent link="wheel-frame120"/>
    <child link="roller-1-0"/>
    <axis xyz="1.0 0.0 0.0"/>
    <dynamics damping="0.01" friction="0.1" />
  </joint>

  <joint name="wheel120-roller1" type="continuous">
    <origin xyz="0.0207846 0.013 -0.012" rpy="0 2.094395102 0"/>
    <parent link="wheel-frame120"/>
    <child link="roller-1-1"/>
    <axis xyz="1.0 0.0 0.0"/>
    <dynamics damping="0.01" friction="0.1" />
  </joint>

  <joint name="wheel120-roller2" type="continuous">
    <origin xyz="-0.0207846 0.013 -0.012" rpy="0 4.188790205 0"/>
    <parent link="wheel-frame120"/>
    <child link="roller-1-2"/>
    <axis xyz="1.0 0.0 0.0"/>
    <dynamics damping="0.01" friction="0.1" />
  </joint>

  <joint name="wheel120-roller3" type="continuous">
    <origin xyz="0.0207846 -0.013 0.012" rpy="0 1.0471975512 0"/>
    <parent link="wheel-frame120"/>
    <child link="roller-1-3"/>
    <axis xyz="1.0 0.0 0.0"/>
    <dynamics damping="0.01" friction="0.1" />
  </joint>

  <joint name="wheel120-roller4" type="continuous">
    <origin xyz="0.0 -0.013 -0.024" rpy="0 3.1415926536 0"/>
    <parent link="wheel-frame120"/>
    <child link="roller-1-4"/>
    <axis xyz="1.0 0.0 0.0"/>
    <dynamics damping="0.01" friction="0.1" />
  </joint>

  <joint name="wheel120-roller5" type="continuous">
    <origin xyz="-0.0207846 -0.013 0.012" rpy="0 5.235987756 0"/>
    <parent link="wheel-frame120"/>
    <child link="roller-1-5"/>
    <axis xyz="1.0 0.0 0.0"/>
    <dynamics damping="0.01" friction="0.1" />
  </joint>

  <joint name="wheel0-roller0" type="continuous">
    <origin xyz="0.0 0.013 0.024" rpy="0 0 0"/>
    <parent link="wheel-frame0"/>
    <child link="roller-0-0"/>
    <axis xyz="1.0 0.0 0.0"/>
    <dynamics damping="0.01" friction="0.1" />
  </joint>

  <joint name="wheel0-roller1" type="continuous">
    <origin xyz="0.0207846 0.013 -0.012" rpy="0 2.094395102 0"/>
    <parent link="wheel-frame0"/>
    <child link="roller-0-1"/>
    <axis xyz="1.0 0.0 0.0"/>
    <dynamics damping="0.01" friction="0.1" />
  </joint>

  <joint name="wheel0-roller2" type="continuous">
    <origin xyz="-0.0207846 0.013 -0.012" rpy="0 4.188790205 0"/>
    <parent link="wheel-frame0"/>
    <child link="roller-0-2"/>
    <axis xyz="1.0 0.0 0.0"/>
    <dynamics damping="0.01" friction="0.1" />
  </joint>

  <joint name="wheel0-roller3" type="continuous">
    <origin xyz="0.0207846 -0.013 0.012" rpy="0 1.0471975512 0"/>
    <parent link="wheel-frame0"/>
    <child link="roller-0-3"/>
    <axis xyz="1.0 0.0 0.0"/>
    <dynamics damping="0.01" friction="0.1" />
  </joint>

  <joint name="wheel0-roller4" type="continuous">
    <origin xyz="0.0 -0.013 -0.024" rpy="0 3.1415926536 0"/>
    <parent link="wheel-frame0"/>
    <child link="roller-0-4"/>
    <axis xyz="1.0 0.0 0.0"/>
    <dynamics damping="0.01" friction="0.1" />
  </joint>

  <joint name="wheel0-roller5" type="continuous">
    <origin xyz="-0.0207846 -0.013 0.012" rpy="0 5.235987756 0"/>
    <parent link="wheel-frame0"/>
    <child link="roller-0-5"/>
    <axis xyz="1.0 0.0 0.0"/>
    <dynamics damping="0.01" friction="0.1" />
  </joint>
  
  <webots>
    <device reference="wheel-frame0" type="RotationalMotor"/>
    <device reference="wheel-frame120" type="RotationalMotor"/>
    <device reference="wheel-frame240" type="RotationalMotor"/>
    <plugin type="omni_1_webots.motor_driver.MotorDriver"/>
  </webots>

</robot>
