<?xml version="1.0" ?>
<robot name="omni-1">

  <material name="silver">
    <color rgba="0.8 0.8 0.8 1.0"/>
  </material>

  <material name="grey">
    <color rgba="0.4 0.4 0.4 1.0"/>
  </material>

  <material name="black">
    <color rgba="0.2 0.2 0.2 1.0"/>
  </material>

  <link name="base_link">
    <inertial>
      <origin xyz="0 0 0" rpy="0 0 2.6177994"/>
      <mass value="0.7"/>
      <inertia ixx="0.065" iyy="0.065" izz="0.065" ixy="0.0" iyz="0.0" ixz="0.0"/>
    </inertial>
    <visual>
      <origin xyz="0 0 0" rpy="0 0 2.6177994"/>
      <geometry>
        <mesh filename="package://omni_1_description/meshes/base_link.stl" scale="1 1 1"/>
      </geometry>
      <material name="silver"/>
    </visual>
    <collision>
      <origin xyz="0 0 0" rpy="0 0 2.6177994"/>
      <geometry>
        <mesh filename="package://omni_1_description/meshes/base_link.stl" scale="1 1 1"/>
      </geometry>
    </collision>
  </link>

  <link name="wheel-frame60">
    <inertial>
      <origin xyz="0 0 0" rpy="0 0 0"/>
      <mass value="0.1"/>
      <inertia ixx="1.7e-4" iyy="1.8e-4" izz="1.7e-4" ixy="0.0" iyz="0.0" ixz="0.0"/>
    </inertial>
    <visual>
      <origin xyz="0.0 0.0 0.0" rpy="0 0 0"/>
      <geometry>
        <mesh filename="package://omni_1_description/meshes/wheel_frame.stl" scale="1 1 1"/>
      </geometry>
      <material name="grey"/>
    </visual>
    <collision>
      <origin xyz="0.0 0.0 0.0" rpy="0 0 0"/>
      <geometry>
        <mesh filename="package://omni_1_description/meshes/wheel_frame.stl" scale="1 1 1"/>
      </geometry>
    </collision>
  </link>

  <link name="wheel-frame180">
    <inertial>
      <origin xyz="0 0 0" rpy="0 0 0"/>
      <mass value="0.1"/>
      <inertia ixx="1.7e-4" iyy="1.8e-4" izz="1.7e-4" ixy="0.0" iyz="0.0" ixz="0.0"/>
    </inertial>
    <visual>
      <origin xyz="0.0 0.0 0.0" rpy="0 0 0"/>
      <geometry>
        <mesh filename="package://omni_1_description/meshes/wheel_frame.stl" scale="1 1 1"/>
      </geometry>
      <material name="grey"/>
    </visual>
    <collision>
      <origin xyz="0.0 0.0 0.0" rpy="0 0 0"/>
      <geometry>
        <mesh filename="package://omni_1_description/meshes/wheel_frame.stl" scale="1 1 1"/>
      </geometry>
    </collision>
  </link>

  <link name="wheel-frame300">
    <inertial>
      <origin xyz="0 0 0" rpy="0 0 0"/>
      <mass value="0.1"/>
      <inertia ixx="1.7e-4" iyy="1.8e-4" izz="1.7e-4" ixy="0.0" iyz="0.0" ixz="0.0"/>
    </inertial>
    <visual>
      <origin xyz="0.0 0.0 0.0" rpy="0 0 0"/>
      <geometry>
        <mesh filename="package://omni_1_description/meshes/wheel_frame.stl" scale="1 1 1"/>
      </geometry>
      <material name="grey"/>
    </visual>
    <collision>
      <origin xyz="0.0 0.0 0.0" rpy="0 0 0"/>
      <geometry>
        <mesh filename="package://omni_1_description/meshes/wheel_frame.stl" scale="1 1 1"/>
      </geometry>
    </collision>
  </link>

  <link name="roller-0-0">
    <inertial>
      <origin xyz="0 0 0" rpy="0 0 0"/>
      <mass value="0.002"/>
      <inertia ixx="2.7e-6" iyy="2.7e-6" izz="1.0e-6" ixy="0.0" iyz="0.0" ixz="0.0"/>
    </inertial>
    <visual>
      <origin xyz="0.0 0.0 -0.024" rpy="0 0 0"/>
      <geometry>
        <mesh filename="package://omni_1_description/meshes/roller.stl" scale="1 1 1"/>
      </geometry>
      <material name="black"/>
    </visual>
    <collision>
      <origin xyz="0.0 0.0 -0.024" rpy="0 0 0"/>
      <geometry>
        <mesh filename="package://omni_1_description/meshes/roller.stl" scale="1 1 1"/>
      </geometry>
    </collision>
  </link>

  <link name="roller-0-1">
    <inertial>
      <origin xyz="0 0 0" rpy="0 0 0"/>
      <mass value="0.002"/>
      <inertia ixx="2.7e-6" iyy="2.7e-6" izz="1.0e-6" ixy="0.0" iyz="0.0" ixz="0.0"/>
    </inertial>
    <visual>
      <origin xyz="0.0 0.0 -0.024" rpy="0 0 0"/>
      <geometry>
        <mesh filename="package://omni_1_description/meshes/roller.stl" scale="1 1 1"/>
      </geometry>
      <material name="black"/>
    </visual>
    <collision>
      <origin xyz="0.0 0.0 -0.024" rpy="0 0 0"/>
      <geometry>
        <mesh filename="package://omni_1_description/meshes/roller.stl" scale="1 1 1"/>
      </geometry>
    </collision>
  </link>

  <link name="roller-0-2">
    <inertial>
      <origin xyz="0 0 0" rpy="0 0 0"/>
      <mass value="0.002"/>
      <inertia ixx="2.7e-6" iyy="2.7e-6" izz="1.0e-6" ixy="0.0" iyz="0.0" ixz="0.0"/>
    </inertial>
    <visual>
      <origin xyz="0.0 0.0 -0.024" rpy="0 0 0"/>
      <geometry>
        <mesh filename="package://omni_1_description/meshes/roller.stl" scale="1 1 1"/>
      </geometry>
      <material name="black"/>
    </visual>
    <collision>
      <origin xyz="0.0 0.0 -0.024" rpy="0 0 0"/>
      <geometry>
        <mesh filename="package://omni_1_description/meshes/roller.stl" scale="1 1 1"/>
      </geometry>
    </collision>
  </link>

  <link name="roller-0-3">
    <inertial>
      <origin xyz="0 0 0" rpy="0 0 0"/>
      <mass value="0.002"/>
      <inertia ixx="2.7e-6" iyy="2.7e-6" izz="1.0e-6" ixy="0.0" iyz="0.0" ixz="0.0"/>
    </inertial>
    <visual>
      <origin xyz="0.0 0.0 -0.024" rpy="0 0 0"/>
      <geometry>
        <mesh filename="package://omni_1_description/meshes/roller.stl" scale="1 1 1"/>
      </geometry>
      <material name="black"/>
    </visual>
    <collision>
      <origin xyz="0.0 0.0 -0.024" rpy="0 0 0"/>
      <geometry>
        <mesh filename="package://omni_1_description/meshes/roller.stl" scale="1 1 1"/>
      </geometry>
    </collision>
  </link>

  <link name="roller-0-4">
    <inertial>
      <origin xyz="0 0 0" rpy="0 0 0"/>
      <mass value="0.002"/>
      <inertia ixx="2.7e-6" iyy="2.7e-6" izz="1.0e-6" ixy="0.0" iyz="0.0" ixz="0.0"/>
    </inertial>
    <visual>
      <origin xyz="0.0 0.0 -0.024" rpy="0 0 0"/>
      <geometry>
        <mesh filename="package://omni_1_description/meshes/roller.stl" scale="1 1 1"/>
      </geometry>
      <material name="black"/>
    </visual>
    <collision>
      <origin xyz="0.0 0.0 -0.024" rpy="0 0 0"/>
      <geometry>
        <mesh filename="package://omni_1_description/meshes/roller.stl" scale="1 1 1"/>
      </geometry>
    </collision>
  </link>

  <link name="roller-0-5">
    <inertial>
      <origin xyz="0 0 0" rpy="0 0 0"/>
      <mass value="0.002"/>
      <inertia ixx="2.7e-6" iyy="2.7e-6" izz="1.0e-6" ixy="0.0" iyz="0.0" ixz="0.0"/>
    </inertial>
    <visual>
      <origin xyz="0.0 0.0 -0.024" rpy="0 0 0"/>
      <geometry>
        <mesh filename="package://omni_1_description/meshes/roller.stl" scale="1 1 1"/>
      </geometry>
      <material name="black"/>
    </visual>
    <collision>
      <origin xyz="0.0 0.0 -0.024" rpy="0 0 0"/>
      <geometry>
        <mesh filename="package://omni_1_description/meshes/roller.stl" scale="1 1 1"/>
      </geometry>
    </collision>
  </link>

  <link name="roller-2-0">
    <inertial>
      <origin xyz="0 0 0" rpy="0 0 0"/>
      <mass value="0.002"/>
      <inertia ixx="2.7e-6" iyy="2.7e-6" izz="1.0e-6" ixy="0.0" iyz="0.0" ixz="0.0"/>
    </inertial>
    <visual>
      <origin xyz="0.0 0.0 -0.024" rpy="0 0 0"/>
      <geometry>
        <mesh filename="package://omni_1_description/meshes/roller.stl" scale="1 1 1"/>
      </geometry>
      <material name="black"/>
    </visual>
    <collision>
      <origin xyz="0.0 0.0 -0.024" rpy="0 0 0"/>
      <geometry>
        <mesh filename="package://omni_1_description/meshes/roller.stl" scale="1 1 1"/>
      </geometry>
    </collision>
  </link>

  <link name="roller-2-1">
    <inertial>
      <origin xyz="0 0 0" rpy="0 0 0"/>
      <mass value="0.002"/>
      <inertia ixx="2.7e-6" iyy="2.7e-6" izz="1.0e-6" ixy="0.0" iyz="0.0" ixz="0.0"/>
    </inertial>
    <visual>
      <origin xyz="0.0 0.0 -0.024" rpy="0 0 0"/>
      <geometry>
        <mesh filename="package://omni_1_description/meshes/roller.stl" scale="1 1 1"/>
      </geometry>
      <material name="black"/>
    </visual>
    <collision>
      <origin xyz="0.0 0.0 -0.024" rpy="0 0 0"/>
      <geometry>
        <mesh filename="package://omni_1_description/meshes/roller.stl" scale="1 1 1"/>
      </geometry>
    </collision>
  </link>

  <link name="roller-2-2">
    <inertial>
      <origin xyz="0 0 0" rpy="0 0 0"/>
      <mass value="0.002"/>
      <inertia ixx="2.7e-6" iyy="2.7e-6" izz="1.0e-6" ixy="0.0" iyz="0.0" ixz="0.0"/>
    </inertial>
    <visual>
      <origin xyz="0.0 0.0 -0.024" rpy="0 0 0"/>
      <geometry>
        <mesh filename="package://omni_1_description/meshes/roller.stl" scale="1 1 1"/>
      </geometry>
      <material name="black"/>
    </visual>
    <collision>
      <origin xyz="0.0 0.0 -0.024" rpy="0 0 0"/>
      <geometry>
        <mesh filename="package://omni_1_description/meshes/roller.stl" scale="1 1 1"/>
      </geometry>
    </collision>
  </link>

  <link name="roller-2-3">
    <inertial>
      <origin xyz="0 0 0" rpy="0 0 0"/>
      <mass value="0.002"/>
      <inertia ixx="2.7e-6" iyy="2.7e-6" izz="1.0e-6" ixy="0.0" iyz="0.0" ixz="0.0"/>
    </inertial>
    <visual>
      <origin xyz="0.0 0.0 -0.024" rpy="0 0 0"/>
      <geometry>
        <mesh filename="package://omni_1_description/meshes/roller.stl" scale="1 1 1"/>
      </geometry>
      <material name="black"/>
    </visual>
    <collision>
      <origin xyz="0.0 0.0 -0.024" rpy="0 0 0"/>
      <geometry>
        <mesh filename="package://omni_1_description/meshes/roller.stl" scale="1 1 1"/>
      </geometry>
    </collision>
  </link>

  <link name="roller-2-4">
    <inertial>
      <origin xyz="0 0 0" rpy="0 0 0"/>
      <mass value="0.002"/>
      <inertia ixx="2.7e-6" iyy="2.7e-6" izz="1.0e-6" ixy="0.0" iyz="0.0" ixz="0.0"/>
    </inertial>
    <visual>
      <origin xyz="0.0 0.0 -0.024" rpy="0 0 0"/>
      <geometry>
        <mesh filename="package://omni_1_description/meshes/roller.stl" scale="1 1 1"/>
      </geometry>
      <material name="black"/>
    </visual>
    <collision>
      <origin xyz="0.0 0.0 -0.024" rpy="0 0 0"/>
      <geometry>
        <mesh filename="package://omni_1_description/meshes/roller.stl" scale="1 1 1"/>
      </geometry>
    </collision>
  </link>

  <link name="roller-2-5">
    <inertial>
      <origin xyz="0 0 0" rpy="0 0 0"/>
      <mass value="0.002"/>
      <inertia ixx="2.7e-6" iyy="2.7e-6" izz="1.0e-6" ixy="0.0" iyz="0.0" ixz="0.0"/>
    </inertial>
    <visual>
      <origin xyz="0.0 0.0 -0.024" rpy="0 0 0"/>
      <geometry>
        <mesh filename="package://omni_1_description/meshes/roller.stl" scale="1 1 1"/>
      </geometry>
      <material name="black"/>
    </visual>
    <collision>
      <origin xyz="0.0 0.0 -0.024" rpy="0 0 0"/>
      <geometry>
        <mesh filename="package://omni_1_description/meshes/roller.stl" scale="1 1 1"/>
      </geometry>
    </collision>
  </link>

  <link name="roller-1-0">
    <inertial>
      <origin xyz="0 0 0" rpy="0 0 0"/>
      <mass value="0.002"/>
      <inertia ixx="2.7e-6" iyy="2.7e-6" izz="1.0e-6" ixy="0.0" iyz="0.0" ixz="0.0"/>
    </inertial>
    <visual>
      <origin xyz="0.0 0.0 -0.024" rpy="0 0 0"/>
      <geometry>
        <mesh filename="package://omni_1_description/meshes/roller.stl" scale="1 1 1"/>
      </geometry>
      <material name="black"/>
    </visual>
    <collision>
      <origin xyz="0.0 0.0 -0.024" rpy="0 0 0"/>
      <geometry>
        <mesh filename="package://omni_1_description/meshes/roller.stl" scale="1 1 1"/>
      </geometry>
    </collision>
  </link>

  <link name="roller-1-1">
    <inertial>
      <origin xyz="0 0 0" rpy="0 0 0"/>
      <mass value="0.002"/>
      <inertia ixx="2.7e-6" iyy="2.7e-6" izz="1.0e-6" ixy="0.0" iyz="0.0" ixz="0.0"/>
    </inertial>
    <visual>
      <origin xyz="0.0 0.0 -0.024" rpy="0 0 0"/>
      <geometry>
        <mesh filename="package://omni_1_description/meshes/roller.stl" scale="1 1 1"/>
      </geometry>
      <material name="black"/>
    </visual>
    <collision>
      <origin xyz="0.0 0.0 -0.024" rpy="0 0 0"/>
      <geometry>
        <mesh filename="package://omni_1_description/meshes/roller.stl" scale="1 1 1"/>
      </geometry>
    </collision>
  </link>

  <link name="roller-1-2">
    <inertial>
      <origin xyz="0 0 0" rpy="0 0 0"/>
      <mass value="0.002"/>
      <inertia ixx="2.7e-6" iyy="2.7e-6" izz="1.0e-6" ixy="0.0" iyz="0.0" ixz="0.0"/>
    </inertial>
    <visual>
      <origin xyz="0.0 0.0 -0.024" rpy="0 0 0"/>
      <geometry>
        <mesh filename="package://omni_1_description/meshes/roller.stl" scale="1 1 1"/>
      </geometry>
      <material name="black"/>
    </visual>
    <collision>
      <origin xyz="0.0 0.0 -0.024" rpy="0 0 0"/>
      <geometry>
        <mesh filename="package://omni_1_description/meshes/roller.stl" scale="1 1 1"/>
      </geometry>
    </collision>
  </link>

  <link name="roller-1-3">
    <inertial>
      <origin xyz="0 0 0" rpy="0 0 0"/>
      <mass value="0.002"/>
      <inertia ixx="2.7e-6" iyy="2.7e-6" izz="1.0e-6" ixy="0.0" iyz="0.0" ixz="0.0"/>
    </inertial>
    <visual>
      <origin xyz="0.0 0.0 -0.024" rpy="0 0 0"/>
      <geometry>
        <mesh filename="package://omni_1_description/meshes/roller.stl" scale="1 1 1"/>
      </geometry>
      <material name="black"/>
    </visual>
    <collision>
      <origin xyz="0.0 0.0 -0.024" rpy="0 0 0"/>
      <geometry>
        <mesh filename="package://omni_1_description/meshes/roller.stl" scale="1 1 1"/>
      </geometry>
    </collision>
  </link>

  <link name="roller-1-4">
    <inertial>
      <origin xyz="0 0 0" rpy="0 0 0"/>
      <mass value="0.002"/>
      <inertia ixx="2.7e-6" iyy="2.7e-6" izz="1.0e-6" ixy="0.0" iyz="0.0" ixz="0.0"/>
    </inertial>
    <visual>
      <origin xyz="0.0 0.0 -0.024" rpy="0 0 0"/>
      <geometry>
        <mesh filename="package://omni_1_description/meshes/roller.stl" scale="1 1 1"/>
      </geometry>
      <material name="black"/>
    </visual>
    <collision>
      <origin xyz="0.0 0.0 -0.024" rpy="0 0 0"/>
      <geometry>
        <mesh filename="package://omni_1_description/meshes/roller.stl" scale="1 1 1"/>
      </geometry>
    </collision>
  </link>

  <link name="roller-1-5">
    <inertial>
      <origin xyz="0 0 0" rpy="0 0 0"/>
      <mass value="0.002"/>
      <inertia ixx="2.7e-6" iyy="2.7e-6" izz="1.0e-6" ixy="0.0" iyz="0.0" ixz="0.0"/>
    </inertial>
    <visual>
      <origin xyz="0.0 0.0 -0.024" rpy="0 0 0"/>
      <geometry>
        <mesh filename="package://omni_1_description/meshes/roller.stl" scale="1 1 1"/>
      </geometry>
      <material name="black"/>
    </visual>
    <collision>
      <origin xyz="0.0 0.0 -0.024" rpy="0 0 0"/>
      <geometry>
        <mesh filename="package://omni_1_description/meshes/roller.stl" scale="1 1 1"/>
      </geometry>
    </collision>
  </link>

  <joint name="wheel-frame60" type="continuous">
    <origin xyz="0.05 0.08660254038 0.0" rpy="0 0 -0.5235987756"/>
    <parent link="base_link"/>
    <child link="wheel-frame60"/>
    <axis xyz="0.0 -1.0 0.0"/>
    <limit effort="10" velocity="10"/>
  </joint>
  
  <joint name="wheel-frame180" type="continuous">
    <origin xyz="-0.1 0.0 0.0" rpy="0 0 1.570796327"/>
    <parent link="base_link"/>
    <child link="wheel-frame180"/>
    <axis xyz="0.0 -1.0 0.0"/>
    <limit effort="10" velocity="10"/>
  </joint>

  <joint name="wheel-frame300" type="continuous">
    <origin xyz="0.05 -0.08660254038 0." rpy="0 0 -2.617993878"/>
    <parent link="base_link"/>
    <child link="wheel-frame300"/>
    <axis xyz="0.0 -1.0 0.0"/>
    <limit effort="10" velocity="10"/>
  </joint>

  <joint name="wheel300-roller0" type="continuous">
    <origin xyz="0.0 0.013 0.024" rpy="0 0 0"/>
    <parent link="wheel-frame300"/>
    <child link="roller-2-0"/>
    <axis xyz="1.0 0.0 0.0"/>
    <dynamics damping="0.01" friction="0.1" />
  </joint>

  <joint name="wheel300-roller1" type="continuous">
    <origin xyz="0.0207846 0.013 -0.012" rpy="0 2.094395102 0"/>
    <parent link="wheel-frame300"/>
    <child link="roller-2-1"/>
    <axis xyz="1.0 0.0 0.0"/>
    <dynamics damping="0.01" friction="0.1" />
  </joint>

  <joint name="wheel300-roller2" type="continuous">
    <origin xyz="-0.0207846 0.013 -0.012" rpy="0 4.188790205 0"/>
    <parent link="wheel-frame300"/>
    <child link="roller-2-2"/>
    <axis xyz="1.0 0.0 0.0"/>
    <dynamics damping="0.01" friction="0.1" />
  </joint>

  <joint name="wheel300-roller3" type="continuous">
    <origin xyz="0.0207846 -0.013 0.012" rpy="0 1.0471975512 0"/>
    <parent link="wheel-frame300"/>
    <child link="roller-2-3"/>
    <axis xyz="1.0 0.0 0.0"/>
    <dynamics damping="0.01" friction="0.1" />
  </joint>

  <joint name="wheel300-roller4" type="continuous">
    <origin xyz="0.0 -0.013 -0.024" rpy="0 3.1415926536 0"/>
    <parent link="wheel-frame300"/>
    <child link="roller-2-4"/>
    <axis xyz="1.0 0.0 0.0"/>
    <dynamics damping="0.01" friction="0.1" />
  </joint>

  <joint name="wheel300-roller5" type="continuous">
    <origin xyz="-0.0207846 -0.013 0.012" rpy="0 5.235987756 0"/>
    <parent link="wheel-frame300"/>
    <child link="roller-2-5"/>
    <axis xyz="1.0 0.0 0.0"/>
    <dynamics damping="0.01" friction="0.1" />
  </joint>

  <joint name="wheel180-roller0" type="continuous">
    <origin xyz="0.0 0.013 0.024" rpy="0 0 0"/>
    <parent link="wheel-frame180"/>
    <child link="roller-1-0"/>
    <axis xyz="1.0 0.0 0.0"/>
    <dynamics damping="0.01" friction="0.1" />
  </joint>

  <joint name="wheel180-roller1" type="continuous">
    <origin xyz="0.0207846 0.013 -0.012" rpy="0 2.094395102 0"/>
    <parent link="wheel-frame180"/>
    <child link="roller-1-1"/>
    <axis xyz="1.0 0.0 0.0"/>
    <dynamics damping="0.01" friction="0.1" />
  </joint>

  <joint name="wheel180-roller2" type="continuous">
    <origin xyz="-0.0207846 0.013 -0.012" rpy="0 4.188790205 0"/>
    <parent link="wheel-frame180"/>
    <child link="roller-1-2"/>
    <axis xyz="1.0 0.0 0.0"/>
    <dynamics damping="0.01" friction="0.1" />
  </joint>

  <joint name="wheel180-roller3" type="continuous">
    <origin xyz="0.0207846 -0.013 0.012" rpy="0 1.0471975512 0"/>
    <parent link="wheel-frame180"/>
    <child link="roller-1-3"/>
    <axis xyz="1.0 0.0 0.0"/>
    <dynamics damping="0.01" friction="0.1" />
  </joint>

  <joint name="wheel180-roller4" type="continuous">
    <origin xyz="0.0 -0.013 -0.024" rpy="0 3.1415926536 0"/>
    <parent link="wheel-frame180"/>
    <child link="roller-1-4"/>
    <axis xyz="1.0 0.0 0.0"/>
    <dynamics damping="0.01" friction="0.1" />
  </joint>

  <joint name="wheel180-roller5" type="continuous">
    <origin xyz="-0.0207846 -0.013 0.012" rpy="0 5.235987756 0"/>
    <parent link="wheel-frame180"/>
    <child link="roller-1-5"/>
    <axis xyz="1.0 0.0 0.0"/>
    <dynamics damping="0.01" friction="0.1" />
  </joint>

  <joint name="wheel60-roller0" type="continuous">
    <origin xyz="0.0 0.013 0.024" rpy="0 0 0"/>
    <parent link="wheel-frame60"/>
    <child link="roller-0-0"/>
    <axis xyz="1.0 0.0 0.0"/>
    <dynamics damping="0.01" friction="0.1" />
  </joint>

  <joint name="wheel60-roller1" type="continuous">
    <origin xyz="0.0207846 0.013 -0.012" rpy="0 2.094395102 0"/>
    <parent link="wheel-frame60"/>
    <child link="roller-0-1"/>
    <axis xyz="1.0 0.0 0.0"/>
    <dynamics damping="0.01" friction="0.1" />
  </joint>

  <joint name="wheel60-roller2" type="continuous">
    <origin xyz="-0.0207846 0.013 -0.012" rpy="0 4.188790205 0"/>
    <parent link="wheel-frame60"/>
    <child link="roller-0-2"/>
    <axis xyz="1.0 0.0 0.0"/>
    <dynamics damping="0.01" friction="0.1" />
  </joint>

  <joint name="wheel60-roller3" type="continuous">
    <origin xyz="0.0207846 -0.013 0.012" rpy="0 1.0471975512 0"/>
    <parent link="wheel-frame60"/>
    <child link="roller-0-3"/>
    <axis xyz="1.0 0.0 0.0"/>
    <dynamics damping="0.01" friction="0.1" />
  </joint>

  <joint name="wheel60-roller4" type="continuous">
    <origin xyz="0.0 -0.013 -0.024" rpy="0 3.1415926536 0"/>
    <parent link="wheel-frame60"/>
    <child link="roller-0-4"/>
    <axis xyz="1.0 0.0 0.0"/>
    <dynamics damping="0.01" friction="0.1" />
  </joint>

  <joint name="wheel60-roller5" type="continuous">
    <origin xyz="-0.0207846 -0.013 0.012" rpy="0 5.235987756 0"/>
    <parent link="wheel-frame60"/>
    <child link="roller-0-5"/>
    <axis xyz="1.0 0.0 0.0"/>
    <dynamics damping="0.01" friction="0.1" />
  </joint>
  
  <webots>
    <device reference="wheel-frame60" type="RotationalMotor"/>
    <device reference="wheel-frame180" type="RotationalMotor"/>
    <device reference="wheel-frame300" type="RotationalMotor"/>
    <plugin type="omni_1_webots.motor_driver.MotorDriver"/>
  </webots>

</robot>
